File: DateTimeSpectrumPointNumber.txt
#Acq. time (s)=	1
#Accumulations=	2
#Range (cm-¹)=	-400...800
#Windows=	3
#Autofocus=	Off
#AutoExposure=	Off
#Spike filter=	Off
#Delay time (s)=	0
#Binning=	1
#Readout mode=	Signal
#DeNoise=	Off
#ICS correction=	Off
#Dark correction=	Off
#Inst. Process=	Off
#Instrument=	LabRAM HR Evol
#Detector=	Emulator CCD
#Objective=	x100
#Grating=	1800 gr/mm
#ND Filter=	100%
#Laser (nm)=	512
#Slit=	150.001
#Hole=	70.0087
#Project=	A
#Sample=	B
#Site=	C
#Title=	D_23
#Remark=
#Date=	05.10.2017 07:53
#Acquired=	05.10.2017 07:53:28
-399.951	349
-398.69	380.5
-397.429	356.5
-396.169	363.001
-394.91	362.501
-393.65	339.001
-392.39	345.501
-391.131	371.001
-389.872	368.501
-388.613	372.002
-387.355	383.502
-386.096	389.502
-384.838	339.002
-383.581	344.502
-382.322	396.502
-381.065	384.503
-379.808	374.503
-378.551	398.503
-377.294	334.003
-376.037	343.503
-374.781	344.503
-373.524	386.504
-372.268	352.004
-371.012	356.004
-369.756	365.504
-368.501	360.004
-367.245	353.004
-365.991	358.505
-364.736	349.505
-363.481	359.005
-362.227	376.505
-360.972	366.005
-359.719	381.506
-358.464	397.006
-357.211	378.006
-355.958	410.506
-354.704	362.006
-353.452	348.506
-352.199	376.507
-350.947	384.007
-349.694	349.007
-348.442	390.007
-347.19	335.507
-345.938	367.507
-344.687	383.508
-343.435	382.008
-342.184	350.508
-340.933	373.008
-339.684	339.008
-338.433	362.008
-337.182	341.509
-335.932	333.509
-334.683	402.009
-333.433	377.009
-332.184	336.009
-330.934	335.509
-329.686	363.01
-328.436	374.51
-327.188	355.51
-325.939	358.01
-324.691	349.51
-323.444	339.511
-322.196	360.011
-320.948	363.511
-319.701	370.511
-318.454	331.511
-317.207	377.011
-315.96	330.012
-314.714	347.512
-313.467	370.512
-312.221	343.012
-310.975	341.012
-309.73	354.012
-308.485	375.513
-307.239	344.013
-305.995	326.013
-304.749	357.513
-303.504	356.013
-302.261	345.513
-301.016	393.014
-299.772	397.514
-298.528	343.014
-297.285	387.514
-296.042	368.014
-294.798	382.014
-293.555	377.515
-292.313	366.015
-291.07	382.515
-289.828	371.515
-288.586	356.015
-287.344	377.016
-286.102	364.016
-284.861	365.516
-283.619	356.516
-282.378	400.516
-281.137	338.016
-279.896	356.017
-278.656	324.017
-277.416	375.517
-276.175	377.517
-274.936	380.517
-273.696	360.517
-272.457	397.518
-271.217	362.518
-269.979	332.018
-268.739	341.518
-267.501	346.518
-266.263	352.518
-265.024	384.519
-263.786	360.019
-262.548	326.519
-261.311	340.519
-260.074	387.519
-258.837	373.519
-257.6	346.02
-256.363	364.02
-255.126	323.02
-253.89	365.02
-252.653	381.02
-251.418	370.521
-250.182	326.021
-248.946	360.521
-247.711	387.021
-246.476	325.021
-245.241	339.021
-244.007	382.522
-242.772	360.522
-241.538	376.522
-240.304	328.522
-239.07	369.522
-237.836	352.522
-236.603	367.023
-235.369	345.523
-234.136	336.023
-232.903	382.023
-231.671	350.523
-230.439	342.523
-229.206	386.524
-227.974	347.524
-226.742	397.024
-225.511	329.524
-224.28	376.024
-223.049	339.024
-221.817	361.025
-220.586	341.525
-219.356	372.525
-218.126	350.525
-216.896	391.025
-215.666	348.026
-214.436	369.526
-213.206	392.526
-211.977	342.526
-210.747	367.526
-209.519	355.026
-208.29	358.527
-207.062	395.527
-205.834	330.527
-204.605	361.527
-203.377	380.527
-202.149	355.527
-200.922	370.028
-199.694	365.528
-198.468	332.028
-197.241	358.028
-196.014	341.528
-194.788	356.028
-193.561	348.529
-192.336	380.529
-191.109	349.029
-189.884	390.029
-188.658	310.529
-187.433	342.029
-186.208	340.53
-184.984	335.53
-183.758	361.03
-182.534	341.03
-181.31	348.03
-180.086	343.031
-178.862	359.031
-177.639	360.531
-176.415	368.531
-175.192	328.031
-173.969	354.031
-172.746	395.532
-171.524	371.032
-170.301	353.032
-169.079	348.532
-167.858	375.532
-166.636	346.532
-165.414	342.033
-164.192	354.033
-162.971	339.033
-161.75	362.533
-160.53	337.033
-159.309	328.033
-158.089	402.534
-156.868	325.534
-155.649	369.034
-154.429	353.534
-153.21	326.034
-151.99	344.534
-150.771	385.535
-149.552	337.035
-148.333	345.035
-147.115	330.535
-145.897	387.035
-144.678	383.536
-143.46	373.536
-142.243	396.536
-141.026	367.536
-139.808	332.536
-138.591	352.036
-137.374	348.037
-136.158	383.037
-134.941	367.037
-133.725	309.537
-132.509	333.537
-131.293	337.037
-130.077	378.038
-128.862	335.038
-127.647	354.538
-126.431	339.038
-125.217	398.538
-124.002	359.538
-122.788	349.039
-121.574	362.539
-120.36	375.539
-119.146	354.039
-117.932	379.039
-116.719	336.539
-115.505	345.54
-114.292	367.54
-113.079	319.04
-111.867	389.54
-110.654	330.04
-109.442	365.541
-108.231	344.041
-107.018	383.041
-105.807	317.041
-104.595	315.541
-103.384	367.041
-102.173	401.042
-100.962	353.542
-99.7521	378.042
-98.542	375.542
-97.3309	388.542
-96.1211	328.042
-94.9114	390.543
-93.7019	371.043
-92.4925	335.043
-91.2833	361.043
-90.0742	355.043
-88.8653	352.043
-87.6566	316.544
-86.4491	394.544
-85.2407	330.544
-84.0323	360.044
-82.8253	331.544
-81.6173	323.544
-80.4095	364.545
-79.2029	357.545
-77.9953	336.045
-76.7891	339.045
-75.583	381.545
-74.3758	320.546
-73.17	385.046
-71.9644	362.546
-70.7589	374.046
-69.5535	332.046
-68.3471	349.546
-67.1421	334.047
-65.9371	335.547
-64.7324	325.047
-63.5277	352.547
-62.3244	386.547
-61.1201	313.047
-59.9159	349.048
-58.7119	363.048
-57.5092	330.048
-56.3055	349.548
-55.1019	355.548
-53.8996	367.048
-52.6963	358.049
-51.4944	336.049
-50.2914	361.549
-49.0897	364.049
-47.8882	375.549
-46.6856	372.049
-45.4844	361.55
-44.2833	366.05
-43.0823	347.05
-41.8816	333.05
-40.6809	349.05
-39.4804	324.051
-38.2801	370.551
-37.0799	356.051
-35.8798	315.051
-34.6799	379.551
-33.4801	357.051
-32.2817	306.052
-31.0822	326.552
-29.8829	364.052
-28.6849	367.052
-27.4859	366.052
-26.2882	347.552
-25.0894	354.053
-23.892	342.553
-22.6947	329.553
-21.4964	329.553
-20.2995	356.053
-19.1026	365.553
-17.9059	360.554
-16.7082	338.054
-15.5118	340.054
-14.3156	366.554
-13.1195	308.554
-11.9235	350.054
-10.7289	383.555
-9.53325	341.055
-8.33773	378.555
-7.14236	371.555
-5.94714	359.055
-4.75323	389.556
-3.5583	362.056
-2.36468	359.056
-1.17004	325.056
0.023283	371.556
1.21763	379.556
2.41183	370.557
3.60355	310.557
4.79746	389.057
5.99122	318.557
7.18251	350.557
8.37598	357.057
9.56698	327.058
10.7602	369.558
11.9509	370.058
13.1438	352.558
14.3342	391.058
15.5268	367.058
16.7169	366.559
17.9092	373.059
19.099	344.559
20.2887	363.059
21.4806	344.559
22.67	369.559
23.8592	342.56
25.0484	329.56
26.2396	348.56
27.4285	308.56
28.6171	326.06
29.8057	365.561
30.994	330.061
32.1823	363.061
33.3727	327.061
34.5607	326.561
35.7485	341.561
36.9361	385.062
38.1236	349.062
39.311	360.062
40.4982	352.562
41.683	333.562
42.8699	347.062
44.0567	357.063
45.2434	369.063
46.4299	345.563
47.6162	339.563
48.8025	312.063
49.9862	339.063
51.1721	339.064
52.3579	372.064
53.5412	386.064
54.7267	369.564
55.9121	383.564
57.095	328.564
58.28	319.565
59.465	337.565
60.6474	358.565
61.832	344.065
63.0142	347.565
64.1986	352.566
65.3804	365.566
66.5622	318.066
67.7461	305.566
68.9275	319.566
70.1112	343.066
71.2923	376.067
72.4734	348.567
73.6565	350.067
74.8373	328.567
76.0179	333.067
77.1983	311.067
78.3786	327.068
79.5611	367.568
80.7411	354.568
81.921	318.568
83.1007	364.568
84.2803	381.068
85.4598	319.069
86.6391	351.069
87.8182	323.069
88.9973	375.069
90.1761	385.069
91.3549	357.569
92.5334	371.57
93.7119	305.07
94.8902	346.07
96.0684	363.57
97.2441	346.57
98.4219	385.07
99.5997	348.571
100.777	338.571
101.952	369.071
103.13	354.071
104.307	353.571
105.482	356.072
106.658	354.572
107.835	335.572
109.009	346.572
110.186	356.572
111.36	326.072
112.536	352.573
113.71	353.073
114.886	359.073
116.059	326.573
117.235	337.073
118.408	350.573
119.581	327.074
120.756	383.074
121.929	347.074
123.101	329.074
124.276	375.574
125.448	365.574
126.621	373.075
127.793	355.575
128.964	338.575
130.139	353.075
131.31	306.575
132.482	387.076
133.653	378.576
134.824	344.076
135.995	347.576
137.166	329.576
138.337	351.076
139.507	320.077
140.678	371.077
141.848	354.577
143.018	365.077
144.186	358.077
145.356	336.577
146.526	360.078
147.695	347.078
148.865	342.078
150.032	354.078
151.201	331.578
152.37	352.078
153.537	375.579
154.705	340.079
155.874	357.579
157.04	379.079
158.209	346.674
159.375	337.934
160.543	386.284
161.708	332.455
162.876	340.576
164.041	373.948
165.209	354.588
166.374	370.1
167.541	334.156
168.706	338.364
169.871	360.207
171.037	359.178
172.202	356.511
173.366	336.476
174.53	345.558
175.696	382.003
176.86	337.213
178.024	355.024
179.187	357.633
180.351	327.684
181.514	350.249
182.677	347.87
183.84	342.999
185.003	346.578
186.166	325.71
187.328	353.021
188.491	340.087
189.653	348.204
190.815	355.766
191.977	346.96
193.139	365.258
194.301	347.635
195.46	355.762
196.621	367.87
197.783	372.776
198.944	354.381
200.103	345.984
201.263	345.629
202.424	351.663
203.582	340.656
204.743	319.642
205.901	355.553
207.061	368.726
208.221	358.358
209.379	332.671
210.539	341.312
211.696	368.021
212.853	340.716
214.012	355.823
215.169	340.231
216.169	386.899
217.339	363.897
218.51	351.895
219.68	376.393
220.85	322.391
222.019	337.389
223.189	387.387
224.358	367.385
225.528	326.383
226.695	300.381
227.864	364.879
229.033	357.377
230.201	367.875
231.368	311.373
232.536	322.871
233.705	337.369
234.871	355.866
236.039	347.364
237.207	342.362
238.372	339.36
239.54	324.858
240.705	303.856
241.872	340.854
243.037	371.352
244.204	350.35
245.369	345.848
246.536	315.846
247.7	328.844
248.867	313.342
250.031	342.34
251.195	389.338
252.361	366.836
253.525	377.334
254.688	340.832
255.852	329.83
257.017	372.328
258.18	360.826
259.343	314.323
260.506	351.821
261.669	351.819
262.834	321.317
263.996	350.315
265.158	355.813
266.32	367.811
267.482	350.309
268.644	357.807
269.806	377.305
270.968	372.803
272.129	339.301
273.29	355.299
274.451	329.797
275.61	364.295
276.771	320.793
277.932	340.791
279.092	310.289
280.253	357.287
281.413	338.284
282.571	327.782
283.731	352.28
284.891	391.278
286.049	362.276
287.208	350.274
288.368	361.272
289.525	359.77
290.684	326.768
291.843	317.266
293	375.764
294.158	352.762
295.315	358.76
296.473	373.758
297.629	333.256
298.788	315.254
299.944	351.752
301.099	376.25
302.257	359.748
303.412	370.746
304.568	368.243
305.725	315.241
306.88	367.239
308.035	375.737
309.192	309.735
310.347	384.233
311.501	327.731
312.655	337.729
313.809	332.727
314.963	341.225
316.12	381.723
317.273	350.221
318.427	352.219
319.58	350.717
320.734	347.715
321.887	349.713
323.04	358.711
324.193	327.709
325.346	363.207
326.498	385.205
327.649	310.202
328.801	321.2
329.953	345.198
331.105	349.696
332.257	322.194
333.407	363.192
334.558	362.19
335.71	321.688
336.861	358.186
338.01	354.184
339.161	335.182
340.312	322.18
341.461	332.678
342.612	361.176
343.76	325.674
344.911	354.172
346.059	372.67
347.209	336.668
348.357	384.666
349.506	366.164
350.654	346.661
351.803	359.159
352.951	307.657
354.1	380.155
355.247	333.153
356.394	353.651
357.543	366.149
358.689	381.147
359.836	356.645
360.982	375.143
362.128	347.141
363.276	353.639
364.422	327.137
365.568	348.135
366.713	343.633
367.859	388.631
369.004	305.629
370.149	368.127
371.294	355.125
372.439	352.123
373.584	358.62
374.729	363.618
375.873	345.616
377.017	337.614
378.162	323.112
379.306	353.11
380.45	360.608
381.593	317.106
382.735	369.604
383.878	344.102
385.022	366.6
386.165	332.098
387.306	377.596
388.449	362.094
389.592	338.592
390.732	331.09
391.875	346.088
393.017	331.586
394.157	367.084
395.299	343.082
396.439	315.079
397.581	391.077
398.721	338.075
399.862	363.073
401.001	361.071
402.143	368.069
403.282	310.567
404.421	353.065
405.562	337.063
406.7	332.061
407.839	307.559
408.979	339.557
410.117	315.555
411.255	355.553
412.393	364.051
413.531	380.549
414.671	338.547
415.808	354.545
416.946	313.543
418.083	355.041
419.22	347.038
420.357	336.536
421.494	368.034
422.63	361.532
423.767	341.53
424.903	308.528
426.039	332.026
427.176	381.024
428.312	346.522
429.447	340.52
430.581	366.518
431.717	340.016
432.852	394.014
433.987	325.012
435.122	353.51
436.255	356.008
437.39	374.506
438.525	313.504
439.657	337.502
440.792	340
441.926	338.997
443.058	305.495
444.192	341.993
445.324	362.991
446.458	339.989
447.59	371.487
448.723	333.985
449.854	326.983
450.988	319.981
452.119	357.979
453.249	340.477
454.382	380.475
455.513	348.973
456.643	315.971
457.776	374.469
458.906	340.967
460.036	316.965
461.166	345.963
462.298	366.461
463.427	387.459
464.557	351.457
465.686	370.954
466.815	308.952
467.944	346.45
469.073	344.448
470.202	346.946
471.331	339.944
472.459	355.442
473.588	340.44
474.716	319.438
475.844	336.436
476.972	344.934
478.1	328.932
479.228	333.43
480.353	380.928
481.48	352.426
482.608	361.424
483.735	347.422
484.86	371.92
485.987	336.418
487.114	311.416
488.238	345.913
489.365	334.911
490.491	334.409
491.615	337.907
492.741	350.905
493.865	339.403
494.991	330.901
496.114	345.899
497.24	334.897
498.363	355.895
499.489	365.893
500.612	351.391
501.737	333.889
502.859	373.387
503.982	348.885
505.104	342.383
506.229	359.381
507.351	357.879
508.473	371.377
509.595	342.375
510.719	360.872
511.841	367.37
512.962	318.368
514.084	321.866
515.205	337.864
516.326	363.862
517.447	352.36
518.568	304.858
519.689	360.356
520.809	333.354
521.93	325.352
523.05	354.85
524.17	321.848
525.29	324.846
526.41	395.844
527.53	374.342
528.648	349.34
529.767	384.838
530.887	349.336
532.006	330.833
533.123	347.331
534.242	332.329
535.361	364.827
536.477	367.325
537.596	389.323
538.715	353.821
539.831	334.819
540.949	337.817
542.065	359.815
543.183	344.313
544.298	355.311
545.416	345.809
546.531	338.307
547.649	411.805
548.764	345.803
549.879	328.301
550.996	357.299
552.111	374.797
553.225	309.795
554.34	351.793
555.456	338.79
556.571	353.288
557.685	354.786
558.799	370.284
559.912	383.282
561.028	315.28
562.142	338.278
563.255	335.276
564.369	374.274
565.482	338.272
566.595	354.77
567.708	340.768
568.82	362.766
569.933	339.264
571.045	371.762
572.156	388.26
573.268	383.758
574.38	392.256
575.492	374.754
576.604	358.252
577.713	307.249
578.825	366.247
579.936	353.245
581.048	344.743
582.157	378.241
583.268	314.239
584.379	339.737
585.487	342.235
586.598	349.733
587.706	359.231
588.817	345.729
589.925	386.227
591.035	327.225
592.143	331.723
593.253	351.721
594.36	339.219
595.468	349.217
596.577	359.215
597.684	341.713
598.792	375.711
599.901	379.708
601.007	350.206
602.114	391.704
603.221	373.702
604.329	343.7
605.436	386.198
606.542	310.196
607.648	351.194
608.754	361.192
609.859	328.19
610.965	334.188
612.07	348.686
613.176	371.184
614.281	342.682
615.386	370.18
616.491	310.678
617.596	325.176
618.701	344.674
619.805	369.672
620.908	384.656
622.012	309.14
623.116	334.124
624.22	329.108
625.322	335.093
626.426	361.577
627.53	396.061
628.631	357.545
629.734	369.029
630.838	366.014
631.939	382.998
633.042	350.982
634.143	338.466
635.245	371.451
636.346	323.935
637.448	375.919
638.549	337.403
639.651	355.387
640.751	333.372
641.851	366.856
642.953	317.34
644.052	344.324
645.152	348.808
646.253	354.793
647.352	341.277
648.452	334.761
649.55	342.245
650.649	318.229
651.75	356.714
652.849	300.698
653.947	353.682
655.045	391.666
656.144	360.651
657.242	353.635
658.34	351.119
659.437	330.103
660.535	360.587
661.633	357.572
662.73	347.556
663.825	371.04
664.922	337.024
666.019	340.008
667.116	356.993
668.213	347.477
669.308	306.461
670.404	353.945
671.5	362.929
672.597	349.414
673.691	332.898
674.787	342.382
675.88	377.366
676.976	401.351
678.072	373.335
679.165	346.319
680.261	360.303
681.354	374.287
682.449	364.272
683.542	372.657
684.634	388.919
685.729	367.75
686.822	345.736
687.914	358.054
689.008	329.5
690.1	374.022
691.192	339.344
692.286	350.016
693.378	373.86
694.469	315.909
695.561	368.971
696.652	345.394
697.743	347.588
698.834	341.692
699.925	349.046
701.016	348.974
702.109	351.769
703.197	366.05
704.288	368.772
705.378	359.864
706.468	357.394
707.558	346.945
708.648	357.976
709.738	355.971
710.828	332.378
711.915	337.878
713.005	342.861
714.094	347.175
715.183	354.925
716.27	350.831
717.359	355.794
718.448	331.7
719.534	361.029
720.623	348.836
721.709	353.525
722.797	330.84
723.885	352.055
724.971	380.666
726.057	345.429
727.145	351.981
728.23	350.318
729.318	339.26
730.403	336.425
731.488	357.753
732.575	354.205
733.66	323.472
734.745	361.528
735.832	367.063
736.77	351.455
737.867	381.436
738.964	367.916
740.061	346.897
741.158	344.377
742.255	320.358
743.352	350.338
744.446	342.819
745.542	349.299
746.639	366.78
747.735	342.26
748.831	369.241
749.925	349.221
751.02	350.702
752.116	331.682
753.209	326.663
754.305	346.643
755.4	351.124
756.493	340.104
757.588	326.085
758.683	360.565
759.776	331.546
760.87	375.026
761.963	352.007
763.057	376.987
764.149	352.968
765.241	367.448
766.335	388.929
767.427	319.909
768.521	406.39
769.612	352.87
770.703	349.851
771.797	370.331
772.888	340.312
773.979	347.792
775.07	350.273
776.162	373.253
777.253	343.234
778.343	382.215
779.434	378.695
780.524	347.676
781.614	344.656
782.704	306.637
783.794	375.617
784.883	325.598
785.973	313.578
787.063	353.059
788.152	352.039
789.241	355.52
790.33	322
791.419	348.981
792.508	357.961
793.596	309.942
794.685	309.922
795.771	378.403
796.86	388.883
797.948	350.364
799.036	346.844
799.58	360.334