File: DateTimeSpectrumPointNumber1.txt
#Acq. time (s)=	0.15444
#Accumulations=	3
#Range (cm-¹)=	-1230...1250
#Windows=	5
#Autofocus=	Off
#AutoExposure=	Off
#Spike filter=	Multiple accum.
#Delay time (s)=	0
#Binning=	1
#Readout mode=	Signal
#DeNoise=	Off
#ICS correction=	Off
#Dark correction=	Off
#Inst. Process=	Off
#Instrument=	LabRAM HR Evol
#Detector=	Emulator CCD
#Objective=	x100
#Grating=	1800 gr/mm
#ND Filter=	100%
#Laser (nm)=	512
#Slit=	150.001
#Hole=	70.0087
#Project=	A
#Sample=	B
#Site=	C
#Title=	D_60
#Remark=
#Date=	18.10.2017 14:24
#Acquired=	18.10.2017 14:24:01
-1229.32	437.5
-1227.24	473.017
-1225.16	424.034
-1223.09	449.55
-1221.01	418.067
-1218.94	416.084
-1216.86	456.101
-1214.79	396.117
-1212.72	405.134
-1210.64	444.651
-1208.57	440.168
-1206.5	453.684
-1204.43	437.201
-1202.36	419.218
-1200.29	446.235
-1198.22	424.251
-1196.15	418.268
-1194.08	427.285
-1192.01	398.302
-1189.95	404.818
-1187.88	406.335
-1185.81	389.352
-1183.75	405.369
-1181.68	414.385
-1179.62	424.902
-1177.55	431.419
-1175.49	419.936
-1173.43	396.952
-1171.36	396.469
-1169.3	411.486
-1167.24	385.503
-1165.18	454.019
-1163.12	422.536
-1161.06	419.553
-1159	393.57
-1156.94	428.586
-1154.88	395.603
-1152.82	401.62
-1150.77	415.137
-1148.71	397.653
-1146.65	448.67
-1144.6	385.187
-1142.54	410.204
-1140.49	425.72
-1138.44	429.237
-1136.38	425.754
-1134.33	416.271
-1132.28	436.287
-1130.22	399.304
-1128.17	429.321
-1126.12	381.838
-1124.07	396.854
-1122.02	391.371
-1119.97	407.888
-1117.92	375.905
-1115.88	413.921
-1113.83	373.938
-1111.78	391.455
-1109.73	401.972
-1107.69	444.988
-1105.64	401.005
-1103.6	388.022
-1101.55	408.539
-1099.51	391.555
-1097.46	396.072
-1095.42	394.089
-1093.38	417.106
-1091.34	449.122
-1089.3	370.139
-1087.25	389.156
-1085.21	394.673
-1083.17	388.189
-1081.14	434.206
-1079.1	376.223
-1077.06	398.24
-1075.02	405.256
-1072.98	372.773
-1070.95	440.79
-1068.91	410.307
-1066.88	440.323
-1064.84	412.34
-1062.81	424.357
-1060.77	396.374
-1058.74	397.89
-1056.7	401.407
-1054.67	396.424
-1052.64	380.441
-1050.61	431.957
-1048.58	404.474
-1046.55	394.991
-1044.52	425.008
-1042.49	424.024
-1040.46	394.041
-1038.43	399.058
-1036.4	382.575
-1034.38	363.591
-1032.35	384.608
-1030.32	360.625
-1028.3	377.142
-1026.27	362.658
-1024.25	384.175
-1022.22	400.692
-1020.2	365.709
-1018.18	359.225
-1016.15	391.742
-1014.13	408.759
-1012.11	355.776
-1010.09	390.793
-1008.07	378.809
-1006.05	396.326
-1004.03	409.343
-1002.01	355.86
-999.992	419.376
-997.974	365.893
-995.957	374.91
-993.94	379.927
-991.923	401.943
-989.908	366.96
-987.893	387.977
-985.878	385.494
-983.864	394.51
-981.85	394.527
-979.837	353.044
-977.824	386.061
-975.812	387.077
-973.801	356.094
-971.789	402.111
-969.779	392.128
-967.768	377.144
-965.759	381.161
-963.75	369.178
-961.741	417.195
-959.733	351.211
-957.725	349.228
-955.718	405.745
-953.712	386.762
-951.706	363.778
-949.701	396.795
-947.697	390.312
-945.691	373.829
-943.688	348.345
-941.684	387.362
-939.681	382.379
-937.679	389.896
-935.678	391.912
-933.676	387.929
-931.675	375.946
-929.675	394.463
-927.675	387.979
-925.676	370.496
-923.677	403.013
-921.679	372.53
-919.682	362.546
-917.684	381.563
-915.687	357.58
-913.692	359.597
-911.696	410.613
-909.701	405.63
-907.706	371.147
-905.712	375.664
-903.719	373.68
-901.726	394.697
-899.734	394.714
-897.741	352.731
-895.75	362.747
-893.758	399.264
-891.768	374.781
-889.778	380.298
-887.789	400.814
-885.799	353.831
-883.811	369.848
-881.823	345.865
-879.836	385.381
-877.849	402.898
-875.862	357.915
-873.877	375.932
-871.891	359.948
-869.907	383.965
-867.922	377.482
-865.939	374.999
-863.956	377.515
-861.973	352.532
-859.99	380.049
-858.009	411.566
-856.027	361.082
-854.046	352.599
-852.066	389.116
-850.086	384.133
-848.107	364.149
-846.128	338.166
-844.15	376.183
-842.173	342.2
-840.196	348.216
-838.219	384.233
-836.242	363.75
-834.267	417.267
-832.292	373.283
-830.317	343.8
-828.343	343.317
-826.37	355.334
-824.396	390.85
-822.424	364.867
-820.452	369.384
-818.48	356.901
-816.509	385.417
-814.539	375.934
-812.568	333.451
-810.6	373.968
-808.63	354.984
-806.662	388.001
-804.694	343.518
-802.727	374.535
-800.76	357.552
-798.793	359.068
-796.827	386.585
-794.861	342.602
-792.897	350.118
-790.932	343.635
-788.968	374.652
-787.004	348.169
-785.041	365.686
-783.079	344.702
-781.117	378.719
-779.156	378.736
-777.194	347.753
-775.235	336.769
-773.274	332.786
-771.316	337.803
-769.356	353.82
-767.398	377.836
-765.44	409.353
-763.483	370.87
-761.526	349.387
-759.57	361.403
-757.614	376.92
-755.658	327.937
-753.704	356.454
-751.749	361.47
-749.795	372.487
-747.842	380.004
-745.889	358.521
-743.936	368.037
-741.985	349.554
-740.034	355.071
-738.083	348.088
-736.133	351.104
-734.183	328.121
-732.233	365.638
-730.285	330.155
-728.337	361.171
-726.388	401.188
-724.441	363.705
-722.494	361.222
-720.549	366.238
-718.603	359.255
-716.657	327.272
-714.713	336.289
-712.768	341.305
-710.825	352.322
-708.882	334.339
-706.939	341.356
-704.997	347.372
-703.055	331.389
-701.113	327.406
-699.172	334.423
-697.233	369.439
-695.292	350.456
-693.354	335.473
-691.414	346.49
-689.476	381.006
-687.538	345.523
-685.601	360.04
-683.664	394.557
-681.729	357.573
-679.793	397.09
-677.857	356.607
-675.923	379.624
-673.989	326.64
-672.054	327.657
-670.121	354.674
-668.189	349.691
-666.256	361.707
-664.324	328.724
-662.394	356.241
-660.463	346.758
-658.532	344.774
-656.603	335.791
-654.674	361.308
-652.745	398.825
-650.816	354.841
-648.888	365.858
-646.962	351.375
-645.035	361.392
-643.108	402.408
-641.183	379.925
-639.258	364.442
-637.333	336.959
-635.408	363.975
-633.484	390.992
-631.561	390.509
-629.638	354.526
-627.716	360.542
-625.795	371.059
-623.873	344.576
-621.953	368.593
-620.032	324.109
-618.113	339.126
-616.194	325.631
-614.274	360.135
-612.356	324.62
-610.439	331.184
-608.521	342.045
-606.604	352.287
-604.687	349.67
-602.772	351.095
-600.857	356.22
-598.941	347.796
-597.027	368.233
-595.113	353.753
-593.2	340.121
-591.287	339.672
-589.375	327.567
-587.463	330.924
-585.552	357.597
-583.641	342.916
-581.731	327.208
-579.821	345.175
-577.912	356.015
-576.003	336.147
-574.094	336.614
-572.186	340.094
-570.278	369.396
-568.372	350.496
-566.465	339.162
-564.56	344.598
-562.654	355.34
-560.748	358.643
-558.844	365.011
-556.94	329.189
-555.037	336.039
-553.134	360.171
-551.469	391.434
-549.546	331.435
-547.624	372.437
-545.704	377.939
-543.783	335.941
-541.863	333.443
-539.942	341.944
-538.024	324.446
-536.105	323.448
-534.187	373.45
-532.269	345.451
-530.352	327.453
-528.434	362.955
-526.518	359.457
-524.601	348.458
-522.687	371.46
-520.771	376.962
-518.857	372.964
-516.943	363.966
-515.03	383.967
-513.116	379.969
-511.203	333.471
-509.292	358.473
-507.38	315.474
-505.469	377.976
-503.558	325.478
-501.648	349.98
-499.739	371.481
-497.829	332.483
-495.921	353.485
-494.013	337.987
-492.105	371.489
-490.198	315.99
-488.291	316.492
-486.384	319.494
-484.479	332.496
-482.573	339.497
-480.669	381.499
-478.764	321.501
-476.86	311.503
-474.957	332.504
-473.054	320.506
-471.151	343.508
-469.249	315.51
-467.348	364.512
-465.447	367.513
-463.546	325.515
-461.647	344.517
-459.746	380.519
-457.848	327.52
-455.949	371.022
-454.051	332.024
-452.154	345.526
-450.256	346.527
-448.359	357.029
-446.463	352.531
-444.568	337.533
-442.672	346.535
-440.778	398.536
-438.883	342.538
-436.989	344.54
-435.096	338.542
-433.203	339.043
-431.31	349.545
-429.418	336.047
-427.527	325.549
-425.636	317.55
-423.745	347.552
-421.856	312.554
-419.967	326.556
-418.077	333.558
-416.188	342.559
-414.3	342.561
-412.413	338.063
-410.525	312.565
-408.639	359.566
-406.753	342.568
-404.867	354.07
-402.982	346.572
-401.098	368.573
-399.212	339.575
-397.329	330.577
-395.445	343.579
-393.563	361.081
-391.68	344.582
-389.798	325.584
-387.917	362.586
-386.036	351.088
-384.156	379.089
-382.275	336.591
-380.396	340.093
-378.517	352.095
-376.638	313.596
-374.76	337.598
-372.882	342.6
-371.005	324.602
-369.129	325.104
-367.252	322.605
-365.376	345.107
-363.501	349.609
-361.627	345.611
-359.753	359.112
-357.879	328.114
-356.005	355.116
-354.132	363.118
-352.26	322.619
-350.387	332.621
-348.516	330.623
-346.645	351.625
-344.775	321.127
-342.904	366.128
-341.034	362.63
-339.165	328.132
-337.297	335.134
-335.428	336.135
-333.562	362.137
-331.694	350.139
-329.827	327.141
-327.961	322.142
-326.094	350.644
-324.229	398.146
-322.365	328.148
-320.5	332.65
-318.636	313.651
-316.773	353.653
-314.91	318.655
-313.048	341.657
-311.185	331.158
-309.324	373.66
-307.462	340.162
-305.602	382.164
-303.742	327.665
-301.882	354.167
-300.023	351.169
-298.164	328.671
-296.306	311.673
-294.447	308.674
-292.591	343.676
-290.733	350.178
-288.877	347.18
-287.022	307.681
-285.165	358.183
-283.31	316.185
-281.456	356.687
-279.603	349.688
-277.749	378.19
-275.895	369.192
-274.043	351.694
-272.19	350.696
-270.339	370.197
-268.488	312.699
-266.636	353.201
-264.786	382.203
-262.936	320.204
-261.087	320.706
-259.238	339.208
-257.389	334.21
-255.542	327.711
-253.694	337.713
-251.847	321.715
-250.001	356.217
-248.155	362.719
-246.309	359.22
-244.464	310.722
-242.619	324.724
-240.774	334.226
-238.93	325.727
-237.087	333.229
-235.245	350.231
-233.402	326.733
-231.56	379.734
-229.719	336.236
-227.878	378.738
-226.037	330.24
-224.197	343.242
-222.358	325.743
-220.518	370.745
-218.68	356.247
-216.841	311.749
-215.004	319.75
-213.167	308.752
-211.33	326.254
-209.494	343.256
-207.658	323.257
-205.822	373.259
-203.987	307.761
-202.153	352.263
-200.318	335.765
-198.485	315.766
-196.652	340.268
-194.82	377.27
-192.987	363.272
-191.156	315.773
-189.324	330.775
-187.493	313.777
-185.664	319.279
-183.833	317.78
-182.004	326.782
-180.174	316.784
-178.346	334.786
-176.518	358.788
-174.691	311.289
-172.864	346.791
-171.037	339.793
-169.211	325.295
-167.385	336.296
-165.561	316.798
-163.735	356.8
-161.911	332.802
-160.087	361.303
-158.264	360.305
-156.441	308.807
-154.618	337.809
-152.796	345.811
-150.975	342.812
-149.154	341.814
-147.334	318.816
-145.513	330.318
-143.693	367.819
-141.874	334.821
-140.055	329.323
-138.237	325.825
-136.419	320.826
-134.602	326.828
-132.785	365.33
-130.969	311.332
-129.152	342.834
-127.337	371.835
-125.522	338.837
-123.707	355.839
-121.893	312.341
-120.079	309.842
-118.266	313.344
-116.454	342.346
-114.641	365.848
-112.829	337.849
-111.017	346.851
-109.206	337.353
-107.396	304.855
-105.586	349.857
-103.776	347.358
-101.967	341.86
-100.159	328.862
-98.3503	335.364
-96.5431	328.865
-94.7351	347.867
-92.9285	324.369
-91.1223	347.371
-89.3165	325.872
-87.5109	339.374
-85.7057	355.876
-83.9008	381.378
-82.0975	340.38
-80.2933	350.381
-78.4905	323.883
-76.687	354.885
-74.885	347.387
-73.0832	333.388
-71.2819	322.89
-69.4808	311.392
-67.6813	337.894
-65.8809	312.895
-64.0808	344.397
-62.2823	319.899
-60.484	358.401
-58.685	358.903
-56.8874	352.904
-55.0902	343.906
-53.2933	326.908
-51.4967	308.91
-49.7016	324.911
-47.9057	369.413
-46.1113	360.415
-44.316	314.047
-42.5223	313.365
-40.7288	310.031
-38.9357	346.859
-37.143	316.02
-35.3505	330.445
-33.5584	348.262
-31.7678	344.33
-29.9763	346.793
-28.1863	338.023
-26.3967	321.424
-24.6062	365.342
-22.8173	342.836
-21.0286	321.368
-19.2414	360.539
-17.4534	352.847
-15.6658	337.587
-13.8796	335.027
-12.0926	327.932
-10.307	322.985
-8.52183	344.648
-6.73695	323.544
-4.9524	333.782
-3.16817	352.524
-1.38428	330.446
0.398132	340.544
2.18138	356.206
3.9643	333.624
5.7469	350.675
7.52684	343.974
9.30879	369.22
11.0881	338.128
12.8694	331.543
14.648	334.764
16.1311	339.152
17.9278	394.159
19.7264	329.666
21.5224	346.172
23.3204	367.179
25.118	346.185
26.913	332.192
28.7077	339.199
30.5043	334.705
32.2983	340.212
34.092	311.218
35.8853	343.725
37.6807	345.731
39.4733	325.238
41.2657	341.745
43.0577	350.251
44.8494	308.258
46.6407	340.764
48.4318	347.271
50.2202	361.278
52.0105	340.784
53.8006	331.791
55.588	316.297
57.3774	363.304
59.1664	327.811
60.9528	362.317
62.7412	347.824
64.527	339.83
66.3124	331.337
68.0998	327.843
69.8846	322.35
71.6691	319.857
73.4532	376.863
75.2393	370.37
77.0228	314.376
78.8059	337.883
80.5887	322.39
82.3712	306.396
84.1511	308.403
85.9329	332.909
87.7144	304.416
89.4956	353.422
91.2741	321.429
93.0547	303.436
94.8349	312.442
96.6124	308.449
98.392	304.455
100.169	310.462
101.948	307.469
103.724	351.475
105.5	338.482
107.276	330.488
109.053	329.495
110.828	320.502
112.603	342.508
114.377	358.515
116.151	330.021
117.925	309.528
119.698	310.534
121.469	340.541
123.242	324.548
125.014	324.054
126.786	315.561
128.556	330.067
130.327	313.574
132.096	339.581
133.866	325.587
135.635	342.594
137.405	307.6
139.172	341.607
140.939	343.614
142.709	362.62
144.475	329.127
146.241	307.633
148.007	369.14
149.773	343.146
151.538	328.153
153.303	323.16
155.068	323.166
156.832	309.673
158.593	348.179
160.357	319.186
162.12	359.193
163.881	331.199
165.644	318.206
167.406	344.712
169.166	366.719
170.928	335.225
172.687	312.732
174.446	381.239
176.206	349.245
177.964	331.752
179.722	344.758
181.48	324.765
183.237	330.272
184.994	332.778
186.75	330.285
188.507	370.291
190.263	324.798
192.018	335.805
193.773	362.811
195.526	333.818
197.281	331.824
199.035	362.831
200.787	311.837
202.54	324.844
204.292	322.851
206.042	318.857
207.795	370.864
209.545	334.87
211.295	332.877
213.047	310.884
214.796	334.89
216.545	333.897
218.293	339.903
220.042	319.91
221.789	354.417
223.537	304.923
225.284	316.43
227.029	340.936
228.776	380.943
230.522	314.949
232.268	331.456
234.012	310.963
235.757	332.969
237.5	317.976
239.244	329.482
240.987	371.989
242.729	325.996
244.472	362.002
246.214	344.009
247.954	316.015
249.695	335.022
251.435	343.028
253.175	356.035
254.915	343.042
256.654	325.048
258.393	308.055
260.132	334.061
261.87	338.068
263.606	305.075
265.344	364.581
267.082	330.588
268.816	320.094
270.553	364.101
272.287	372.108
274.024	305.114
275.757	322.621
277.491	351.627
279.226	334.134
280.959	309.14
282.691	331.647
284.423	349.154
286.155	325.66
287.886	315.167
289.617	362.173
291.348	335.18
293.079	365.187
294.807	326.193
296.537	347.2
298.266	316.706
299.993	326.213
301.722	345.22
303.451	306.226
305.177	327.733
306.903	306.239
308.63	328.746
310.356	355.252
312.08	332.259
313.807	318.766
315.531	320.272
317.255	321.779
318.979	356.785
320.702	314.292
322.425	358.799
324.148	313.305
325.87	315.312
327.59	365.318
329.312	358.325
331.033	323.331
332.752	356.838
334.473	350.845
336.191	322.851
337.911	341.858
339.629	344.364
341.349	309.871
343.066	321.878
344.782	326.384
346.499	335.891
348.217	343.397
349.933	365.404
351.649	334.411
353.364	361.417
355.079	361.424
356.793	346.43
358.505	346.437
360.219	337.943
361.933	366.95
363.646	334.457
365.357	352.463
367.07	323.47
368.78	320.476
370.492	344.483
372.202	322.49
373.913	338.496
375.622	323.503
377.331	319.509
379.039	345.516
380.747	355.522
382.455	319.529
384.165	345.036
385.872	308.542
387.577	315.549
389.283	338.555
390.989	305.562
392.695	372.069
394.401	315.575
396.104	324.582
397.809	330.588
399.511	364.595
401.216	338.102
402.918	359.108
404.622	335.615
406.323	327.121
408.024	350.628
409.727	307.134
411.427	322.141
413.127	333.148
414.827	337.654
416.526	310.661
418.225	320.667
419.924	336.674
421.623	307.681
423.321	310.687
425.017	308.694
426.714	323.7
428.412	335.707
430.107	375.714
431.803	354.72
433.498	332.727
435.194	337.733
436.887	342.24
438.581	367.246
440.276	333.753
441.969	364.76
443.661	332.766
445.353	335.273
447.045	330.779
448.736	361.286
450.428	357.793
452.119	352.299
453.809	336.806
455.497	332.812
457.187	357.319
458.877	331.325
460.564	335.832
462.253	306.839
463.94	317.845
465.628	336.852
467.314	341.358
469.002	338.365
470.688	340.872
472.373	359.878
474.058	336.885
475.742	322.891
477.426	338.898
479.11	327.905
480.794	322.911
482.477	341.418
484.16	346.424
485.843	332.431
487.525	345.937
489.205	371.944
490.887	331.951
492.569	363.457
494.248	324.788
495.926	312.365
497.607	310.582
499.285	365.865
500.965	337.996
502.643	308.361
504.32	362.847
505.997	334.873
507.674	342.959
509.35	348.039
511.026	339.816
512.702	339.043
514.377	319.7
516.052	329.088
517.725	366.73
519.4	341.089
521.074	334.439
522.746	332.609
524.42	329.615
526.091	327.596
527.764	312.299
529.435	349.492
531.105	343.703
532.777	363.801
534.447	321.474
536.116	309.739
537.785	342.917
539.454	322.384
541.123	340.507
542.791	359.087
544.459	316.29
546.127	326.81
547.792	350.722
549.094	318.278
550.781	335.268
552.465	388.259
554.149	378.749
555.832	323.739
557.516	344.229
559.198	352.219
560.881	340.209
562.563	347.2
564.246	327.19
565.927	305.18
567.607	343.17
569.288	362.16
570.969	337.15
572.647	318.14
574.327	341.131
576.005	370.121
577.685	358.111
579.362	356.101
581.041	321.091
582.718	359.081
584.394	360.071
586.07	307.062
587.746	311.552
589.423	319.042
591.099	334.032
592.773	325.522
594.448	366.012
596.12	336.002
597.794	331.993
599.468	319.983
601.141	322.473
602.812	324.963
604.484	303.453
606.157	385.943
607.827	333.933
609.499	333.424
611.168	361.414
612.839	323.904
614.508	310.894
616.177	350.384
617.845	362.374
619.515	324.365
621.183	350.355
622.85	339.845
624.517	347.335
626.184	362.325
627.85	347.815
629.516	322.805
631.182	328.796
632.846	327.286
634.511	329.776
636.176	330.766
637.838	326.756
639.503	332.246
641.165	334.236
642.829	335.727
644.49	346.217
646.153	305.707
647.814	309.697
649.474	328.187
651.137	309.677
652.797	346.667
654.456	354.158
656.115	344.148
657.774	358.638
659.433	310.628
661.092	325.618
662.75	315.608
664.405	308.598
666.063	310.589
667.72	337.079
669.377	338.569
671.032	331.559
672.688	318.549
674.342	321.539
675.998	342.529
677.651	304.52
679.304	316.51
680.959	307.5
682.611	331.49
684.264	332.48
685.916	349.47
687.567	329.46
689.218	350.451
690.869	309.441
692.52	310.931
694.171	358.421
695.821	363.411
697.471	304.401
699.12	375.391
700.767	322.382
702.416	317.372
704.063	374.362
705.711	305.352
707.357	342.342
709.005	319.332
710.651	320.323
712.298	318.813
713.943	334.803
715.587	326.293
717.231	341.783
718.875	321.273
720.519	324.263
722.162	343.754
723.805	333.244
725.448	335.734
727.091	344.724
728.733	309.214
730.375	351.204
732.014	326.194
733.656	335.185
735.297	322.175
736.936	316.665
738.576	307.155
740.214	356.645
741.852	308.635
743.492	305.125
745.129	329.616
746.766	321.106
748.402	336.596
750.039	337.086
751.675	301.076
753.311	370.066
754.946	323.056
756.581	335.547
758.216	320.037
759.851	337.527
761.485	311.017
763.117	307.007
764.751	359.997
766.385	339.987
768.016	317.978
769.649	323.968
771.279	347.458
772.909	343.948
774.541	346.438
776.171	358.928
777.8	339.419
779.43	321.909
781.06	307.899
782.689	346.889
784.317	337.379
785.945	314.869
787.571	338.369
789.198	339.888
790.825	317.407
792.452	325.926
794.079	338.445
795.703	375.464
797.329	304.983
798.952	316.502
800.578	328.021
802.201	349.04
803.826	363.059
805.448	319.078
807.07	310.097
808.692	307.616
810.316	320.635
811.937	353.154
813.558	345.173
815.179	354.692
816.799	330.711
818.417	349.23
820.037	324.749
821.657	349.768
823.276	322.287
824.893	311.306
826.512	337.325
828.13	301.344
829.747	350.863
831.365	330.382
832.98	346.901
834.595	332.42
836.212	359.439
837.827	322.958
839.442	303.477
841.056	376.496
842.67	338.515
844.283	318.533
845.896	330.052
847.509	355.571
849.122	332.09
850.735	310.609
852.347	332.628
853.957	310.647
855.568	313.666
857.18	322.685
858.789	318.704
860.399	356.723
862.008	346.742
863.618	325.761
865.226	311.78
866.833	347.799
868.441	317.818
870.05	308.337
871.657	311.856
873.263	353.875
874.869	355.394
876.475	336.913
878.081	324.932
879.684	322.951
881.289	370.47
882.894	347.989
884.498	343.008
886.101	346.027
887.704	306.046
889.306	351.565
890.909	340.584
892.51	320.103
894.111	328.622
895.714	334.641
897.314	318.16
898.914	315.679
900.514	318.698
902.113	339.717
903.712	330.236
905.311	336.255
906.909	317.774
908.508	325.293
910.106	303.312
911.703	351.331
913.299	376.85
914.896	304.369
916.493	306.388
918.087	335.407
919.684	326.426
921.278	337.445
922.871	338.464
924.467	349.483
926.06	365.502
927.653	368.521
929.246	338.54
930.838	337.559
932.43	317.578
934.022	318.597
935.613	352.116
937.205	305.635
938.795	328.654
940.386	314.673
941.974	320.692
943.565	331.711
945.155	306.73
946.742	332.249
948.331	317.768
949.918	363.787
951.507	355.806
953.094	340.825
954.68	329.844
956.266	360.862
957.851	332.882
959.439	314.9
961.024	347.919
962.608	362.938
964.193	387.957
965.775	387.476
967.359	335.495
968.943	358.514
970.526	334.533
972.107	325.052
973.69	309.071
975.271	362.09
976.853	327.109
978.433	341.128
980.015	304.147
981.594	376.166
983.174	332.685
984.755	335.204
986.333	342.223
987.912	345.742
989.49	349.261
991.068	381.28
992.645	387.799
994.222	373.326
995.797	308.228
997.374	325.806
998.951	313.656
1000.52	362.835
1002.1	348.808
1003.68	320.985
1005.25	330.426
1006.82	351.757
1008.4	331.278
1009.97	318.365
1011.54	352.312
1013.12	367.218
1014.69	335.231
1016.26	337.527
1017.83	324.587
1019.4	326.995
1020.97	320.775
1022.54	336.1
1024.11	316.14
1025.68	331.517
1027.25	328.572
1028.82	320.975
1030.39	330.555
1031.95	347.223
1033.52	327.394
1035.09	341.768
1036.66	346.877
1038.22	331.844
1039.79	347.252
1041.35	356.453
1042.92	346.797
1044.48	347.833
1046.05	364.793
1047.61	317.688
1049.17	331.178
1050.27	369.098
1051.85	315.067
1053.43	349.536
1055.01	368.006
1056.59	320.975
1058.17	314.944
1059.75	322.914
1061.32	346.883
1062.91	351.352
1064.48	329.322
1066.06	384.791
1067.64	338.26
1069.22	375.73
1070.79	355.699
1072.37	349.168
1073.94	338.638
1075.52	350.607
1077.09	344.076
1078.67	345.045
1080.24	367.515
1081.82	350.984
1083.39	305.453
1084.96	337.423
1086.54	400.392
1088.11	311.861
1089.68	303.331
1091.25	318.8
1092.83	337.269
1094.4	325.739
1095.97	316.208
1097.54	319.177
1099.11	364.646
1100.68	353.116
1102.25	318.085
1103.82	329.554
1105.38	316.024
1106.95	354.993
1108.52	325.962
1110.08	331.932
1111.65	339.901
1113.22	322.87
1114.79	324.34
1116.35	303.809
1117.92	309.278
1119.48	309.248
1121.05	353.717
1122.61	321.686
1124.17	382.655
1125.74	359.125
1127.3	344.594
1128.86	310.563
1130.43	315.533
1131.99	332.502
1133.55	356.971
1135.11	321.941
1136.67	353.41
1138.23	336.879
1139.79	321.349
1141.35	356.318
1142.91	336.287
1144.47	321.757
1146.03	318.726
1147.59	320.195
1149.15	325.664
1150.7	359.634
1152.26	310.103
1153.82	366.572
1155.38	341.042
1156.93	346.511
1158.49	326.98
1160.04	390.45
1161.6	339.919
1163.15	315.888
1164.7	331.858
1166.26	314.827
1167.81	347.296
1169.37	344.765
1170.92	303.735
1172.47	364.704
1174.02	353.673
1175.58	348.143
1177.13	306.612
1178.68	354.581
1180.23	349.551
1181.78	326.02
1183.33	371.489
1184.88	319.459
1186.42	326.928
1187.97	346.397
1189.52	348.367
1191.07	364.336
1192.62	380.805
1194.17	323.274
1195.71	333.244
1197.26	325.213
1198.8	347.182
1200.35	330.152
1201.9	337.621
1203.44	392.09
1204.98	306.06
1206.53	343.029
1208.07	309.998
1209.62	314.968
1211.16	318.437
1212.7	346.906
1214.25	339.375
1215.79	351.845
1217.33	319.814
1218.87	331.283
1220.41	329.753
1221.95	329.722
1223.49	334.691
1225.03	366.161
1226.57	304.63
1228.11	362.599
1229.65	355.569
1231.19	325.038
1232.72	372.007
1234.26	381.477
1235.8	323.446
1237.34	322.415
1238.87	321.884
1240.41	334.854
1241.95	353.823
1243.48	346.792
1245.02	310.262
1246.55	345.731
1248.08	317.2
1249.62	335.17