File: DateTimeSpectrumPointNumber1.txt
#Acq. time (s)=	0.5
#Accumulations=	2
#Range (cm-¹)=	1500...4500
#Windows=	9
#Autofocus=	Off
#AutoExposure=	Off
#Spike filter=	Multiple accum.
#Delay time (s)=	0
#Binning=	1
#Readout mode=	Signal
#DeNoise=	Off
#ICS correction=	Off
#Dark correction=	Off
#Inst. Process=	Off
#Instrument=	LabRAM HR Evol
#Detector=	Emulator CCD
#Objective=	x100
#Grating=	1800 gr/mm
#ND Filter=	100%
#Laser (nm)=	512
#Slit=	150.001
#Hole=	70.0087
#Project=	A
#Sample=	B
#Site=	C
#Title=	D_1
#Remark=
#Date=	23.10.2017 15:48
#Acquired=	23.10.2017 15:48:11
1500.39	351
1503.38	345.027
1506.36	383.053
1509.34	402.08
1512.32	354.107
1515.3	336.133
1518.28	358.16
1521.25	423.187
1524.23	383.213
1527.2	388.24
1530.17	386.267
1533.14	352.293
1536.11	417.32
1539.08	357.347
1542.04	361.373
1545.01	341.4
1547.97	372.427
1550.93	383.453
1553.89	386.48
1556.85	367.507
1559.81	417.533
1562.76	365.56
1565.72	395.587
1568.67	351.613
1571.62	390.64
1574.58	360.667
1577.52	376.693
1580.47	369.72
1583.42	366.747
1586.36	355.773
1589.31	440.8
1592.25	390.827
1595.19	429.853
1598.13	355.88
1601.07	419.907
1604	403.934
1606.94	406.96
1609.88	421.987
1612.81	399.013
1615.74	362.04
1618.67	363.067
1621.6	398.094
1624.52	381.12
1627.45	358.147
1630.37	440.174
1633.3	388.2
1636.22	360.227
1639.14	361.254
1642.06	366.28
1644.98	409.307
1647.89	376.334
1650.81	369.36
1653.72	363.387
1656.63	373.414
1659.54	398.44
1662.45	379.467
1665.36	381.494
1668.27	409.52
1671.17	371.547
1674.08	392.574
1676.98	387.6
1679.88	433.627
1682.78	389.654
1685.68	388.68
1688.58	384.707
1691.47	376.734
1694.37	455.76
1697.26	390.787
1700.15	412.814
1703.04	380.84
1705.93	378.867
1708.82	398.894
1711.7	409.92
1714.59	390.947
1717.47	390.974
1720.36	395
1723.24	443.027
1726.12	397.054
1728.99	407.08
1731.87	445.107
1734.74	388.134
1737.62	458.16
1740.49	411.187
1743.36	404.214
1746.23	462.24
1749.1	403.267
1751.97	424.294
1754.84	432.32
1757.7	464.347
1760.56	400.374
1763.43	419.4
1766.29	434.427
1769.15	440.454
1772	420.48
1774.86	405.507
1777.71	471.534
1780.57	444.56
1783.42	425.587
1786.27	469.614
1789.12	474.64
1791.97	493.667
1794.82	410.694
1797.66	455.72
1800.51	448.747
1803.35	430.774
1806.19	446.8
1809.03	426.827
1811.87	438.854
1814.71	470.88
1817.55	422.907
1820.38	442.934
1823.21	469.96
1826.05	478.987
1828.88	452.014
1831.71	514.04
1834.53	491.067
1837.36	470.094
1840.19	448.12
1843.01	441.147
1845.84	456.174
1848.66	461.2
1851.48	456.227
1854.3	454.254
1857.11	498.281
1859.93	504.307
1862.74	442.334
1865.56	443.361
1868.37	468.387
1871.18	467.414
1873.99	450.441
1876.8	450.467
1879.61	476.494
1882.41	472.521
1885.22	506.547
1888.02	453.574
1890.82	498.601
1893.62	475.627
1896.42	477.654
1899.22	520.681
1902.01	466.707
1904.81	521.734
1907.6	478.761
1910.4	503.787
1913.19	533.814
1915.98	504.841
1918.77	508.867
1921.55	508.894
1924.34	476.921
1927.12	482.947
1929.91	527.974
1932.69	495.001
1935.47	482.027
1938.25	516.054
1941.02	508.081
1943.8	543.911
1946.58	561.663
1949.35	508.362
1952.12	521.61
1954.89	532.604
1957.66	530.177
1960.43	510.108
1963.2	534.325
1965.97	545.363
1968.73	540.049
1971.49	551.588
1974.26	566.321
1977.02	522.851
1979.78	563.386
1982.54	526.992
1985.29	556.973
1988.05	564.912
1990.72	525.151
1993.51	529.161
1996.3	522.17
1999.08	592.18
2001.87	531.189
2004.65	565.199
2007.43	527.209
2010.21	537.218
2012.99	567.228
2015.77	583.238
2018.54	593.247
2021.32	568.257
2024.09	577.266
2026.86	569.276
2029.63	586.286
2032.4	564.295
2035.17	556.305
2037.94	575.314
2040.71	590.324
2043.47	562.334
2046.23	584.343
2049	593.353
2051.76	589.363
2054.52	574.372
2057.27	579.382
2060.03	576.392
2062.78	591.401
2065.54	576.411
2068.29	574.42
2071.04	575.43
2073.79	608.44
2076.55	591.449
2079.29	625.459
2082.04	597.469
2084.78	613.478
2087.53	587.488
2090.27	613.497
2093.01	602.507
2095.75	623.517
2098.49	619.526
2101.23	609.536
2103.97	630.546
2106.7	629.555
2109.44	607.565
2112.17	644.574
2114.9	633.584
2117.63	642.594
2120.36	612.603
2123.09	637.613
2125.81	631.622
2128.54	629.632
2131.26	639.642
2133.99	718.651
2136.71	685.661
2139.43	701.671
2142.15	696.68
2144.86	669.69
2147.58	645.7
2150.3	664.709
2153.01	649.719
2155.72	669.728
2158.43	664.738
2161.14	660.748
2163.85	677.757
2166.56	679.767
2169.26	742.776
2171.97	695.786
2174.67	674.796
2177.38	679.805
2180.08	719.815
2182.78	669.825
2185.48	707.834
2188.17	754.844
2190.87	706.853
2193.56	682.863
2196.26	706.873
2198.95	718.882
2201.64	771.892
2204.33	689.902
2207.02	728.911
2209.71	710.921
2212.4	725.93
2215.08	786.94
2217.76	750.95
2220.45	708.959
2223.13	760.969
2225.81	725.979
2228.49	712.988
2231.16	760.998
2233.84	723.007
2236.51	774.017
2239.19	720.027
2241.86	756.036
2244.53	778.046
2247.2	755.056
2249.87	743.065
2252.54	768.075
2255.2	809.084
2257.87	739.094
2260.53	832.104
2263.2	745.113
2265.86	828.123
2268.52	756.133
2271.18	814.142
2273.83	774.152
2276.49	789.161
2279.14	803.171
2281.8	802.181
2284.45	788.19
2287.1	827.2
2289.75	798.21
2292.4	782.219
2295.05	873.229
2297.7	857.238
2300.34	819.248
2302.99	829.258
2305.63	786.267
2308.27	832.277
2310.91	844.287
2313.55	843.296
2316.19	815.306
2318.82	851.315
2321.46	835.325
2324.09	805.335
2326.72	842.344
2329.36	823.354
2331.99	818.364
2334.62	847.373
2337.25	855.383
2339.87	840.392
2342.5	825.402
2345.12	872.412
2347.74	838.421
2350.37	855.431
2352.99	863.441
2355.61	873.45
2358.23	873.46
2360.84	891.141
2363.46	848.879
2366.07	887.723
2368.68	864.264
2371.3	862.334
2373.91	881.092
2376.52	915.44
2379.12	931.055
2381.73	878.58
2384.34	893.987
2386.94	924.61
2389.55	928.954
2392.15	913.023
2394.75	898.125
2397.35	937.755
2399.95	911.594
2402.55	934.902
2404.97	926.394
2407.6	921.424
2410.23	972.454
2412.86	918.484
2415.48	925.514
2418.1	905.544
2420.73	986.574
2423.35	923.604
2425.97	921.634
2428.59	926.664
2431.2	939.694
2433.82	977.724
2436.44	956.754
2439.05	923.784
2441.67	924.814
2444.28	939.844
2446.89	981.874
2449.5	949.904
2452.1	968.934
2454.71	937.964
2457.32	956.994
2459.92	1007.02
2462.53	1003.05
2465.13	964.084
2467.73	1006.11
2470.33	974.144
2472.93	959.174
2475.53	992.204
2478.12	996.234
2480.72	1001.26
2483.31	994.294
2485.91	994.324
2488.5	1024.35
2491.09	1033.38
2493.68	1056.41
2496.26	997.444
2498.85	981.474
2501.44	1040.5
2504.02	1017.53
2506.61	1032.56
2509.19	1046.59
2511.77	993.624
2514.35	1014.65
2516.93	1028.68
2519.51	1053.71
2522.08	1039.74
2524.66	1014.77
2527.23	1082.8
2529.81	1054.83
2532.38	1030.86
2534.95	1066.89
2537.52	1019.92
2540.08	1093.95
2542.65	1035.98
2545.22	1046.01
2547.78	1027.04
2550.35	1032.07
2552.91	1048.1
2555.47	1056.13
2558.03	1045.16
2560.59	1069.19
2563.15	1118.22
2565.7	1076.25
2568.26	1062.28
2570.81	1053.31
2573.36	1058.34
2575.91	1088.37
2578.47	1074.4
2581.02	1065.43
2583.56	1065.46
2586.11	1112.49
2588.66	1082.52
2591.2	1078.55
2593.74	1128.58
2596.29	1079.61
2598.83	1072.64
2601.37	1079.67
2603.91	1127.7
2606.44	1095.73
2608.98	1082.76
2611.52	1134.79
2614.05	1085.82
2616.58	1090.85
2619.12	1102.88
2621.65	1091.91
2624.18	1091.94
2626.71	1106.97
2629.23	1094
2631.76	1152.03
2634.28	1120.06
2636.81	1188.09
2639.33	1150.12
2641.85	1153.15
2644.37	1111.18
2646.89	1142.21
2649.41	1149.24
2651.92	1148.27
2654.44	1145.3
2656.95	1122.33
2659.47	1129.36
2661.98	1185.39
2664.49	1129.42
2667	1196.45
2669.51	1145.48
2672.02	1130.51
2674.52	1156.54
2677.03	1171.57
2679.53	1136.6
2682.04	1199.63
2684.54	1182.66
2687.04	1165.69
2689.54	1161.72
2692.04	1195.75
2694.53	1202.78
2697.03	1188.81
2699.52	1196.84
2702.02	1173.87
2704.51	1187.9
2707	1167.93
2709.49	1190.96
2711.98	1160.99
2714.47	1154.02
2716.96	1150.05
2719.44	1181.08
2721.93	1233.11
2724.41	1193.14
2726.89	1178.17
2729.37	1178.2
2731.85	1175.23
2734.33	1173.26
2736.81	1167.29
2739.29	1167.32
2741.76	1202.35
2744.24	1167.38
2746.71	1252.41
2749.18	1188.44
2751.65	1197.47
2754.12	1235.76
2756.59	1174.53
2759.06	1168.95
2761.52	1190.28
2763.99	1223.53
2766.45	1196.17
2768.91	1223.91
2771.38	1234.65
2773.84	1198.91
2776.3	1208.13
2778.75	1225.81
2781.21	1206.69
2783.67	1204.29
2786.12	1229.79
2788.58	1208.15
2791.03	1204.33
2793.48	1214.95
2795.66	1248.57
2798.14	1230.59
2800.62	1190.61
2803.1	1212.63
2805.58	1238.65
2808.06	1182.67
2810.53	1268.69
2813.01	1191.71
2815.48	1180.73
2817.96	1210.75
2820.43	1181.77
2822.9	1182.79
2825.37	1181.8
2827.84	1190.82
2830.31	1196.84
2832.77	1239.86
2835.24	1211.88
2837.7	1205.9
2840.17	1186.92
2842.63	1235.94
2845.09	1194.96
2847.55	1213.98
2850.01	1228
2852.47	1250.02
2854.92	1186.04
2857.38	1200.06
2859.83	1223.08
2862.29	1199.1
2864.74	1187.12
2867.19	1194.14
2869.64	1216.16
2872.09	1259.18
2874.53	1209.2
2876.98	1266.22
2879.43	1237.24
2881.87	1218.26
2884.31	1201.28
2886.76	1187.3
2889.2	1215.32
2891.64	1235.34
2894.08	1214.36
2896.51	1187.38
2898.95	1247.4
2901.39	1227.42
2903.82	1230.44
2906.26	1200.46
2908.69	1196.48
2911.12	1223.5
2913.55	1220.52
2915.98	1241.54
2918.41	1186.56
2920.83	1236.58
2923.26	1180.6
2925.68	1181.62
2928.11	1210.64
2930.53	1208.66
2932.95	1187.68
2935.37	1208.7
2937.79	1180.72
2940.21	1239.74
2942.62	1209.76
2945.04	1183.78
2947.46	1229.8
2949.87	1178.82
2952.28	1176.84
2954.69	1189.86
2957.1	1179.88
2959.51	1195.9
2961.92	1181.92
2964.33	1171.94
2966.73	1217.96
2969.14	1191.98
2971.54	1210
2973.95	1194.02
2976.35	1177.04
2978.75	1162.06
2981.15	1194.08
2983.55	1225.1
2985.94	1165.12
2988.34	1233.14
2990.73	1218.16
2993.13	1158.18
2995.52	1215.2
2997.91	1196.22
3000.3	1229.24
3002.69	1198.26
3005.08	1198.28
3007.47	1182.29
3009.86	1170.31
3012.24	1228.33
3014.63	1160.35
3017.01	1183.37
3019.39	1173.39
3021.77	1212.41
3024.15	1189.43
3026.53	1143.45
3028.91	1174.47
3031.29	1194.49
3033.66	1191.51
3036.04	1143.53
3038.41	1175.55
3040.78	1182.57
3043.15	1129.59
3045.52	1194.61
3047.89	1190.63
3050.26	1137.65
3052.63	1126.67
3054.99	1155.69
3057.36	1178.71
3059.72	1139.73
3062.08	1148.75
3064.45	1151.77
3066.81	1123.79
3069.17	1133.81
3071.53	1121.83
3073.88	1123.85
3076.24	1166.87
3078.59	1120.89
3080.95	1117.91
3083.3	1134.93
3085.65	1137.95
3088	1131.97
3090.35	1128.99
3092.7	1117.01
3095.05	1100.03
3097.4	1127.05
3099.74	1158.07
3102.09	1145.09
3104.43	1144.11
3106.77	1152.13
3109.11	1125.15
3111.45	1122.17
3113.79	1148.19
3116.13	1086.21
3118.47	1081.23
3120.8	1073.25
3123.14	1074.55
3125.47	1075.02
3127.8	1082.6
3130.14	1117.79
3132.47	1071.85
3134.8	1113.81
3137.12	1065.86
3139.45	1077.73
3141.78	1065.8
3144.1	1093.82
3146.43	1070.99
3148.75	1076.8
3151.07	1111.83
3153.39	1068.16
3155.71	1059.38
3158.03	1081.07
3160.35	1062.31
3162.67	1064.53
3164.84	1034.45
3167.18	1033.48
3169.53	1059.51
3171.87	1094.53
3174.22	1049.56
3176.56	1021.59
3178.9	1069.61
3181.24	1030.64
3183.58	1029.67
3185.92	1054.69
3188.26	1013.72
3190.59	1052.75
3192.93	1009.77
3195.26	1052.8
3197.59	1051.83
3199.93	1048.85
3202.26	1071.88
3204.59	1008.91
3206.92	1004.93
3209.24	1035.96
3211.57	1025.99
3213.9	998.012
3216.22	1018.04
3218.54	984.065
3220.87	1013.09
3223.19	996.118
3225.51	1031.14
3227.83	1006.17
3230.15	1044.2
3232.46	962.224
3234.78	1047.25
3237.1	988.278
3239.41	998.304
3241.72	990.331
3244.04	965.357
3246.35	995.384
3248.66	1017.41
3250.97	945.437
3253.27	962.463
3255.58	979.49
3257.89	957.516
3260.19	1008.54
3262.5	961.57
3264.8	1006.6
3267.1	939.623
3269.4	923.649
3271.7	1011.68
3274	939.702
3276.3	960.729
3278.6	919.755
3280.89	916.782
3283.19	954.809
3285.48	973.835
3287.77	914.862
3290.07	911.888
3292.36	901.915
3294.64	917.941
3296.93	923.968
3299.22	936.994
3301.51	895.021
3303.79	889.048
3306.08	883.074
3308.36	938.101
3310.64	928.127
3312.93	923.154
3315.21	912.18
3317.48	873.207
3319.76	907.233
3322.04	900.26
3324.32	889.286
3326.59	865.313
3328.87	907.34
3331.14	919.366
3333.41	883.393
3335.68	900.419
3337.95	872.446
3340.22	912.472
3342.49	842.499
3344.76	887.525
3347.02	835.552
3349.29	915.579
3351.55	832.605
3353.82	899.632
3356.08	859.658
3358.34	831.685
3360.6	903.711
3362.86	826.738
3365.12	853.764
3367.37	862.791
3369.63	826.818
3371.88	835.844
3374.14	837.871
3376.39	828.897
3378.64	818.924
3380.89	796.95
3383.14	852.977
3385.39	813.003
3387.64	861.03
3389.89	805.057
3392.13	809.083
3394.38	784.11
3396.62	815.136
3398.87	867.163
3401.11	801.189
3403.35	864.216
3405.59	811.242
3407.83	783.269
3410.06	846.295
3412.3	786.322
3414.54	766.349
3416.77	792.375
3419.01	835.402
3421.24	762.428
3423.47	819.455
3425.7	805.481
3427.93	789.508
3430.16	755.534
3432.39	785.561
3434.61	740.588
3436.84	738.614
3439.06	771.641
3441.29	755.667
3443.51	749.694
3445.73	784.72
3447.95	735.747
3450.17	730.773
3452.39	772.8
3454.61	787.826
3456.82	710.853
3459.04	729.88
3461.25	744.906
3463.47	716.933
3465.68	755.959
3467.89	724.986
3470.1	703.012
3472.31	710.073
3474.52	750.115
3476.73	708.591
3478.94	717.767
3481.14	703.63
3483.35	682.658
3485.55	711.282
3487.75	694.063
3489.95	699.439
3492.15	703.328
3494.35	693.512
3496.55	699.499
3498.75	699.589
3500.95	673.867
3503.14	731.349
3505.34	680.039
3507.53	660.395
3509.72	674.311
3511.68	687.823
3513.9	734.804
3516.12	668.784
3518.34	676.765
3520.56	704.745
3522.78	675.726
3525	637.706
3527.21	671.687
3529.43	681.667
3531.64	638.647
3533.86	629.628
3536.07	668.608
3538.28	679.589
3540.49	641.569
3542.7	617.55
3544.91	618.53
3547.11	691.511
3549.32	673.491
3551.52	634.471
3553.73	625.452
3555.93	653.432
3558.13	676.413
3560.34	631.393
3562.54	595.374
3564.74	601.354
3566.93	636.335
3569.13	646.315
3571.33	619.295
3573.52	625.276
3575.72	653.256
3577.91	648.237
3580.1	634.217
3582.3	637.198
3584.49	630.178
3586.68	622.159
3588.87	592.139
3591.05	581.12
3593.24	598.1
3595.43	597.08
3597.61	584.061
3599.79	562.041
3601.98	569.022
3604.16	638.002
3606.34	629.983
3608.52	562.963
3610.7	554.944
3612.88	568.924
3615.06	573.904
3617.23	554.885
3619.41	581.865
3621.58	572.846
3623.75	590.826
3625.93	572.807
3628.1	570.787
3630.27	569.768
3632.44	555.748
3634.61	596.728
3636.77	594.709
3638.94	526.689
3641.11	528.67
3643.27	552.65
3645.43	533.631
3647.6	539.611
3649.76	549.592
3651.92	520.572
3654.08	529.552
3656.24	546.533
3658.4	513.513
3660.55	559.494
3662.71	523.474
3664.87	596.455
3667.02	570.435
3669.17	517.416
3671.32	534.396
3673.48	539.377
3675.63	533.357
3677.78	510.337
3679.92	510.318
3682.07	494.298
3684.22	491.279
3686.36	507.259
3688.51	487.24
3690.65	521.22
3692.79	570.201
3694.93	536.181
3697.08	486.161
3699.22	526.142
3701.35	493.122
3703.49	484.103
3705.63	514.083
3707.77	522.064
3709.9	491.044
3712.03	477.025
3714.17	488.005
3716.3	503.985
3718.43	527.966
3720.56	474.946
3722.69	479.927
3724.82	482.907
3726.95	516.888
3729.07	502.868
3731.2	490.849
3733.32	495.829
3735.45	514.81
3737.57	498.79
3739.69	464.77
3741.81	454.751
3743.93	546.731
3746.05	511.712
3748.17	467.692
3750.28	484.673
3752.4	490.653
3754.52	442.634
3756.63	490.614
3758.74	503.594
3760.86	454.575
3762.97	462.555
3765.08	435.536
3767.19	449.516
3769.3	446.497
3771.4	466.477
3773.51	483.458
3775.61	437.438
3777.72	496.418
3779.82	459.399
3781.93	434.379
3784.03	477.36
3786.13	431.34
3788.23	481.321
3790.33	440.301
3792.43	421.282
3794.52	490.262
3796.62	441.242
3798.71	463.223
3800.81	437.203
3802.9	483.184
3804.99	477.164
3807.09	466.91
3809.18	434.37
3811.27	434.392
3813.36	457.807
3815.44	458.034
3817.53	450.863
3819.62	414.212
3821.7	467.462
3823.78	445.052
3825.87	450.229
3827.95	408.231
3830.03	453.721
3832.11	429.79
3834.19	416.397
3836.27	418.438
3838.35	451.228
3840.08	474.844
3842.18	402.844
3844.29	422.845
3846.39	427.845
3848.5	405.845
3850.6	434.846
3852.7	411.846
3854.8	437.846
3856.9	467.846
3859	432.847
3861.1	405.847
3863.2	429.847
3865.29	453.847
3867.39	422.848
3869.48	439.848
3871.58	441.848
3873.67	399.848
3875.76	456.849
3877.85	435.849
3879.94	446.849
3882.03	447.85
3884.12	390.85
3886.21	396.85
3888.29	466.85
3890.38	444.851
3892.46	404.851
3894.55	402.851
3896.63	401.851
3898.71	427.852
3900.79	409.852
3902.87	414.852
3904.95	375.853
3907.03	438.853
3909.11	424.853
3911.18	375.853
3913.26	388.854
3915.33	410.854
3917.41	422.854
3919.48	442.854
3921.55	393.855
3923.62	453.855
3925.69	430.855
3927.76	366.856
3929.83	424.856
3931.89	388.856
3933.96	392.856
3936.03	386.857
3938.09	363.857
3940.15	415.857
3942.22	381.857
3944.28	436.858
3946.34	437.858
3948.4	432.858
3950.46	362.859
3952.52	395.859
3954.57	436.859
3956.63	365.859
3958.69	404.86
3960.74	395.86
3962.79	376.86
3964.85	357.86
3966.9	384.861
3968.95	394.861
3971	351.861
3973.05	390.862
3975.1	376.862
3977.14	438.862
3979.19	357.862
3981.23	371.863
3983.28	402.863
3985.32	431.863
3987.37	412.863
3989.41	355.864
3991.45	400.864
3993.49	351.864
3995.53	352.864
3997.57	422.865
3999.6	416.865
4001.64	359.865
4003.68	418.866
4005.71	414.866
4007.74	376.866
4009.78	356.866
4011.81	356.867
4013.84	381.867
4015.87	355.867
4017.9	399.867
4019.93	359.868
4021.96	355.868
4023.98	367.868
4026.01	367.869
4028.03	386.869
4030.06	408.869
4032.08	378.869
4034.1	347.87
4036.12	396.87
4038.14	346.87
4040.16	349.87
4042.18	397.871
4044.2	385.871
4046.22	376.871
4048.23	337.872
4050.25	334.872
4052.26	360.872
4054.27	347.872
4056.29	354.873
4058.3	371.873
4060.31	389.873
4062.32	348.873
4064.33	385.874
4066.33	389.874
4068.34	352.874
4070.35	346.875
4072.35	333.875
4074.36	379.875
4076.36	365.875
4078.36	347.876
4080.36	337.876
4082.36	383.876
4084.36	368.876
4086.36	394.877
4088.36	338.877
4090.36	381.877
4092.35	345.878
4094.35	342.878
4096.35	374.878
4098.34	415.878
4100.33	384.879
4102.32	355.879
4104.31	395.879
4106.3	337.879
4108.29	345.88
4110.28	361.88
4112.27	370.88
4114.25	360.88
4116.24	351.881
4118.23	376.881
4120.21	348.881
4122.19	371.66
4124.18	358.027
4126.16	338.984
4128.14	340.14
4130.12	357.884
4132.1	335.12
4134.07	344.702
4136.05	330.201
4138.03	342.871
4140	361.379
4141.97	345.621
4143.95	349.652
4145.92	359.143
4147.89	334.11
4149.86	338.352
4151.83	355.68
4153.8	333.897
4155.72	327.666
4157.72	334.642
4159.71	369.618
4161.71	324.594
4163.7	352.571
4165.7	317.547
4167.69	329.523
4169.68	334.499
4171.67	317.475
4173.66	319.451
4175.65	331.427
4177.64	390.403
4179.63	329.379
4181.61	321.355
4183.6	359.331
4185.58	351.307
4187.57	407.283
4189.55	333.259
4191.53	325.235
4193.51	387.211
4195.49	315.188
4197.47	339.164
4199.45	403.14
4201.43	364.116
4203.41	364.092
4205.38	332.068
4207.36	326.044
4209.33	321.02
4211.31	321.996
4213.28	333.972
4215.25	314.948
4217.22	321.924
4219.19	369.9
4221.16	356.876
4223.13	336.852
4225.1	331.829
4227.07	378.805
4229.03	344.781
4231	375.757
4232.96	312.733
4234.92	348.709
4236.89	331.685
4238.85	383.661
4240.81	325.637
4242.77	353.613
4244.73	320.589
4246.69	324.565
4248.64	314.541
4250.6	345.517
4252.56	342.493
4254.51	338.469
4256.47	330.446
4258.42	331.422
4260.37	325.398
4262.32	386.374
4264.27	312.35
4266.22	331.326
4268.17	312.302
4270.12	367.278
4272.07	318.254
4274.01	331.23
4275.96	329.206
4277.9	312.182
4279.85	384.158
4281.79	403.134
4283.73	381.11
4285.67	322.086
4287.61	335.063
4289.55	373.039
4291.49	313.015
4293.43	334.991
4295.37	360.967
4297.3	349.943
4299.24	324.919
4301.17	355.895
4303.11	365.871
4305.04	348.847
4306.97	319.823
4308.9	399.799
4310.83	326.775
4312.76	307.751
4314.69	305.727
4316.62	345.703
4318.55	309.68
4320.47	358.656
4322.4	399.632
4324.32	328.608
4326.24	335.584
4328.17	376.56
4330.09	315.536
4332.01	330.512
4333.93	336.488
4335.85	395.464
4337.77	366.44
4339.69	345.416
4341.6	371.392
4343.52	305.368
4345.43	383.344
4347.35	340.32
4349.26	345.297
4351.17	307.273
4353.09	325.249
4355	306.225
4356.91	347.201
4358.81	312.177
4360.72	306.153
4362.63	326.129
4364.54	322.105
4366.44	332.081
4368.35	343.057
4370.25	321.033
4372.16	321.009
4374.06	368.077
4375.96	324.163
4377.86	383.249
4379.76	332.335
4381.66	335.422
4383.56	344.508
4385.46	331.594
4387.35	355.68
4389.25	350.766
4391.14	327.852
4393.04	316.938
4394.93	346.024
4396.82	335.111
4398.71	316.197
4400.6	311.283
4402.5	368.369
4404.38	334.455
4406.27	345.541
4408.16	312.627
4410.05	329.713
4411.93	324.799
4413.82	349.886
4415.7	373.972
4417.58	320.058
4419.47	358.144
4421.35	306.7
4423.23	352.996
4425.11	349.884
4426.99	359.125
4428.87	320.105
4430.74	318.214
4432.62	342.827
4434.49	368.202
4436.37	367.467
4438.24	373.47
4440.12	335.368
4441.99	332.058
4443.86	327.485
4445.73	340.664
4447.6	352.881
4449.47	338.907
4451.34	362.29
4453.17	363.948
4455.06	368.789
4456.96	372.63
4458.85	349.471
4460.75	314.313
4462.64	365.154
4464.53	304.995
4466.42	365.836
4468.31	341.677
4470.2	314.517
4472.09	333.358
4473.98	376.199
4475.87	315.04
4477.75	348.882
4479.64	303.723
4481.52	335.564
4483.41	313.405
4485.29	315.246
4487.17	328.086
4489.05	301.927
4490.93	349.768
4492.81	366.609
4494.69	357.451
4496.57	344.292
4498.45	332.133
4499.7	310.026