File: DateTimeSpectrumPointNumber1.txt
#Acq. time (s)=	2
#Accumulations=	3
#Range (cm-¹)=	100...1000
#Windows=	2
#Autofocus=	Off
#AutoExposure=	Off
#Spike filter=	Multiple accum.
#Delay time (s)=	0
#Binning=	1
#Readout mode=	Signal
#DeNoise=	Off
#ICS correction=	Off
#Dark correction=	Off
#Inst. Process=	Off
#Instrument=	LabRAM HR Evol
#Detector=	Emulator CCD
#Objective=	x100
#Grating=	1800 gr/mm
#ND Filter=	100%
#Laser (nm)=	512
#Slit=	150.001
#Hole=	70.0087
#Project=	A
#Sample=	B
#Site=	C
#Title=	D_46
#Remark=
#Date=	18.10.2017 11:25
#Acquired=	18.10.2017 11:25:54
100.3	330
101.489	381
102.678	305
103.865	366.5
105.053	335.5
106.239	368
107.428	313.5
108.613	335.5
109.799	308
110.987	354.5
112.172	313.5
113.36	316.5
114.545	307
115.73	307
116.915	321.5
118.102	371
119.287	320.5
120.471	336
121.655	345
122.842	320.5
124.026	313
125.209	355.5
126.393	349.5
127.577	340
128.76	336.5
129.943	365
131.126	325.5
132.309	318
133.492	319
134.675	339
135.857	367.5
137.04	352
138.222	341.5
139.404	325
140.586	345.5
141.768	318
142.947	314.5
144.129	313
145.31	316
146.491	379
147.67	320.5
148.851	332
150.032	326
151.212	327
152.391	361
153.571	339
154.749	317.5
155.929	335
157.109	341.5
158.287	324.5
159.466	326
160.643	332.5
161.823	314.5
163	316
164.176	343
165.355	311
166.532	304
167.711	360
168.887	326
170.063	337
171.239	321
172.417	323
173.592	366.5
174.768	355
175.943	326
177.121	309.5
178.296	336
179.471	370
180.646	320
181.82	308.5
182.995	333.5
184.169	338
185.343	327
186.517	305
187.691	354
188.865	344
190.039	313
191.212	311
192.386	323
193.559	354
194.732	320
195.905	326
197.075	319
198.248	360.5
199.421	331.5
200.593	328.5
201.765	365
202.935	332
204.107	324
205.279	336
206.448	337.5
207.62	328
208.789	308.5
209.96	332
211.131	301
212.3	307
213.47	327
214.639	354.5
215.809	352
216.977	317
218.145	318
219.315	340
220.483	325.5
221.653	351
222.82	336.5
223.988	320.5
225.155	301
226.324	308
227.491	339
228.657	313
229.824	360.5
230.993	337
232.159	305
233.325	317
234.491	346.5
235.657	335.5
236.823	350
237.988	368
239.154	354.5
240.319	322
241.484	353
242.649	346
243.814	372
244.979	351.5
246.143	337.5
247.308	358.5
248.472	339
249.634	349
250.798	306.5
251.962	301
253.125	355
254.289	309
255.45	375.5
256.613	375
257.777	316.5
258.937	335
260.1	351.5
261.261	325
262.423	320
263.586	337
264.746	330
265.908	301
267.068	325
268.23	305
269.389	309.5
270.549	319.5
271.71	330.5
272.869	332.5
274.03	303
275.189	345
276.348	328
277.506	306
278.667	359
279.825	334.5
280.983	341.5
282.141	315
283.302	327
284.459	314.5
285.617	309
286.774	330
287.931	340
289.089	347
290.246	346
291.402	325.5
292.559	366.01
293.716	301.029
294.872	336.048
296.029	325.568
297.185	334.587
298.341	343.106
299.497	331.626
300.652	357.645
301.806	374.664
302.961	312.184
304.116	307.203
305.272	326.722
306.424	314.241
307.579	328.261
308.734	326.28
309.887	351.299
311.041	326.319
312.195	349.338
313.347	326.357
314.501	341.377
315.653	337.396
316.807	306.415
317.958	328.935
319.112	334.954
320.263	306.473
321.416	332.993
322.567	336.512
323.72	324.531
324.871	330.551
326.021	314.07
327.174	339.089
328.324	327.608
329.474	322.628
330.624	320.647
331.776	320.666
332.925	322.686
334.075	329.705
335.224	338.724
336.373	337.744
337.522	331.263
338.671	334.782
339.822	300.802
340.971	319.321
342.12	332.84
343.268	315.86
344.416	320.879
345.564	378.898
346.71	316.918
347.858	323.937
349.006	342.956
350.153	329.475
351.301	342.995
352.448	310.514
353.595	330.033
354.74	346.053
355.887	334.072
357.033	350.091
358.18	352.111
359.324	318.13
360.47	366.649
361.617	380.669
362.76	313.188
363.906	386.707
365.05	347.227
366.196	315.246
367.339	314.765
368.484	339.285
369.627	326.304
370.772	325.323
371.915	311.342
373.06	318.362
374.202	305.381
375.345	348.4
376.489	340.42
377.631	338.439
378.773	327.458
379.917	342.478
381.058	343.497
382.2	305.516
383.341	311.036
384.483	316.555
385.624	337.074
386.767	307.594
387.908	341.613
389.048	318.632
390.189	317.652
391.329	348.671
392.469	364.69
393.61	324.209
394.75	317.729
395.889	312.248
397.029	314.767
398.169	359.787
399.308	325.806
400.445	333.825
401.584	302.845
402.723	310.864
403.862	364.383
405.001	344.903
406.138	333.922
407.276	318.941
408.414	344.961
409.55	333.98
410.688	373.999
411.826	334.019
412.962	332.038
414.1	321.057
415.235	307.077
416.372	338.096
417.507	350.615
418.645	326.634
419.779	336.654
420.916	358.173
422.051	338.192
423.185	310.212
424.322	319.231
425.456	335.25
426.592	348.77
427.726	326.789
428.859	325.808
429.993	355.828
431.129	349.347
432.262	335.866
433.395	306.386
434.528	343.405
435.661	363.424
436.794	346.444
437.926	308.463
439.059	315.482
440.191	353.001
441.324	308.521
442.456	338.04
443.588	317.559
444.719	307.579
445.851	339.598
446.983	388.117
448.114	304.637
449.245	308.656
450.377	339.175
451.508	365.695
452.636	365.214
453.767	329.733
454.898	313.753
456.028	340.772
457.156	341.291
458.286	309.811
459.416	324.83
460.544	382.849
461.674	305.868
462.801	379.388
463.931	326.407
465.058	388.426
466.187	306.946
467.314	306.965
468.443	359.484
469.57	345.004
470.699	333.023
471.825	318.542
472.951	351.562
474.08	359.081
475.206	309.1
476.332	318.12
477.457	319.639
478.585	342.658
479.711	356.178
480.836	359.197
481.961	337.716
483.086	314.235
484.213	353.755
485.338	336.274
486.463	328.793
487.587	365.313
488.712	352.832
489.836	352.351
490.96	324.371
492.084	341.39
493.208	311.909
494.332	315.429
495.453	308.448
496.577	352.467
497.7	311.487
498.823	330.506
499.946	303.525
501.067	317.545
502.19	327.564
503.312	320.583
504.435	317.602
505.555	315.122
506.677	304.641
507.799	386.16
508.919	348.18
510.041	333.199
511.161	393.718
512.282	308.738
513.402	340.757
514.523	355.776
515.642	329.796
516.763	322.815
517.882	336.334
519	353.854
520.121	334.373
521.239	337.892
522.358	306.912
523.478	318.931
524.596	349.95
525.714	328.969
526.831	329.989
527.951	352.008
529.069	359.527
530.186	370.047
531.303	306.066
532.42	343.085
533.537	344.105
534.654	321.624
535.77	329.643
536.887	331.663
538.003	332.682
539.12	318.201
540.236	320.221
541.352	327.74
542.468	324.759
543.583	341.279
544.699	350.798
545.812	305.317
546.927	352.336
548.043	339.356
549.158	350.375
550.271	326.394
551.385	333.414
552.5	334.433
553.612	306.452
554.727	346.472
555.841	345.491
556.953	307.51
558.067	343.53
559.179	374.549
560.292	344.068
561.404	327.588
562.517	338.107
563.629	326.626
564.74	392.146
565.853	307.665
566.964	312.684
568.074	324.203
569.187	341.723
570.297	374.242
571.408	329.761
572.52	342.281
573.63	370.8
574.74	340.819
575.849	308.839
576.959	332.858
578.069	339.877
579.178	320.397
580.287	343.416
581.396	353.435
582.505	329.955
583.614	343.974
584.723	350.493
585.831	358.513
586.94	330.532
588.048	329.551
589.156	329.07
590.264	371.09
591.372	339.109
592.478	310.128
593.585	315.148
594.693	366.167
595.8	331.686
596.906	314.206
598.013	333.225
599.12	360.244
600.224	369.264
601.331	331.283
602.436	333.302
603.542	317.322
604.648	316.341
605.753	306.86
606.859	332.38
607.962	337.399
609.066	356.418
610.172	321.438
611.275	335.457
612.381	346.476
613.484	331.995
614.587	380.015
615.69	322.534
616.795	323.053
617.897	322.573
619	342.592
620.102	335.611
621.205	376.131
622.309	306.65
623.411	343.169
624.513	313.831
625.614	313.595
626.716	317.173
627.818	336.92
628.919	309.792
630.02	362.769
631.121	331.955
632.222	330.075
633.323	331.983
634.422	338.605
635.522	351.921
636.623	324.626
637.723	326.333
638.823	344.617
639.921	341.107
641.021	371.454
642.121	352.591
643.218	326.207
644.318	328.348
645.417	341.753
646.514	322.372
647.614	326.51
648.711	318.795
649.809	325.713
650.906	322.522
652.005	331.604
653.101	358.972
654.199	320.281
655.296	339.187
656.392	326.855
657.49	340.468
658.585	331.426
659.681	329.662
660.779	335.976
661.874	337.344
662.969	326.479
664.064	321.275
665.161	350.113
666.256	364.886
667.351	348.518
668.445	348.304
669.54	328.453
670.634	336.728
671.728	365.714
672.823	336.554
673.917	330.402
675.01	324.325
676.104	314.874
677.198	350.676
678.291	322.363
679.382	338.319
680.475	339.783
681.568	305.872
682.648	334.544
683.752	316.035
684.858	305.026
685.961	312.517
687.066	347.008
688.17	372.999
689.275	367.99
690.378	320.981
691.48	372.472
692.585	368.963
693.688	308.954
694.79	313.945
695.892	330.936
696.996	313.927
698.098	331.419
699.2	313.91
700.302	324.401
701.404	342.892
702.505	345.883
703.606	332.374
704.708	323.365
705.809	311.856
706.91	342.847
708.01	333.838
709.111	310.329
710.212	375.82
711.312	373.811
712.412	343.802
713.513	341.793
714.613	357.284
715.712	317.775
716.812	335.766
717.91	305.757
719.009	340.248
720.109	329.74
721.208	333.231
722.305	363.222
723.404	305.713
724.503	328.704
725.599	346.195
726.698	332.686
727.796	339.177
728.893	329.668
729.991	335.659
731.087	368.65
732.185	325.641
733.281	309.632
734.378	340.623
735.474	347.614
736.569	310.605
737.666	315.596
738.761	317.087
739.859	347.078
740.953	351.569
742.048	356.561
743.143	320.052
744.239	334.543
745.333	341.034
746.428	366.025
747.522	354.516
748.618	353.007
749.711	363.998
750.805	344.489
751.899	343.98
752.992	359.471
754.085	368.962
755.178	317.953
756.271	321.944
757.364	360.935
758.457	308.426
759.55	340.417
760.642	326.908
761.735	339.899
762.827	355.89
763.917	304.382
765.009	327.373
766.101	349.364
767.193	347.355
768.284	325.346
769.374	324.337
770.465	344.328
771.556	307.319
772.645	337.31
773.736	314.301
774.827	352.792
775.916	324.283
777.006	334.774
778.094	316.265
779.185	332.756
780.273	344.247
781.363	313.738
782.451	325.729
783.541	304.22
784.628	329.211
785.718	352.703
786.805	308.194
787.892	354.185
788.982	344.176
790.069	313.167
791.155	328.158
792.242	322.649
793.331	358.64
794.417	372.131
795.503	325.122
796.59	347.113
797.676	360.104
798.762	318.595
799.85	327.086
800.935	303.077
802.021	383.068
803.106	337.559
804.192	321.05
805.277	340.541
806.362	352.033
807.447	325.024
808.529	319.015
809.614	345.006
810.699	354.997
811.783	334.988
812.867	325.979
813.952	339.47
815.034	354.961
816.117	327.952
817.201	337.443
818.285	304.434
819.366	340.925
820.45	366.916
821.533	314.407
822.614	345.398
823.697	352.889
824.778	322.88
825.861	353.871
826.941	362.862
828.024	313.854
829.104	348.845
830.186	361.836
831.266	333.327
832.348	354.818
833.428	311.309
834.508	313.8
835.59	333.291
836.669	379.282
837.748	379.773
838.827	353.764
839.909	326.755
840.987	307.746
842.066	313.237
843.145	351.728
844.223	343.719
845.304	362.71
846.382	346.201
847.46	354.692
848.539	352.183
849.616	372.174
850.694	378.666
851.772	331.657
852.849	327.148
853.927	335.639
855.004	350.63
856.079	368.621
857.156	360.112
858.233	364.603
859.31	322.594
860.387	317.585
861.463	316.576
862.537	307.567
863.614	331.558
864.69	371.049
865.764	324.54
866.84	315.531
867.916	311.522
868.989	377.513
870.065	321.504
871.138	308.996
872.213	326.987
873.286	349.478
874.362	316.469
875.434	340.46
876.509	359.451
877.582	360.942
878.656	330.933
879.729	306.424
880.801	360.415
881.875	321.406
882.947	314.397
884.019	353.388
885.093	343.879
886.164	387.37
887.236	356.861
888.307	306.352
889.378	337.343
890.451	320.334
891.522	361.826
892.593	351.317
893.664	346.308
894.734	365.799
895.805	311.29
896.875	348.281
897.946	358.772
899.016	348.263
900.086	333.254
901.156	371.745
902.223	318.236
903.293	320.227
904.362	340.218
905.432	330.209
906.501	320.2
907.57	319.191
908.637	367.182
909.706	339.673
910.774	314.164
911.841	343.155
912.909	317.146
913.978	347.138
915.044	334.629
916.112	349.12
917.178	344.611
918.246	340.102
919.312	353.093
920.379	328.084
921.445	367.075
922.512	347.066
923.577	343.057
924.642	361.048
925.709	353.039
926.774	340.03
927.839	356.521
928.906	367.012
929.97	334.003
931.034	368.994
932.099	318.985
933.165	329.976
934.229	314.967
935.292	314.959
936.356	337.95
937.42	360.941
938.483	363.932
939.547	371.423
940.61	321.914
941.673	356.905
942.736	341.896
943.799	369.387
944.861	320.878
945.924	354.369
946.987	325.86
948.049	308.851
949.111	327.842
950.171	317.833
951.233	339.824
952.295	329.315
953.357	312.806
954.416	305.797
955.478	331.289
956.539	343.28
957.599	324.271
958.66	348.762
959.721	305.753
960.78	346.744
961.84	350.235
962.899	345.726
963.959	311.717
965.018	368.708
966.078	362.699
967.136	325.69
968.196	368.681
969.254	348.672
970.312	346.663
971.372	344.654
972.429	359.145
973.486	323.136
974.544	313.627
975.603	322.618
976.66	324.61
977.717	323.101
978.773	346.592
979.83	384.083
980.887	320.574
981.945	328.565
983.001	363.556
984.058	362.547
985.114	340.538
986.169	336.529
987.225	315.52
988.281	325.011
989.337	326.502
990.39	333.493
991.445	312.484
992.5	367.975
993.555	317.466
994.61	320.957
995.665	339.948
996.718	321.44
997.773	343.931
998.827	332.422
999.879	354.913