File: DateTimeSpectrumPointNumber1.txt
#Acq. time (s)=	0.8
#Accumulations=	3
#Range (cm-¹)=	1500...2000
#Windows=	2
#Autofocus=	Off
#AutoExposure=	Off
#Spike filter=	Multiple accum.
#Delay time (s)=	0
#Binning=	1
#Readout mode=	Signal
#DeNoise=	Off
#ICS correction=	Off
#Dark correction=	Off
#Inst. Process=	Off
#Instrument=	LabRAM HR Evol
#Detector=	Emulator CCD
#Objective=	x100
#Grating=	1800 gr/mm
#ND Filter=	100%
#Laser (nm)=	512
#Slit=	150.001
#Hole=	70.0087
#Project=	A
#Sample=	B
#Site=	C
#Title=	D_166
#Remark=
#Date=	30.10.2017 09:05
#Acquired=	30.10.2017 09:05:54
1500.39	369
1500.89	366
1501.39	391
1501.88	381.5
1502.38	395
1502.88	350
1503.38	381.5
1503.87	372
1504.37	372.5
1504.87	383
1505.37	362
1505.86	363
1506.36	365
1506.86	366
1507.35	361.5
1507.85	387.5
1508.35	357.5
1508.84	360
1509.34	400
1509.84	429
1510.33	353
1510.83	367
1511.33	400
1511.82	367
1512.32	359
1512.82	363
1513.31	373.5
1513.81	377
1514.31	353
1514.8	363
1515.3	389
1515.8	375
1516.29	352
1516.79	374.5
1517.28	395.5
1517.78	359
1518.28	390.5
1518.77	369
1519.27	375
1519.76	403.5
1520.26	384
1520.76	390
1521.25	406.5
1521.75	376
1522.24	361
1522.74	402.5
1523.23	391
1523.73	366
1524.23	405
1524.72	375
1525.22	383
1525.71	377
1526.21	358
1526.7	396.5
1527.2	410
1527.69	358
1528.19	355
1528.68	397
1529.18	366
1529.68	365
1530.17	363.5
1530.66	418
1531.16	405.5
1531.65	394
1532.15	390
1532.65	356
1533.14	365.5
1533.63	367
1534.13	379
1534.62	381.5
1535.12	385.5
1535.61	403.5
1536.11	353
1536.6	413
1537.1	389
1537.59	361
1538.09	358
1538.58	408.5
1539.08	357
1539.57	377.5
1540.07	387.5
1540.56	390
1541.05	363
1541.55	383.5
1542.04	357
1542.54	363.5
1543.03	359
1543.52	390
1544.02	418.5
1544.51	398
1545.01	379.5
1545.5	404
1545.99	358
1546.49	426
1546.98	383.5
1547.48	388
1547.97	359.5
1548.46	381.5
1548.96	369.5
1549.45	430
1549.94	377
1550.44	392.5
1550.93	378
1551.42	363
1551.92	363
1552.41	415.5
1552.91	392
1553.4	400.5
1553.89	386
1554.38	384
1554.88	411
1555.37	409
1555.86	382
1556.36	388
1556.85	394
1557.34	390
1557.84	392.5
1558.33	402
1558.82	390
1559.31	413
1559.81	387
1560.3	394
1560.79	376
1561.29	387
1561.78	373.5
1562.27	404
1562.76	395
1563.26	392.5
1563.75	394
1564.24	390
1564.73	418.5
1565.23	388.5
1565.72	361
1566.21	369
1566.7	412
1567.2	412
1567.69	379
1568.18	370
1568.67	405.5
1569.16	425.5
1569.66	421
1570.15	396
1570.64	388
1571.13	374
1571.62	363
1572.12	391.5
1572.61	414
1573.1	402.5
1573.59	374.5
1574.08	387
1574.58	369
1575.07	391.5
1575.56	408
1576.05	406
1576.54	447.5
1577.03	408
1577.52	401
1578.02	405
1578.51	431
1579	425.5
1579.49	368.5
1579.98	388.5
1580.47	374
1580.96	378
1581.45	399
1581.94	393.5
1582.44	366
1582.93	370
1583.42	380
1583.91	412.5
1584.4	394
1584.89	391
1585.38	373
1585.87	419.5
1586.36	374
1586.85	393
1587.35	413.5
1587.84	442
1588.33	404
1588.82	405
1589.31	408.5
1589.8	423
1590.29	391
1590.78	388.5
1591.27	411
1591.76	388
1592.25	391
1592.74	395.5
1593.23	400
1593.72	441.5
1594.21	404
1594.7	391
1595.19	420
1595.68	441.5
1596.17	372
1596.66	418
1597.15	413
1597.64	400
1598.13	422.5
1598.62	415
1599.11	396
1599.6	395
1600.09	423
1600.58	379
1601.07	419
1601.56	417.5
1602.05	391.5
1602.54	382
1603.03	425.5
1603.52	435
1604	424.5
1604.49	419.5
1604.98	403
1605.47	371
1605.96	425.5
1606.45	426.5
1606.94	414
1607.43	411.5
1607.92	375
1608.41	420
1608.9	409
1609.39	373
1609.88	429
1610.36	391
1610.85	384
1611.34	395
1611.83	430
1612.32	389
1612.81	375
1613.3	408
1613.79	387
1614.27	398
1614.76	408.5
1615.25	428.5
1615.74	392
1616.23	390
1616.72	403
1617.2	425
1617.69	406.5
1618.18	392
1618.67	446
1619.16	388
1619.64	429
1620.13	389
1620.62	382
1621.11	379
1621.6	427
1622.09	435
1622.57	391
1623.06	407
1623.55	410
1624.04	431.5
1624.52	411
1625.01	406
1625.5	425
1625.99	398
1626.48	396
1626.96	428
1627.45	399
1627.94	421.5
1628.42	389
1628.91	425.5
1629.4	414
1629.89	403
1630.37	415
1630.86	420
1631.35	411
1631.84	383
1632.32	436
1632.81	428
1633.3	391.5
1633.78	417
1634.27	391
1634.76	399
1635.25	425.5
1635.73	405
1636.22	432.5
1636.71	446.5
1637.19	456.5
1637.68	435
1638.17	420.5
1638.65	406
1639.14	440
1639.63	384
1640.11	451
1640.6	407
1641.09	478
1641.57	431.5
1642.06	419
1642.55	423.5
1643.03	441.5
1643.52	393
1644	423.5
1644.49	444
1644.98	425.5
1645.46	426.5
1645.95	421
1646.44	418
1646.92	406
1647.41	424.5
1647.89	405.5
1648.38	412
1648.87	437
1649.35	416
1649.84	419
1650.32	406.5
1650.81	431.5
1651.29	427
1651.78	455
1652.26	415
1652.75	412.5
1653.24	404
1653.72	409.5
1654.21	407.5
1654.69	410.5
1655.18	419
1655.66	398
1656.15	442
1656.63	404
1657.12	446
1657.6	402
1658.09	413
1658.57	400
1659.06	425.5
1659.54	458.5
1660.03	443
1660.51	418.5
1661	435
1661.48	417
1661.97	468
1662.45	441.5
1662.94	440
1663.42	437.5
1663.91	430
1664.39	415.5
1664.88	462
1665.36	435.5
1665.85	412
1666.33	466
1666.82	437.5
1667.3	436
1667.78	400
1668.27	423
1668.75	459.5
1669.24	404
1669.72	401
1670.21	449.5
1670.69	449
1671.17	440
1671.66	420
1672.14	443
1672.63	421.5
1673.11	403
1673.59	447.5
1674.08	419
1674.56	458.5
1675.05	409
1675.53	438
1676.01	432.5
1676.5	421
1676.98	452
1677.46	435.5
1677.95	442.5
1678.43	422.5
1678.92	414
1679.4	440.5
1679.88	438.5
1680.36	453
1680.85	404
1681.33	431
1681.81	478.5
1682.3	409.5
1682.78	428
1683.26	420
1683.75	406
1684.23	424
1684.71	422.5
1685.2	405.5
1685.68	429.5
1686.16	468.5
1686.65	450
1687.13	432
1687.61	453
1688.09	437.5
1688.58	479.5
1689.06	440.5
1689.54	444
1690.03	432
1690.51	422.5
1690.99	410
1691.47	447
1691.95	457.5
1692.44	446
1692.92	449
1693.4	418
1693.88	440
1694.37	448
1694.85	436.5
1695.33	442.5
1695.81	429
1696.3	452
1696.78	457.5
1697.26	444
1697.74	463
1698.22	436
1698.71	406
1699.19	438
1699.67	457
1700.15	449.5
1700.63	419
1701.12	439
1701.6	456
1702.08	444
1702.56	421
1703.04	435
1703.52	408
1704	424
1704.49	413.5
1704.97	414
1705.45	459
1705.93	418
1706.41	446
1706.89	429.5
1707.38	448.5
1707.86	422
1708.34	464.5
1708.82	446
1709.3	434.5
1709.78	411
1710.26	479.5
1710.74	430
1711.22	447
1711.7	451
1712.19	425.5
1712.67	453.5
1713.15	458
1713.63	420.5
1714.11	431
1714.59	425
1715.07	433
1715.55	473.5
1716.03	428.5
1716.51	466
1716.99	449
1717.47	454
1717.95	444.5
1718.43	434
1718.91	453
1719.39	474.5
1719.87	449
1720.36	462.5
1720.84	416
1721.32	431.5
1721.8	470
1722.28	437.5
1722.76	441
1723.24	456
1723.72	473.5
1724.2	432
1724.68	428.5
1725.16	451.5
1725.64	491
1726.12	462
1726.6	453.5
1727.08	465.5
1727.55	454
1728.03	427
1728.51	467
1728.99	421
1729.47	444.5
1729.95	423
1730.43	473.5
1730.91	480.5
1731.39	468.5
1731.87	489
1732.35	440.5
1732.83	439
1733.31	471.5
1733.79	470.5
1734.27	432
1734.74	445
1735.22	457
1735.7	471.5
1736.18	444.5
1736.66	483.5
1737.14	465
1737.62	460.5
1738.1	444
1738.58	445
1739.06	497
1739.54	476
1740.01	446
1740.49	495.5
1740.97	502
1741.45	455.5
1741.93	425
1742.41	437.5
1742.89	430
1743.36	461
1743.84	440.5
1744.32	441
1744.8	426
1745.28	446
1745.75	487
1746.23	497
1746.71	471
1747.19	452.5
1747.67	466
1748.15	454
1748.63	464
1749.1	465
1749.58	482
1750.06	500
1750.54	465
1751.01	445
1751.49	482.5
1751.97	482
1752.45	468
1752.92	463.5
1753.4	510
1753.88	464
1754.36	461
1754.84	491.5
1755.31	459
1755.79	467.5
1756.27	451.5
1756.75	494
1757.22	464.5
1757.7	468
1758.18	492
1758.65	464.5
1759.13	500
1759.61	463
1760.09	468.5
1760.56	466
1761.04	476
1761.52	440
1761.99	443.5
1762.47	492
1762.95	454.5
1763.43	464.5
1763.9	466
1764.38	446
1764.86	485
1765.33	454
1765.81	439
1766.29	476.5
1766.76	461
1767.24	528
1767.72	453.5
1768.19	453
1768.67	461.5
1769.15	498.5
1769.62	507
1770.1	442
1770.57	453
1771.05	506
1771.53	499
1772	448
1772.48	459.5
1772.96	486
1773.43	469
1773.91	443
1774.38	497
1774.86	473.5
1775.34	494
1775.81	461.5
1776.29	509.5
1776.76	452
1777.24	446.5
1777.71	474
1778.19	468
1778.67	463.5
1779.14	479
1779.62	468.5
1780.09	451
1780.57	471
1781.04	489.5
1781.52	449
1782	509.5
1782.47	470.5
1782.94	492
1783.42	473
1783.9	476.5
1784.37	460
1784.85	504
1785.32	475
1785.8	469.5
1786.27	448
1786.75	455
1787.22	480.5
1787.7	497
1788.17	502
1788.65	483
1789.12	478.5
1789.6	506
1790.07	501
1790.55	488
1791.02	472
1791.49	478
1791.97	518
1792.45	523
1792.92	474.5
1793.39	459.5
1793.87	455
1794.34	488.5
1794.82	457
1795.29	504
1795.77	499.5
1796.24	475
1796.71	469
1797.19	500.5
1797.66	494
1798.14	460
1798.61	470
1799.08	510
1799.56	502.5
1800.03	518
1800.51	489
1800.98	487
1801.45	496
1801.93	459
1802.4	484.5
1802.88	518.5
1803.35	483
1803.82	458
1804.3	465
1804.77	482
1805.24	500
1805.72	479
1806.19	491
1806.67	505
1807.14	478.5
1807.61	524.5
1808.09	522
1808.56	486
1809.03	473
1809.5	517.5
1809.98	477
1810.45	468
1810.92	485.5
1811.4	472
1811.87	485.5
1812.34	481.5
1812.82	480.5
1813.29	485
1813.76	525.5
1814.24	475
1814.71	496
1815.18	494
1815.65	524
1816.13	507
1816.6	523
1817.07	520
1817.55	493
1818.02	504.5
1818.49	473
1818.96	514.5
1819.44	499.5
1819.91	552
1820.38	500.5
1820.85	506.5
1821.33	513
1821.8	472
1822.27	530
1822.74	504.5
1823.21	503
1823.69	523
1824.16	471
1824.63	486
1825.1	504
1825.57	510
1826.05	508.5
1826.52	486.5
1826.99	510
1827.46	503.5
1827.93	522
1828.41	511.5
1828.88	492
1829.35	519.5
1829.82	508
1830.29	497
1830.76	476
1831.23	519
1831.71	537.5
1832.18	534.5
1832.65	500
1833.12	508.5
1833.59	526
1834.06	500
1834.53	492.5
1835.01	490
1835.48	528.5
1835.95	510
1836.42	478
1836.89	526.5
1837.36	499
1837.83	492
1838.3	491
1838.77	515
1839.25	506.5
1839.72	489.5
1840.19	488.5
1840.66	499
1841.13	499
1841.6	529.5
1842.07	529
1842.54	497.5
1843.01	506
1843.48	514
1843.95	485
1844.42	482
1844.89	488
1845.36	519
1845.84	485
1846.3	483
1846.78	553
1847.25	543.5
1847.72	490.5
1848.19	486.5
1848.66	503.5
1849.13	505
1849.6	508
1850.07	534.5
1850.54	515.5
1851.01	505.5
1851.48	494
1851.95	523
1852.42	517.5
1852.89	500.5
1853.36	495
1853.83	495.5
1854.3	525
1854.76	544.5
1855.24	505
1855.7	530.5
1856.17	530
1856.64	502
1857.11	556.5
1857.58	525
1858.05	510
1858.52	508.5
1858.99	544.5
1859.46	522.5
1859.93	499
1860.4	543.5
1860.87	546
1861.34	518
1861.81	511
1862.28	536
1862.74	527.5
1863.21	568
1863.68	575.5
1864.15	548.5
1864.62	566
1865.09	502
1865.56	515
1866.03	520
1866.5	504.5
1866.96	525
1867.43	497
1867.9	540
1868.37	506
1868.84	514
1869.31	540.5
1869.78	539.5
1870.24	502
1870.71	515
1871.18	544.5
1871.65	500
1872.12	516
1872.59	524.5
1873.05	527.5
1873.52	501
1873.99	558
1874.46	571.5
1874.93	560.5
1875.4	533
1875.86	510
1876.33	507.5
1876.8	519
1877.27	516
1877.73	546.5
1878.2	507
1878.67	542
1879.14	526.5
1879.61	520.5
1880.07	531.5
1880.54	540
1881.01	538.5
1881.48	507
1881.94	544
1882.41	551
1882.88	552.5
1883.35	520
1883.82	571
1884.28	514.5
1884.75	547
1885.22	557
1885.68	591.5
1886.15	549.5
1886.62	569
1887.09	520
1887.55	540.5
1888.02	526
1888.49	521
1888.95	524
1889.42	543
1889.89	535
1890.35	540
1890.82	556
1891.29	532
1891.76	567.5
1892.22	522
1892.69	520
1893.16	565
1893.62	567
1894.09	552.5
1894.55	533
1895.02	519
1895.49	532.5
1895.95	549
1896.42	529
1896.89	550.5
1897.35	532
1897.82	571.5
1898.29	532
1898.75	565
1899.22	555
1899.68	575.5
1900.15	528.5
1900.62	548.5
1901.08	539
1901.55	553
1902.01	557.5
1902.48	541
1902.95	545.5
1903.41	572.5
1903.88	532.5
1904.34	586.5
1904.81	525
1905.28	582
1905.74	575
1906.21	566.5
1906.67	589.5
1907.14	546
1907.6	559.5
1908.07	565
1908.54	576.5
1909	560
1909.47	547
1909.93	552.5
1910.4	567
1910.86	537
1911.33	565
1911.79	550
1912.26	575
1912.72	555.5
1913.19	557
1913.65	558
1914.12	566
1914.58	601
1915.05	569
1915.51	535
1915.98	564
1916.44	594
1916.91	549
1917.37	585
1917.84	554
1918.3	567
1918.77	554
1919.23	585
1919.69	571
1920.16	570.5
1920.62	550.5
1921.09	545
1921.55	588
1922.02	554
1922.48	583
1922.94	589.5
1923.41	599
1923.87	594.5
1924.34	543.5
1924.8	575
1925.27	589
1925.73	564
1926.2	543
1926.66	552
1927.12	592.5
1927.59	602
1928.05	565.5
1928.51	575.527
1928.98	596.054
1929.44	549.081
1929.91	581.107
1930.37	557.634
1930.83	596.661
1931.3	564.188
1931.76	606.215
1932.22	585.242
1932.69	561.269
1933.15	583.296
1933.61	556.322
1934.08	583.349
1934.54	570.376
1935	557.403
1935.47	595.93
1935.93	581.457
1936.39	557.484
1936.86	574.51
1937.32	608.537
1937.78	550.564
1938.25	574.591
1938.71	595.618
1939.17	584.145
1939.64	578.268
1940.1	558.854
1940.56	617.374
1941.02	629.114
1941.49	585.764
1941.95	604.188
1942.41	591.42
1942.88	558.828
1943.34	567.583
1943.8	608.129
1944.27	597.247
1944.73	579.039
1945.19	607.447
1945.65	579.14
1946.11	599.046
1946.58	608.415
1947.04	605.33
1947.5	589.98
1947.96	591.881
1948.43	592.841
1948.89	569.918
1949.35	571.782
1949.81	597.275
1950.28	590.553
1950.74	595.591
1951.2	587.421
1951.66	607.942
1952.12	591.55
1952.59	596.67
1953.05	602.133
1953.51	602.684
1953.97	589.542
1954.43	579.348
1954.89	609.259
1955.36	606.252
1955.82	580.468
1956.28	588.822
1956.74	580.709
1957.2	597.052
1957.66	584.544
1958.13	593.971
1958.59	600.934
1959.05	630.779
1959.51	633.311
1959.97	625.292
1960.43	578.225
1960.89	620.215
1961.36	604.581
1961.82	617.185
1962.28	629.095
1962.74	623.747
1963.2	635.877
1963.66	611.824
1964.12	589.775
1964.58	597.293
1965.04	587.835
1965.51	600.189
1965.97	600.582
1966.43	613.04
1966.89	591.473
1967.35	592.99
1967.81	627.416
1968.27	607.236
1968.73	606.847
1969.19	595.858
1969.65	609.704
1970.11	595.328
1970.57	618.467
1971.04	600.581
1971.49	616.42
1971.96	611.731
1972.42	605.488
1972.88	613.314
1973.34	609.764
1973.8	632.102
1974.26	610.365
1974.72	594.39
1975.18	591.755
1975.64	610.472
1976.1	595.788
1976.56	597.437
1977.02	610.593
1977.48	621.928
1977.94	631.363
1978.4	620.96
1978.86	605.006
1979.32	598.75
1979.78	610.125
1980.24	610.187
1980.7	621.49
1981.16	617.786
1981.62	608.198
1982.08	617.511
1982.54	634.153
1983	604.486
1983.46	617.62
1983.91	625.312
1984.37	621.13
1984.83	622.694
1985.29	609.853
1985.75	637.917
1986.21	634.148
1986.67	616.601
1987.13	624.268
1987.59	638.777
1988.05	621.145
1988.51	618.807
1988.67	624.776
1989.14	611.725
1989.6	672.673
1990.07	599.621
1990.53	606.069
1990.99	629.018
1991.46	619.966
1991.92	612.914
1992.39	607.862
1992.85	622.311
1993.32	642.259
1993.78	623.707
1994.24	642.155
1994.71	648.104
1995.17	625.052
1995.64	652.5
1996.1	639.948
1996.57	617.896
1997.03	611.845
1997.5	604.793
1997.96	669.241
1998.42	627.689
1998.89	656.138
1999.35	615.586
1999.82	640.034