File: DateTimeSpectrumPointNumber1.txt
#Acq. time (s)=	1
#Accumulations=	2
#Range (cm-¹)=	3000...7000
#Windows=	16
#Autofocus=	Off
#AutoExposure=	Off
#Spike filter=	Multiple accum.
#Delay time (s)=	0
#Binning=	1
#Readout mode=	Signal
#DeNoise=	Off
#ICS correction=	Off
#Dark correction=	Off
#Inst. Process=	Off
#Instrument=	LabRAM HR Evol
#Detector=	Emulator CCD
#Objective=	x100
#Grating=	1800 gr/mm
#ND Filter=	100%
#Laser (nm)=	512
#Slit=	150.001
#Hole=	70.0087
#Project=	A
#Sample=	B
#Site=	C
#Title=	D_12
#Remark=
#Date=	06.10.2017 22:02
#Acquired=	06.10.2017 22:02:56
3001.39	1720
3005.41	1712.05
3009.42	1740.09
3013.43	1747.14
3017.44	1719.19
3021.44	1788.23
3025.44	1712.28
3029.44	1691.33
3033.43	1695.38
3037.42	1709.42
3041.41	1675.47
3045.4	1712.52
3049.38	1729.56
3053.36	1738.61
3057.34	1658.66
3061.31	1701.7
3065.28	1676.75
3069.25	1653.8
3073.22	1660.84
3077.18	1651.89
3081.14	1658.94
3085.09	1654.99
3089.05	1664.03
3093	1638.08
3096.94	1640.13
3100.89	1609.17
3104.83	1625.22
3108.77	1611.27
3112.7	1610.31
3116.64	1587.36
3120.56	1639.41
3124.49	1603.46
3128.41	1620.5
3132.34	1562.55
3136.25	1575.6
3140.17	1575.64
3144.08	1553.69
3147.99	1557.74
3151.9	1549.78
3155.8	1552.83
3159.7	1519.88
3163.6	1517.92
3167.49	1526.97
3171.38	1568.02
3175.27	1517.07
3179.16	1515.11
3183.04	1564.16
3186.92	1507.21
3190.8	1502.25
3194.67	1520.3
3198.54	1479.35
3202.41	1482.39
3206.28	1448.44
3210.14	1470.49
3214	1463.53
3217.85	1439.58
3221.71	1447.63
3225.56	1504.68
3229.41	1469.72
3233.25	1458.77
3237.1	1459.82
3240.93	1419.86
3244.77	1377.91
3248.6	1410.96
3252.44	1368
3256.26	1445.05
3260.09	1385.1
3263.91	1372.14
3267.73	1356.19
3271.55	1346.24
3275.36	1339.29
3279.17	1336.33
3282.98	1345.38
3286.78	1304.43
3290.59	1310.47
3294.38	1288.52
3298.18	1307.57
3301.97	1279.61
3305.76	1305.66
3309.55	1302.71
3313.34	1293.75
3317.12	1274.8
3320.9	1298.85
3324.67	1248.9
3328.45	1234.94
3332.22	1235.99
3335.99	1288.04
3339.75	1223.08
3343.51	1212.13
3347.27	1203.18
3351.03	1207.22
3354.78	1169.27
3358.53	1169.42
3362.28	1178.69
3366.03	1170.98
3369.77	1153.07
3373.51	1156.55
3377.24	1145.67
3380.98	1161.69
3384.71	1152.24
3388.44	1127.37
3392.16	1117.18
3395.88	1112.28
3399.55	1111.63
3403.32	1129.63
3407.09	1091.63
3410.85	1085.63
3414.61	1138.63
3418.37	1087.63
3422.12	1120.63
3425.88	1043.63
3429.63	1043.63
3433.38	1095.63
3437.12	1013.63
3440.86	1022.63
3444.6	1003.63
3448.33	1057.63
3452.07	1018.63
3455.8	1052.63
3459.53	1004.63
3463.25	998.631
3466.97	994.631
3470.69	957.632
3474.41	981.632
3478.12	951.632
3481.83	933.632
3485.54	965.633
3489.25	947.633
3492.95	939.633
3496.65	963.633
3500.35	963.634
3504.04	892.634
3507.74	917.634
3511.42	909.635
3515.11	882.635
3518.79	864.635
3522.48	886.635
3526.15	899.636
3529.83	894.636
3533.5	865.636
3537.17	876.636
3540.84	842.637
3544.5	826.637
3548.17	889.637
3551.83	818.638
3555.48	844.638
3559.14	799.638
3562.79	795.638
3566.44	818.639
3570.08	821.639
3573.72	825.639
3577.37	848.639
3581	795.64
3584.64	824.64
3588.27	779.64
3591.9	795.641
3595.53	823.641
3599.15	776.641
3602.77	736.641
3606.39	802.642
3610.01	766.642
3613.62	746.642
3617.23	764.642
3620.84	793.643
3624.44	746.643
3628.05	717.643
3631.64	700.644
3635.24	731.644
3638.84	745.644
3642.43	677.644
3646.02	680.645
3649.6	714.645
3653.19	669.645
3656.77	676.645
3660.35	648.646
3663.92	686.646
3667.49	668.646
3671.06	681.646
3674.63	683.647
3678.2	666.647
3681.76	626.647
3685.32	632.648
3688.88	615.648
3692.43	668.648
3695.98	624.648
3699.53	605.38
3703.08	625.764
3706.62	637.119
3710.16	637.304
3713.7	593.473
3717.24	628.574
3720.77	600.524
3724.3	581.34
3727.83	598.426
3731.35	610.491
3734.67	568.634
3738.24	577.678
3741.81	560.722
3745.37	559.766
3748.94	584.81
3752.5	590.854
3756.06	569.898
3759.61	570.942
3763.17	556.986
3766.72	595.03
3770.26	571.074
3773.81	579.118
3777.35	544.162
3780.89	528.206
3784.43	523.25
3787.96	521.294
3791.5	564.338
3795.03	502.382
3798.55	532.426
3802.08	560.47
3805.6	528.514
3809.12	524.558
3812.63	499.602
3816.15	533.646
3819.66	549.69
3823.17	488.734
3826.68	486.778
3830.18	495.822
3833.68	520.866
3837.18	486.91
3840.68	470.954
3844.17	527.998
3847.66	525.042
3851.15	466.086
3854.64	472.13
3858.12	453.174
3861.6	503.218
3865.08	468.262
3868.55	482.306
3872.03	497.35
3875.5	471.394
3878.97	482.438
3882.43	488.482
3885.89	460.526
3889.35	447.57
3892.81	467.614
3896.27	497.658
3899.72	436.702
3903.17	466.746
3906.62	446.79
3910.06	499.834
3913.51	476.878
3916.95	428.922
3920.38	481.966
3923.82	460.01
3927.25	408.054
3930.68	425.098
3934.11	416.142
3937.53	417.186
3940.96	401.23
3944.38	462.274
3947.79	419.318
3951.21	403.362
3954.62	423.406
3958.03	406.45
3961.44	432.494
3964.84	420.538
3968.24	399.582
3971.64	419.626
3975.04	387.67
3978.43	392.714
3981.82	452.758
3985.22	452.802
3988.6	385.846
3991.99	434.89
3995.37	408.934
3998.75	414.978
4002.12	394.022
4005.5	420.066
4008.87	406.11
4012.24	396.154
4015.61	375.198
4018.97	399.813
4022.33	380.366
4025.69	371.197
4029.05	393.983
4032.4	375.996
4035.76	382.263
4039.1	379.31
4042.45	371.192
4045.8	410.827
4049.14	389.038
4052.4	364.32
4055.79	356.298
4059.17	377.277
4062.55	377.255
4065.93	386.234
4069.31	384.213
4072.68	385.191
4076.06	357.17
4079.43	382.149
4082.79	349.127
4086.16	387.106
4089.52	394.085
4092.88	349.063
4096.24	341.042
4099.59	352.021
4102.95	392.999
4106.3	341.978
4109.64	371.957
4112.99	394.935
4116.33	340.914
4119.67	384.893
4123.01	363.871
4126.35	336.85
4129.68	335.829
4133.01	332.807
4136.34	331.786
4139.67	364.765
4142.99	401.743
4146.31	348.722
4149.63	367.701
4152.95	350.679
4156.26	348.658
4159.57	390.637
4162.88	335.615
4166.19	347.594
4169.49	351.573
4172.79	357.551
4176.09	333.53
4179.39	394.509
4182.69	331.487
4185.98	338.466
4189.27	389.445
4192.56	339.423
4195.84	341.402
4199.12	346.381
4202.4	330.359
4205.68	336.338
4208.96	403.317
4212.23	318.295
4215.5	412.274
4218.77	328.253
4222.04	326.231
4225.3	318.21
4228.56	332.188
4231.82	317.167
4235.07	339.146
4238.33	399.124
4241.58	386.103
4244.83	348.082
4248.08	321.06
4251.32	320.039
4254.56	334.018
4257.8	329.996
4261.04	314.975
4264.27	349.954
4267.51	358.932
4270.74	314.911
4273.97	334.89
4277.19	317.868
4280.41	324.847
4283.63	342.826
4286.85	370.804
4290.07	326.783
4293.28	353.762
4296.49	355.74
4299.7	379.719
4302.91	379.698
4306.11	379.676
4309.31	324.655
4312.51	316.634
4315.71	329.612
4318.9	320.591
4322.1	317.653
4325.29	316.206
4328.48	351.733
4331.66	316.521
4334.84	320.083
4338.02	342.73
4341.2	332.248
4344.38	365.267
4347.55	341.909
4350.72	357.893
4353.8	330.096
4357.02	314.088
4360.23	316.079
4363.44	332.071
4366.65	367.063
4369.85	332.054
4373.06	400.046
4376.26	374.038
4379.46	337.029
4382.66	347.021
4385.85	325.013
4389.04	367.004
4392.23	389.996
4395.42	329.988
4398.61	317.979
4401.79	373.971
4404.97	312.963
4408.15	332.954
4411.33	306.946
4414.5	342.938
4417.67	321.929
4420.84	319.921
4424.01	327.913
4427.18	314.904
4430.34	357.896
4433.5	352.888
4436.66	376.879
4439.81	349.871
4442.97	327.863
4446.12	339.854
4449.27	311.846
4452.41	330.838
4455.56	307.829
4458.7	393.821
4461.84	348.813
4464.98	313.804
4468.11	358.796
4471.25	321.788
4474.38	311.779
4477.5	323.771
4480.63	348.763
4483.75	340.754
4486.88	318.746
4490	319.738
4493.11	314.729
4496.23	354.721
4499.34	307.713
4502.45	356.704
4505.56	381.696
4508.67	338.688
4511.77	315.679
4514.87	353.671
4517.97	320.663
4521.07	312.654
4524.16	365.646
4527.25	342.638
4530.34	339.629
4533.43	311.621
4536.52	368.613
4539.6	304.604
4542.68	365.596
4545.76	392.588
4548.84	322.579
4551.91	372.571
4554.98	330.563
4558.05	339.554
4561.12	320.546
4564.19	304.538
4567.25	337.529
4570.31	384.521
4573.37	337.513
4576.43	321.504
4579.48	327.496
4582.53	378.488
4585.58	314.479
4588.63	311.471
4591.68	314.463
4594.72	336.454
4597.76	303.446
4600.8	356.438
4603.83	319.429
4606.87	303.421
4609.9	459.68
4612.93	318.799
4615.96	315.243
4618.98	380.312
4622.01	331.403
4625.03	360.177
4628.04	327.491
4631.06	325.673
4634.07	346.815
4637.09	322.492
4640.1	361.817
4643.02	319.031
4646.07	376.067
4649.12	365.102
4652.17	315.138
4655.22	347.174
4658.27	349.21
4661.31	304.246
4664.35	345.282
4667.38	379.318
4670.42	328.354
4673.45	306.39
4676.49	309.426
4679.52	343.462
4682.54	328.498
4685.57	341.534
4688.59	309.57
4691.61	344.606
4694.63	310.642
4697.65	339.678
4700.66	360.714
4703.67	307.75
4706.68	312.786
4709.69	383.822
4712.7	309.858
4715.7	334.894
4718.7	351.93
4721.7	363.966
4724.7	334.002
4727.69	310.038
4730.68	360.074
4733.67	341.11
4736.66	342.146
4739.65	364.182
4742.63	336.218
4745.61	352.254
4748.59	378.29
4751.57	326.326
4754.55	310.362
4757.52	321.398
4760.49	317.434
4763.46	325.47
4766.43	314.506
4769.39	326.542
4772.35	312.578
4775.31	334.614
4778.27	362.65
4781.23	314.685
4784.18	360.721
4787.13	351.757
4790.08	350.793
4793.03	338.829
4795.98	373.865
4798.92	348.901
4801.86	309.937
4804.8	312.973
4807.74	334.009
4810.67	318.045
4813.61	341.081
4816.54	334.117
4819.46	356.153
4822.39	317.189
4825.31	325.225
4828.24	312.261
4831.16	330.297
4834.07	363.333
4836.99	334.369
4839.9	331.405
4842.81	317.441
4845.72	334.477
4848.63	383.513
4851.54	307.549
4854.44	340.585
4857.34	388.621
4860.24	352.657
4863.13	370.693
4866.03	331.729
4868.92	312.765
4871.81	349.801
4874.7	358.837
4877.59	321.873
4880.47	319.909
4883.35	311.945
4886.23	334.09
4889.11	318.427
4891.99	387.924
4894.86	346.36
4897.73	328.86
4900.6	333.476
4903.47	330.691
4906.33	329.459
4909.19	318.49
4912.06	317.925
4914.93	324.754
4917.83	331.743
4920.73	309.732
4923.63	347.722
4926.53	308.711
4929.43	359.7
4932.32	372.689
4935.21	311.679
4938.1	315.668
4940.99	336.657
4943.88	307.647
4946.76	317.636
4949.64	327.625
4952.52	305.614
4955.4	313.604
4958.27	318.593
4961.15	323.582
4964.02	351.572
4966.88	325.561
4969.75	314.55
4972.62	366.539
4975.48	369.529
4978.34	320.518
4981.2	314.507
4984.06	312.497
4986.91	335.486
4989.76	393.475
4992.61	397.464
4995.46	381.454
4998.31	372.443
5001.15	309.432
5004	331.422
5006.84	357.411
5009.67	329.4
5012.51	308.389
5015.35	325.379
5018.18	332.368
5021.01	356.357
5023.84	339.347
5026.66	389.336
5029.49	341.325
5032.31	342.314
5035.13	313.304
5037.95	367.293
5040.76	316.282
5043.58	326.272
5046.39	329.261
5049.2	325.25
5052.01	357.239
5054.81	314.229
5057.62	327.218
5060.42	375.207
5063.22	316.197
5066.02	358.186
5068.81	355.175
5071.61	365.164
5074.4	341.154
5077.19	363.143
5079.98	324.132
5082.76	309.121
5085.55	323.111
5088.33	310.1
5091.11	378.089
5093.88	390.079
5096.66	367.068
5099.43	340.057
5102.21	340.046
5104.98	397.036
5107.74	312.025
5110.51	312.014
5113.27	356.004
5116.03	351.993
5118.79	360.982
5121.55	364.971
5124.31	344.961
5127.06	369.95
5129.81	388.939
5132.56	340.929
5135.31	345.918
5138.05	368.907
5140.8	322.896
5143.54	345.886
5146.28	361.945
5149.02	358.359
5151.75	344.746
5154.49	324.226
5157.22	373.835
5159.95	371.14
5162.68	335.904
5165.4	360.558
5168.13	343.659
5170.85	349.509
5173.52	390.18
5176.29	362.169
5179.05	366.158
5181.81	359.146
5184.57	354.135
5187.32	361.124
5190.08	363.112
5192.83	352.101
5195.58	324.09
5198.33	369.078
5201.08	349.067
5203.82	385.056
5206.56	386.044
5209.3	357.033
5212.04	361.022
5214.78	371.01
5217.51	388.999
5220.25	343.988
5222.98	347.976
5225.71	332.965
5228.43	335.954
5231.16	327.942
5233.88	342.931
5236.6	405.92
5239.32	337.908
5242.04	344.897
5244.75	328.886
5247.47	397.874
5250.18	368.863
5252.89	339.852
5255.6	352.84
5258.3	389.829
5261.01	382.818
5263.71	370.806
5266.41	364.795
5269.1	374.784
5271.8	388.772
5274.5	388.761
5277.19	360.75
5279.88	385.738
5282.57	368.727
5285.25	384.716
5287.94	396.704
5290.62	394.693
5293.3	355.682
5295.98	406.67
5298.66	381.659
5301.33	396.648
5304	379.636
5306.68	355.625
5309.35	394.614
5312.01	392.602
5314.68	354.591
5317.34	415.58
5320	427.568
5322.66	380.557
5325.32	402.546
5327.98	422.534
5330.63	380.523
5333.28	361.512
5335.93	370.5
5338.58	391.489
5341.23	398.478
5343.87	374.466
5346.51	434.455
5349.15	407.444
5351.79	422.432
5354.43	405.421
5357.06	403.41
5359.7	374.398
5362.33	369.387
5364.96	416.376
5367.58	388.364
5370.21	374.353
5372.83	437.342
5375.45	416.33
5378.07	389.319
5380.69	382.308
5383.31	418.296
5385.92	384.285
5388.53	433.274
5391.14	468.262
5393.75	437.643
5396.36	422.62
5398.96	395.855
5401.56	450.878
5404.17	401.429
5406.76	424.857
5409.36	395.726
5411.96	453.118
5414.55	423.206
5417.14	418.982
5419.73	440.757
5422.27	407.452
5424.9	459.463
5427.53	416.473
5430.16	455.484
5432.78	424.495
5435.41	456.506
5438.03	454.516
5440.65	460.527
5443.26	433.538
5445.88	451.549
5448.49	437.56
5451.11	480.57
5453.72	428.581
5456.33	437.592
5458.93	450.603
5461.54	441.613
5464.14	439.624
5466.74	489.635
5469.34	442.646
5471.94	459.657
5474.54	453.667
5477.13	474.678
5479.72	487.689
5482.31	459.7
5484.9	473.711
5487.49	450.721
5490.07	491.732
5492.66	494.743
5495.24	496.754
5497.82	538.764
5500.39	522.775
5502.97	512.786
5505.54	475.797
5508.12	510.808
5510.69	480.818
5513.25	502.829
5515.82	488.84
5518.39	481.851
5520.95	537.861
5523.51	489.872
5526.07	502.883
5528.63	500.894
5531.18	502.905
5533.74	521.915
5536.29	508.926
5538.84	550.937
5541.39	580.948
5543.93	589.958
5546.48	602.969
5549.02	563.98
5551.56	546.991
5554.1	552.002
5556.64	526.012
5559.17	621.023
5561.71	596.034
5564.24	594.045
5566.77	568.056
5569.3	606.066
5571.82	569.077
5574.35	625.088
5576.87	553.099
5579.39	643.109
5581.91	635.12
5584.43	595.131
5586.94	595.142
5589.46	580.152
5591.97	611.163
5594.48	609.174
5596.99	630.185
5599.49	585.196
5602	642.206
5604.5	653.217
5607	630.228
5609.5	613.239
5612	623.25
5614.49	646.26
5616.99	626.271
5619.48	632.282
5621.97	658.293
5624.46	664.303
5626.95	633.314
5629.43	633.197
5631.91	656.204
5634.4	669.811
5636.87	703.377
5639.35	671.721
5641.83	665.523
5644.3	694.201
5646.77	728.678
5649.24	722.246
5651.71	710.703
5654.18	731.281
5656.62	730.809
5659.13	750.832
5661.64	710.856
5664.14	697.88
5666.64	727.903
5669.14	699.927
5671.64	759.951
5674.14	755.974
5676.64	724.998
5679.13	735.021
5681.62	802.045
5684.11	738.069
5686.6	755.093
5689.09	788.116
5691.57	795.14
5694.06	754.164
5696.54	786.187
5699.02	774.211
5701.49	803.234
5703.97	782.258
5706.44	777.282
5708.92	856.305
5711.39	800.329
5713.86	804.353
5716.32	850.376
5718.79	857.4
5721.25	811.424
5723.72	867.447
5726.18	830.471
5728.63	849.495
5731.09	851.518
5733.55	896.542
5736	853.566
5738.45	917.589
5740.9	854.613
5743.35	919.637
5745.8	936.66
5748.24	893.684
5750.68	907.708
5753.13	884.731
5755.57	926.755
5758	913.779
5760.44	899.802
5762.87	922.826
5765.31	928.85
5767.74	955.873
5770.17	991.897
5772.59	950.921
5775.02	947.944
5777.44	962.968
5779.86	972.992
5782.29	988.015
5784.7	1039.04
5787.12	969.063
5789.54	1006.09
5791.95	1016.11
5794.36	983.134
5796.77	986.157
5799.18	998.181
5801.59	1060.2
5803.99	1008.23
5806.39	1060.25
5808.8	1022.28
5811.2	1027.3
5813.59	1041.32
5815.99	1038.35
5818.38	1086.37
5820.78	1090.39
5823.17	1086.42
5825.56	1075.44
5827.95	1076.46
5830.33	1089.49
5832.71	1111.51
5835.1	1094.54
5837.48	1138.56
5839.86	1172.58
5842.24	1175.61
5844.61	1134.63
5846.98	1143.65
5849.36	1186.68
5851.73	1134.7
5854.1	1155.58
5856.46	1151.44
5858.83	1222.94
5861.19	1185.57
5863.55	1202.67
5865.91	1189.67
5868.27	1227.35
5870.63	1219.11
5872.98	1215.73
5875.34	1244.85
5877.69	1221.66
5879.86	1262.05
5882.25	1253.04
5884.64	1233.02
5887.03	1231.01
5889.42	1285
5891.81	1250.98
5894.19	1288.97
5896.57	1322.96
5898.95	1267.94
5901.33	1284.93
5903.71	1275.92
5906.08	1311.9
5908.46	1324.89
5910.83	1323.88
5913.2	1315.86
5915.57	1352.85
5917.93	1315.84
5920.3	1369.82
5922.66	1353.81
5925.02	1331.8
5927.38	1367.78
5929.74	1371.77
5932.1	1389.76
5934.46	1360.75
5936.81	1391.73
5939.16	1375.72
5941.51	1383.71
5943.86	1396.69
5946.21	1412.68
5948.55	1407.67
5950.9	1421.65
5953.24	1427.64
5955.58	1433.63
5957.92	1417.61
5960.25	1452.6
5962.59	1438.59
5964.92	1432.57
5967.26	1440.56
5969.59	1482.55
5971.91	1515.53
5974.24	1471.52
5976.57	1496.51
5978.89	1527.49
5981.21	1491.48
5983.53	1508.47
5985.85	1530.45
5988.17	1510.44
5990.48	1519.43
5992.8	1539.42
5995.11	1567.4
5997.42	1567.39
5999.73	1529.38
6002.04	1524.36
6004.34	1536.35
6006.65	1564.34
6008.95	1568.32
6011.25	1612.31
6013.55	1608.3
6015.85	1579.28
6018.14	1563.27
6020.44	1610.26
6022.73	1593.24
6025.02	1583.23
6027.31	1594.22
6029.6	1618.2
6031.88	1614.19
6034.17	1638.18
6036.45	1675.16
6038.73	1619.15
6041.01	1634.14
6043.29	1683.12
6045.56	1618.11
6047.84	1692.1
6050.11	1676.08
6052.38	1636.07
6054.65	1673.06
6056.92	1675.05
6059.18	1676.03
6061.45	1658.02
6063.71	1705.01
6065.97	1652.99
6068.23	1661.98
6070.49	1666.13
6072.75	1669.53
6075	1715.99
6077.25	1724.94
6079.5	1689.74
6081.75	1727.6
6084	1720.71
6086.25	1713.54
6088.49	1695.93
6090.74	1705.15
6092.84	1730.79
6095.12	1756.78
6097.4	1766.78
6099.68	1738.78
6101.96	1728.78
6104.24	1744.78
6106.51	1738.78
6108.79	1746.77
6111.06	1806.77
6113.33	1799.77
6115.6	1735.77
6117.87	1738.77
6120.13	1762.77
6122.39	1796.77
6124.66	1764.76
6126.92	1757.76
6129.18	1775.76
6131.44	1766.76
6133.69	1767.76
6135.95	1827.76
6138.2	1767.76
6140.45	1767.75
6142.7	1791.75
6144.95	1770.75
6147.19	1802.75
6149.44	1767.75
6151.68	1760.75
6153.93	1797.75
6156.17	1794.74
6158.4	1815.74
6160.64	1790.74
6162.88	1823.74
6165.11	1799.74
6167.34	1809.74
6169.57	1808.74
6171.8	1788.73
6174.03	1833.73
6176.26	1774.73
6178.48	1784.73
6180.7	1821.73
6182.92	1858.73
6185.15	1781.72
6187.36	1831.72
6189.58	1773.72
6191.79	1780.72
6194.01	1777.72
6196.22	1774.72
6198.43	1813.72
6200.64	1781.71
6202.85	1773.71
6205.05	1782.71
6207.25	1803.71
6209.46	1817.71
6211.66	1816.71
6213.86	1792.71
6216.05	1806.7
6218.25	1781.7
6220.44	1821.7
6222.64	1784.7
6224.83	1782.7
6227.02	1777.7
6229.21	1808.7
6231.39	1825.69
6233.58	1797.69
6235.76	1799.69
6237.94	1797.69
6240.12	1765.69
6242.3	1775.69
6244.48	1792.69
6246.65	1757.68
6248.83	1777.68
6251	1763.68
6253.17	1756.68
6255.34	1800.68
6257.51	1757.68
6259.68	1764.68
6261.84	1748.67
6264	1792.67
6266.16	1740.67
6268.33	1765.67
6270.48	1810.67
6272.64	1759.67
6274.79	1770.33
6276.95	1760.21
6279.1	1745.72
6281.25	1770.55
6283.4	1742.83
6285.55	1729.72
6287.69	1760.53
6289.84	1788.74
6291.98	1728.62
6294.12	1720.21
6296.26	1773.98
6298.28	1712.45
6300.46	1738.46
6302.64	1737.48
6304.81	1714.49
6306.99	1702.51
6309.16	1690.53
6311.33	1704.54
6313.5	1721.56
6315.67	1678.58
6317.84	1669.59
6320	1673.61
6322.16	1664.62
6324.33	1662.64
6326.49	1661.66
6328.65	1651.67
6330.8	1720.69
6332.96	1694.71
6335.12	1636.72
6337.27	1645.74
6339.42	1676.75
6341.57	1677.77
6343.72	1632.79
6345.86	1622.8
6348.01	1635.82
6350.15	1657.84
6352.3	1621.85
6354.44	1620.87
6356.58	1656.88
6358.72	1637.9
6360.85	1627.92
6362.99	1591.93
6365.12	1646.95
6367.25	1611.97
6369.38	1576.98
6371.51	1628
6373.64	1563.01
6375.76	1576.03
6377.89	1565.05
6380.01	1617.06
6382.13	1620.08
6384.25	1622.1
6386.37	1528.11
6388.49	1547.13
6390.6	1558.14
6392.72	1521.16
6394.83	1517.18
6396.94	1509.19
6399.05	1501.21
6401.16	1504.23
6403.26	1500.24
6405.37	1504.26
6407.47	1508.27
6409.57	1545.29
6411.67	1484.31
6413.77	1457.32
6415.87	1452.34
6417.96	1473.36
6420.06	1505.37
6422.15	1455.39
6424.24	1507.4
6426.33	1458.42
6428.42	1501.44
6430.5	1412.45
6432.59	1453.47
6434.67	1420.48
6436.75	1465.5
6438.83	1441.52
6440.91	1427.53
6442.99	1397.55
6445.07	1371.57
6447.14	1384.58
6449.22	1428.6
6451.29	1428.61
6453.36	1347.63
6455.43	1375.65
6457.49	1345.66
6459.56	1337.68
6461.62	1347.7
6463.69	1381.71
6465.75	1319.73
6467.81	1309.74
6469.86	1308.76
6471.92	1331.11
6473.98	1365.07
6476.03	1302.03
6478.08	1312.79
6480.13	1318.52
6482.18	1278.53
6484.23	1283.69
6486.28	1265.61
6488.32	1285.79
6490.36	1298.08
6492.39	1278.9
6494.47	1267.92
6496.55	1223.93
6498.63	1225.95
6500.71	1240.97
6502.78	1214.99
6504.86	1210
6506.93	1263.02
6509	1234.04
6511.07	1263.06
6513.14	1250.07
6515.21	1166.09
6517.28	1247.11
6519.34	1184.13
6521.4	1158.15
6523.47	1167.16
6525.53	1151.18
6527.59	1146.2
6529.64	1175.22
6531.7	1164.23
6533.75	1155.25
6535.81	1166.27
6537.86	1140.29
6539.91	1110.3
6541.96	1102.32
6544.01	1103.34
6546.05	1102.36
6548.1	1117.37
6550.14	1077.39
6552.18	1075.41
6554.22	1064.43
6556.26	1077.44
6558.3	1040.46
6560.33	1102.48
6562.37	1036.5
6564.4	1032.52
6566.43	1019.53
6568.46	1014.55
6570.49	1052.57
6572.52	1018.59
6574.54	1060.6
6576.57	1033.62
6578.59	1001.64
6580.61	974.656
6582.63	969.674
6584.65	989.692
6586.67	978.709
6588.68	972.727
6590.7	962.745
6592.71	953.762
6594.72	966.78
6596.73	980.798
6598.74	941.815
6600.74	979.833
6602.75	964.85
6604.75	950.868
6606.76	912.886
6608.76	955.903
6610.76	919.921
6612.76	923.939
6614.75	884.956
6616.75	885.974
6618.74	935.991
6620.73	880.009
6622.73	898.027
6624.72	858.044
6626.7	883.062
6628.69	883.08
6630.68	861.097
6632.66	922.115
6634.64	846.133
6636.62	870.15
6638.6	823.168
6640.58	821.185
6642.56	825.203
6644.53	809.221
6646.51	816.238
6648.48	804.256
6650.45	822.274
6652.42	786.291
6654.39	798.309
6656.35	809.326
6658.32	791.594
6660.28	848.927
6662.25	769.843
6664.21	781.853
6666.17	775.342
6668.12	783.488
6670.08	762.71
6672.04	797.773
6673.99	777.43
6675.94	737.873
6677.89	760.321
6679.81	773.431
6681.8	715.404
6683.79	721.378
6685.77	726.352
6687.76	786.334
6689.74	745.316
6691.73	697.299
6693.71	761.281
6695.69	689.263
6697.66	762.246
6699.64	693.228
6701.62	680.21
6703.59	714.193
6705.56	662.175
6707.53	704.157
6709.5	654.14
6711.47	660.122
6713.44	698.104
6715.4	677.087
6717.37	717.069
6719.33	641.051
6721.29	700.034
6723.25	692.016
6725.21	662.998
6727.17	653.981
6729.12	646.963
6731.08	642.945
6733.03	607.927
6734.98	604.91
6736.93	634.892
6738.88	609.875
6740.83	612.857
6742.78	607.839
6744.72	589.821
6746.66	628.804
6748.61	579.786
6750.55	574.768
6752.48	574.751
6754.42	582.733
6756.36	607.715
6758.29	567.698
6760.23	598.68
6762.16	594.662
6764.09	631.645
6766.02	555.627
6767.95	566.609
6769.88	596.592
6771.8	576.574
6773.72	551.556
6775.65	605.539
6777.57	570.521
6779.49	566.503
6781.41	564.486
6783.32	573.468
6785.24	569.45
6787.15	564.433
6789.07	544.415
6790.98	521.397
6792.89	520.38
6794.8	531.362
6796.7	509.344
6798.61	507.326
6800.51	497.309
6802.42	516.291
6804.32	505.273
6806.22	506.256
6808.12	487.238
6810.02	507.22
6811.91	489.203
6813.81	547.185
6815.7	493.167
6817.59	483.15
6819.48	488.132
6821.37	531.114
6823.26	491.097
6825.15	469.079
6827.03	492.061
6828.92	462.044
6830.8	473.026
6832.68	537.008
6834.56	453.991
6836.44	511.8
6838.32	522.063
6840.19	452.966
6842.07	498.849
6843.94	498.954
6845.81	462.285
6847.68	499.976
6849.55	465.41
6851.42	459.858
6853.28	513.048
6855.15	475.081
6856.94	457.421
6858.84	471.364
6860.75	455.307
6862.65	433.25
6864.54	474.192
6866.44	477.135
6868.34	440.078
6870.23	421.021
6872.12	442.964
6874.02	462.906
6875.91	482.849
6877.8	422.792
6879.68	417.735
6881.57	431.678
6883.46	484.62
6885.34	482.563
6887.22	491.506
6889.1	454.449
6890.98	413.392
6892.86	401.335
6894.74	418.277
6896.61	456.22
6898.49	444.163
6900.36	468.106
6902.23	417.049
6904.1	418.991
6905.97	461.934
6907.84	411.877
6909.71	397.82
6911.57	394.763
6913.44	403.705
6915.3	421.648
6917.16	409.591
6919.02	382.534
6920.88	394.477
6922.73	389.419
6924.59	399.362
6926.45	385.305
6928.3	387.248
6930.15	429.191
6932	388.133
6933.85	397.076
6935.7	383.019
6937.54	390.962
6939.39	399.905
6941.23	420.847
6943.08	384.79
6944.92	398.733
6946.76	365.676
6948.59	404.619
6950.43	409.561
6952.27	405.504
6954.1	389.447
6955.94	392.39
6957.77	381.333
6959.6	369.275
6961.43	433.218
6963.26	376.161
6965.08	408.104
6966.91	397.047
6968.73	426.989
6970.55	366.932
6972.37	429.875
6974.19	409.818
6976.01	381.761
6977.83	390.703
6979.65	348.646
6981.46	389.589
6983.27	343.532
6985.09	358.475
6986.9	385.418
6988.71	350.36
6990.51	387.303
6992.32	347.246
6994.13	370.189
6995.93	360.132
6997.73	365.074
6999.53	364.017
6999.9	361.006