File: DateTimeSpectrumPointNumber1.txt
#Acq. time (s)=	0.1
#Accumulations=	3
#Range (cm-¹)=	0...3000
#Windows=	7
#Autofocus=	Off
#AutoExposure=	Off
#Spike filter=	Multiple accum.
#Delay time (s)=	0
#Binning=	1
#Readout mode=	Signal
#DeNoise=	Off
#ICS correction=	Off
#Dark correction=	Off
#Inst. Process=	Off
#Instrument=	LabRAM HR Evol
#Detector=	Emulator CCD
#Objective=	x100
#Grating=	1800 gr/mm
#ND Filter=	100%
#Laser (nm)=	512
#Slit=	150.001
#Hole=	70.0087
#Project=	A
#Sample=	B
#Site=	C
#Title=	D_91
#Remark=
#Date=	18.10.2017 15:40
#Acquired=	18.10.2017 15:40:26
0.232828	363
3.23814	318.026
6.24252	339.553
9.24598	313.079
12.2485	321.106
15.2478	323.132
18.2485	343.658
21.2459	334.185
24.2425	331.711
27.2381	349.738
30.2328	328.264
33.2265	337.79
36.217	346.317
39.209	307.343
42.1977	301.369
45.1878	312.396
48.1746	325.422
51.1606	351.949
54.1433	329.475
57.1274	301.501
60.1106	307.028
63.0906	328.554
66.0696	355.581
69.0478	319.607
72.025	345.633
75.0013	326.16
77.9767	302.686
80.9512	313.713
83.9225	346.739
86.8929	344.765
89.8647	315.292
92.8333	355.318
95.8009	362.845
98.7654	308.371
101.731	315.897
104.696	317.424
107.658	331.95
110.619	336.976
113.579	324.003
116.538	341.029
119.496	308.556
122.453	325.082
125.407	308.608
128.362	327.135
131.315	361.161
134.266	352.688
137.216	341.214
140.166	312.24
143.115	323.267
146.06	328.293
149.007	349.32
151.951	337.346
154.893	331.372
157.835	341.399
160.776	323.925
163.716	345.451
166.655	310.478
169.591	357.004
172.527	327.531
175.463	310.557
178.396	315.583
181.329	366.61
184.258	321.636
187.189	302.663
190.119	320.189
193.045	306.715
195.971	317.242
198.896	317.768
201.82	344.795
204.743	342.821
207.665	316.847
210.584	335.374
213.505	359.9
216.422	347.927
219.338	324.953
222.254	307.979
225.168	341.006
228.08	307.032
230.993	303.059
233.902	308.585
236.814	338.111
239.721	303.138
242.629	352.164
245.533	363.69
248.438	368.717
251.342	338.743
254.244	318.27
257.144	361.296
260.044	334.822
262.942	323.349
265.84	304.375
268.737	371.402
271.633	302.928
274.526	360.454
277.418	305.481
280.309	313.507
283.2	309.534
286.089	343.56
288.978	308.586
291.863	337.113
294.75	317.639
297.634	328.665
300.517	318.692
303.399	309.718
306.28	325.745
309.16	302.771
312.038	333.797
314.914	339.324
317.792	364.85
320.666	349.377
323.54	342.403
326.413	308.929
329.283	392.956
332.154	327.982
335.022	347.009
337.889	373.535
340.755	309.061
343.621	353.088
346.485	352.114
349.349	327.641
352.21	341.667
355.072	322.693
357.931	315.22
360.789	342.246
363.646	341.772
366.503	350.299
369.356	327.325
372.211	340.852
375.062	334.878
377.913	305.404
380.763	315.431
383.612	365.957
386.46	328.984
389.308	379.51
392.152	317.036
394.995	326.563
397.838	328.589
400.682	342.116
403.521	365.642
406.361	329.668
409.2	357.695
412.036	316.221
414.871	310.747
417.706	335.774
420.54	326.8
423.372	335.827
426.204	380.353
429.033	315.879
431.863	317.906
434.691	349.432
437.517	344.959
440.343	353.485
443.167	315.011
445.989	322.038
448.812	334.064
451.632	319.091
454.451	332.617
457.269	349.143
460.087	399.67
462.904	338.696
465.719	325.223
468.532	317.249
471.344	317.275
474.155	370.302
476.965	318.328
479.775	337.854
482.583	326.881
485.389	371.907
488.196	333.434
491	305.46
493.803	305.486
496.605	338.513
499.407	389.539
502.205	315.066
505.005	342.592
507.802	327.618
510.598	350.645
513.393	309.671
516.187	312.698
518.981	316.724
521.773	341.25
524.563	316.777
527.352	312.803
530.14	334.83
532.927	322.992
535.713	340.812
538.499	324.07
541.281	329.603
544.063	321.641
546.846	349.444
549.626	338.91
552.403	342.696
555.182	334.409
557.959	342.117
560.734	313.862
563.508	354.453
566.283	356.259
569.053	339.222
571.824	367.635
574.595	346.241
577.363	333.774
580.131	351.407
582.897	337.444
585.663	360.705
588.022	331.914
590.816	376.933
593.61	329.951
596.402	330.469
599.192	321.988
601.983	345.506
604.771	369.525
607.558	336.043
610.347	324.062
613.132	350.58
615.915	327.098
618.699	320.117
621.482	321.135
624.262	337.154
627.041	352.172
629.822	357.191
632.599	321.209
635.374	339.227
638.15	322.246
640.925	373.264
643.697	311.283
646.469	336.301
649.241	321.32
652.011	350.338
654.78	334.356
657.546	331.875
660.313	310.393
663.078	338.412
665.843	323.93
668.606	304.449
671.368	333.467
674.129	367.485
676.889	341.004
679.647	333.022
682.405	322.541
685.161	376.559
687.916	354.578
690.67	360.596
693.423	328.115
696.176	320.633
698.928	338.651
701.676	342.67
704.424	322.688
707.173	349.707
709.92	328.225
712.663	320.744
715.408	334.762
718.152	368.28
720.893	364.799
723.635	321.317
726.374	365.836
729.113	330.854
731.851	316.873
734.587	335.891
737.321	322.909
740.057	335.928
742.789	340.946
745.521	348.965
748.252	356.983
750.982	349.502
753.711	323.02
756.437	361.038
759.165	340.057
761.89	316.075
764.613	307.094
767.337	313.112
770.059	345.631
772.78	320.649
775.501	328.167
778.219	313.186
780.936	309.204
783.652	345.223
786.368	364.241
789.082	341.76
791.796	310.278
794.509	351.296
797.219	308.315
799.929	308.333
802.637	333.352
805.345	318.37
808.052	311.889
810.759	331.407
813.462	338.425
816.167	326.944
818.868	351.962
821.569	325.481
824.27	316.499
826.969	352.018
829.668	319.536
832.363	324.054
835.06	325.573
837.755	339.091
840.448	316.61
843.141	320.628
845.83	330.647
848.521	305.665
851.212	335.684
853.899	315.702
856.586	351.22
859.272	388.239
861.957	354.257
864.641	344.776
867.322	307.794
870.005	316.813
872.685	315.831
875.364	340.349
878.043	334.368
880.72	309.886
883.397	323.905
886.071	329.423
888.746	329.942
891.418	314.96
894.09	319.478
896.761	332.997
899.431	340.015
902.098	336.034
904.767	330.052
907.432	310.071
910.097	372.089
912.761	322.107
915.425	341.126
918.087	313.144
920.747	329.163
923.408	326.181
926.066	390.2
928.724	352.218
931.381	338.736
934.037	347.755
936.692	338.773
939.344	345.792
941.996	385.81
944.648	308.329
947.299	323.847
949.948	316.865
952.594	350.384
955.242	325.902
957.887	337.421
960.533	329.439
963.177	339.958
965.819	309.476
968.461	327.494
971.1	321.513
973.741	321.531
976.378	382.55
979.015	317.568
981.651	339.087
984.286	343.105
986.921	329.623
989.555	307.642
992.186	326.16
994.816	352.179
997.448	338.697
1000.08	351.216
1002.7	351.734
1005.33	334.753
1007.96	313.271
1010.58	345.789
1013.2	377.808
1015.82	323.826
1018.45	345.845
1021.07	322.863
1023.69	322.882
1026.3	362.4
1028.92	314.918
1031.54	361.639
1034.15	364.814
1036.76	359.583
1039.38	342.952
1041.99	338.708
1044.6	328.977
1047.21	331.492
1049.82	332.705
1052.43	363.636
1055.03	344.022
1057.64	362.806
1060.24	348.469
1062.84	314.391
1065.45	339.143
1068.05	344.126
1070.65	358.751
1073.25	348.527
1075.84	346.374
1078.44	331.733
1081.04	331.013
1083.63	345.274
1086.07	324.209
1088.69	369.727
1091.31	323.746
1093.93	308.265
1096.55	348.283
1099.17	355.802
1101.79	339.321
1104.41	326.34
1107.02	332.358
1109.64	326.377
1112.25	320.896
1114.86	338.414
1117.47	350.933
1120.08	330.452
1122.69	362.47
1125.3	323.989
1127.91	311.008
1130.51	362.526
1133.12	313.545
1135.73	354.564
1138.33	318.582
1140.93	338.601
1143.53	315.62
1146.13	313.638
1148.73	326.157
1151.33	359.176
1153.93	336.194
1156.52	351.713
1159.12	309.732
1161.71	321.751
1164.3	336.769
1166.89	317.788
1169.49	369.807
1172.08	329.825
1174.66	325.344
1177.25	338.863
1179.84	337.881
1182.42	328.4
1185.01	354.919
1187.59	337.437
1190.17	325.956
1192.76	330.475
1195.34	329.493
1197.92	341.512
1200.5	329.531
1203.07	358.049
1205.65	320.568
1208.23	317.587
1210.8	339.105
1213.37	337.124
1215.95	309.143
1218.52	306.162
1221.09	349.18
1223.66	331.199
1226.22	338.218
1228.79	329.736
1231.36	323.755
1233.92	343.274
1236.49	332.792
1239.05	347.311
1241.61	321.33
1244.17	335.348
1246.73	345.867
1249.29	335.386
1251.85	348.904
1254.41	329.423
1256.96	369.442
1259.52	348.96
1262.07	312.479
1264.63	355.498
1267.18	348.517
1269.73	346.535
1272.28	355.054
1274.83	342.573
1277.37	353.091
1279.92	368.61
1282.47	374.129
1285.01	316.647
1287.56	356.166
1290.1	312.685
1292.64	332.703
1295.18	355.722
1297.72	374.741
1300.26	338.259
1302.8	309.778
1305.34	361.797
1307.87	338.815
1310.4	318.834
1312.94	375.353
1315.47	327.871
1318	362.39
1320.53	340.409
1323.06	375.928
1325.59	318.946
1328.12	363.965
1330.65	356.984
1333.17	323.002
1335.7	352.021
1338.22	327.04
1340.74	340.558
1343.26	336.077
1345.79	336.096
1348.3	311.114
1350.82	333.133
1353.34	356.152
1355.86	392.67
1358.37	337.189
1360.89	329.208
1363.4	317.226
1365.91	315.245
1368.42	343.764
1370.94	370.782
1373.44	345.301
1375.95	315.32
1378.46	335.839
1380.97	377.357
1383.47	342.376
1385.98	317.395
1388.48	329.413
1390.98	344.932
1393.49	353.451
1395.99	346.469
1398.48	340.488
1400.98	340.507
1403.48	361.525
1405.98	332.544
1408.47	334.563
1410.97	349.581
1413.46	373.1
1415.95	363.119
1418.45	383.137
1420.94	382.656
1423.42	354.675
1425.91	363.694
1428.4	327.712
1430.89	349.231
1433.37	344.25
1435.86	361.768
1438.34	377.787
1440.83	348.806
1443.31	371.324
1445.79	325.843
1448.27	320.862
1450.75	331.88
1453.22	362.899
1455.7	384.918
1458.17	353.936
1460.65	387.955
1463.12	380.474
1465.6	324.992
1468.07	387.011
1470.54	353.03
1473.01	331.548
1475.48	342.567
1477.94	349.586
1480.41	344.605
1482.88	356.123
1485.34	380.142
1487.81	372.161
1490.27	355.179
1492.73	377.198
1495.19	341.217
1497.65	383.235
1500.11	340.254
1502.57	367.659
1505.02	327.325
1507.48	375.114
1509.93	357.999
1512.39	366.965
1514.84	353.204
1517.29	344.629
1519.74	363.386
1522.19	349.447
1524.64	359.829
1527.09	355.58
1529.54	327.427
1531.99	337.483
1534.43	346.951
1536.87	368.691
1539.32	331.817
1541.76	338.885
1544.2	355.727
1546.64	354.564
1549.08	371.15
1551.08	327.941
1553.54	362.443
1556.01	332.945
1558.47	358.948
1560.94	345.95
1563.4	334.952
1565.86	356.954
1568.33	339.456
1570.79	344.459
1573.25	368.461
1575.7	340.963
1578.16	329.965
1580.62	334.967
1583.07	327.47
1585.53	345.972
1587.98	364.974
1590.43	348.976
1592.89	329.979
1595.34	332.981
1597.79	347.983
1600.24	375.985
1602.68	366.487
1605.13	373.99
1607.58	331.992
1610.02	363.494
1612.47	366.996
1614.91	404.998
1617.35	359.501
1619.79	346.003
1622.23	381.505
1624.67	364.007
1627.11	373.51
1629.55	357.012
1631.98	342.014
1634.42	377.516
1636.85	374.018
1639.29	389.021
1641.72	371.023
1644.15	396.025
1646.58	391.527
1649.01	352.529
1651.44	347.032
1653.87	343.034
1656.3	343.036
1658.72	342.038
1661.15	353.041
1663.57	349.543
1666	334.045
1668.42	388.547
1670.84	379.049
1673.26	374.052
1675.68	363.054
1678.1	379.056
1680.51	349.558
1682.93	358.06
1685.35	338.063
1687.76	349.565
1690.17	344.567
1692.59	374.569
1695	369.072
1697.41	345.574
1699.82	373.076
1702.23	367.078
1704.64	387.58
1707.05	361.083
1709.45	402.585
1711.86	347.087
1714.26	400.589
1716.66	356.091
1719.07	374.594
1721.47	379.596
1723.87	345.098
1726.27	366.1
1728.67	356.602
1731.06	357.605
1733.46	367.107
1735.86	352.109
1738.25	346.611
1740.64	352.114
1743.04	347.616
1745.43	369.118
1747.82	399.62
1750.21	375.122
1752.6	394.125
1754.99	357.127
1757.38	377.129
1759.76	429.131
1762.15	395.633
1764.53	400.636
1766.92	412.138
1769.3	368.64
1771.68	366.142
1774.06	405.145
1776.44	410.147
1778.82	390.649
1781.2	367.651
1783.58	367.153
1785.95	358.156
1788.33	400.158
1790.7	388.66
1793.07	362.162
1795.45	401.164
1797.82	391.167
1800.19	405.169
1802.56	407.671
1804.93	366.673
1807.29	370.176
1809.66	384.678
1812.03	359.18
1814.39	390.182
1816.76	366.184
1819.12	358.187
1821.48	425.689
1823.84	387.691
1826.2	393.193
1828.56	371.695
1830.92	374.198
1833.28	378.2
1835.64	369.702
1837.99	408.204
1840.34	431.707
1842.7	394.209
1845.05	409.211
1847.4	395.213
1849.76	365.215
1852.1	422.718
1854.45	365.22
1856.8	398.722
1859.15	379.224
1861.5	378.226
1863.84	426.229
1866.18	387.231
1868.53	432.233
1870.87	382.235
1873.21	424.738
1875.55	416.24
1877.89	373.242
1880.23	419.244
1882.57	390.246
1884.91	432.249
1887.25	430.251
1889.58	422.753
1891.91	384.255
1894.25	419.257
1896.58	382.26
1898.91	425.762
1901.24	383.264
1903.57	389.266
1905.9	402.769
1908.23	422.771
1910.56	408.273
1912.88	385.275
1915.21	433.277
1917.53	423.28
1919.86	406.282
1922.18	399.784
1924.5	434.786
1926.82	436.288
1929.14	417.791
1931.46	423.293
1933.78	419.795
1936.09	392.797
1938.41	438.799
1940.72	399.302
1943.04	442.554
1945.35	447.754
1947.66	451.441
1949.98	438.87
1952.29	423.036
1954.6	405.826
1956.9	419.483
1959.21	420.221
1961.52	431.772
1963.83	422.013
1966.13	422.054
1968.43	420.007
1970.74	435.824
1973.04	426.649
1975.34	425.076
1977.64	449.494
1979.94	407.232
1982.24	403.906
1984.54	479.669
1986.83	425.434
1989.13	433.973
1991.06	421.36
1993.39	453.836
1995.71	409.812
1998.03	444.788
2000.35	447.764
2002.67	436.24
2004.99	422.716
2007.31	429.192
2009.62	473.168
2011.94	453.144
2014.25	429.119
2016.57	460.095
2018.88	487.571
2021.19	424.547
2023.5	461.523
2025.82	443.499
2028.12	490.475
2030.43	420.451
2032.74	415.427
2035.05	479.403
2037.36	442.379
2039.66	442.355
2041.96	454.331
2044.27	437.307
2046.57	428.283
2048.87	449.759
2051.17	459.735
2053.47	469.211
2055.77	484.687
2058.07	450.163
2060.37	447.139
2062.66	468.115
2064.96	465.091
2067.25	459.067
2069.55	444.543
2071.84	449.519
2074.13	480.995
2076.42	480.471
2078.71	449.447
2081	446.423
2083.29	480.899
2085.58	447.375
2087.86	471.851
2090.15	484.827
2092.43	461.303
2094.72	470.778
2097	491.254
2099.28	490.73
2101.56	475.706
2103.85	492.682
2106.13	448.658
2108.4	475.134
2110.68	461.61
2112.96	496.586
2115.23	459.562
2117.51	485.038
2119.78	509.014
2122.06	504.49
2124.33	480.466
2126.6	479.442
2128.87	468.418
2131.14	454.394
2133.41	495.87
2135.68	491.346
2137.95	507.822
2140.21	456.298
2142.48	517.274
2144.74	492.25
2147.01	503.226
2149.27	489.202
2151.53	520.678
2153.79	490.154
2156.05	496.13
2158.31	493.606
2160.57	502.082
2162.83	469.058
2165.08	495.534
2167.34	487.01
2169.59	503.486
2171.85	487.962
2174.1	523.938
2176.35	467.913
2178.61	479.889
2180.86	506.365
2183.11	486.841
2185.36	529.317
2187.6	516.793
2189.85	510.769
2192.1	524.745
2194.34	491.721
2196.59	524.697
2198.83	503.673
2201.07	499.649
2203.32	478.625
2205.56	529.101
2207.8	512.577
2210.04	506.053
2212.27	547.529
2214.51	548.505
2216.75	499.481
2218.98	502.957
2221.22	514.433
2223.45	525.409
2225.69	545.885
2227.92	550.861
2230.15	549.337
2232.38	512.813
2234.61	535.789
2236.84	513.265
2239.07	542.241
2241.3	559.717
2243.52	507.193
2245.75	514.169
2247.97	511.145
2250.2	557.121
2252.42	532.596
2254.64	542.072
2256.86	547.548
2259.08	582.024
2261.3	534
2263.52	527.976
2265.74	529.952
2267.95	536.928
2270.17	518.904
2272.39	544.88
2274.6	529.356
2276.81	551.832
2279.02	579.808
2281.24	520.784
2283.45	533.76
2285.66	559.736
2287.87	532.712
2290.08	527.688
2292.28	568.164
2294.49	534.64
2296.7	563.616
2298.9	521.592
2301.1	530.568
2303.31	528.044
2305.51	546.52
2307.71	584.496
2309.91	572.472
2312.11	533.448
2314.31	555.424
2316.51	568.4
2318.71	606.376
2320.9	549.352
2323.1	561.328
2325.29	543.304
2327.48	549.279
2329.68	569.756
2331.87	559.232
2334.06	573.207
2336.25	584.183
2338.44	549.159
2340.63	599.635
2342.82	576.111
2345	587.087
2347.19	550.063
2349.37	573.539
2351.56	547.015
2353.74	561.491
2355.92	586.967
2358.11	599.416
2360.29	589.923
2362.47	564.362
2364.65	616.962
2366.82	567.957
2369	591.824
2371.18	584.45
2373.36	583.997
2375.53	609.393
2377.7	603.906
2379.88	585.598
2382.05	592.613
2384.22	590.108
2386.39	598.458
2388.56	582.981
2390.73	583.818
2392.9	592.419
2395.07	582.685
2397.23	592.442
2399.4	615.655
2401.56	587.956
2403.47	580.889
2405.66	636.854
2407.85	642.318
2410.04	612.282
2412.23	621.746
2414.42	586.71
2416.6	610.174
2418.79	612.138
2420.97	632.603
2423.16	605.067
2425.34	599.031
2427.52	620.995
2429.71	595.959
2431.89	612.923
2434.07	629.387
2436.25	609.852
2438.43	619.816
2440.6	600.78
2442.78	606.244
2444.96	599.708
2447.13	616.172
2449.31	644.636
2451.48	631.6
2453.65	635.565
2455.82	607.529
2458	611.493
2460.17	614.457
2462.34	652.921
2464.51	624.885
2466.67	656.849
2468.84	614.314
2471.01	653.778
2473.17	650.242
2475.34	615.206
2477.5	650.17
2479.66	631.634
2481.83	626.098
2483.99	650.063
2486.15	660.027
2488.31	634.991
2490.47	636.955
2492.62	641.919
2494.78	670.383
2496.94	625.847
2499.09	631.812
2501.25	630.776
2503.4	619.74
2505.55	657.704
2507.71	665.168
2509.86	671.132
2512.01	663.096
2514.16	633.561
2516.31	651.525
2518.46	709.489
2520.6	650.453
2522.75	688.417
2524.9	647.381
2527.04	660.845
2529.19	678.31
2531.33	711.274
2533.47	665.238
2535.61	636.202
2537.75	686.183
2539.89	671.731
2542.03	674.778
2544.17	639.326
2546.31	654.374
2548.45	664.421
2550.58	681.469
2552.72	652.017
2554.85	670.565
2556.99	681.612
2559.12	732.66
2561.25	650.708
2563.38	708.256
2565.51	682.303
2567.64	719.351
2569.77	663.899
2571.9	690.947
2574.02	649.994
2576.15	708.042
2578.28	685.09
2580.4	653.137
2582.52	659.185
2584.65	676.733
2586.77	686.781
2588.89	691.328
2591.01	675.376
2593.13	674.924
2595.25	676.971
2597.37	683.519
2599.48	663.567
2601.6	712.615
2603.72	667.662
2605.83	716.71
2607.94	720.758
2610.06	697.806
2612.17	670.353
2614.28	718.901
2616.39	671.949
2618.5	752.497
2620.61	687.044
2622.72	747.092
2624.83	689.64
2626.94	692.188
2629.04	675.235
2631.15	683.283
2633.25	678.331
2635.35	680.378
2637.46	684.926
2639.56	699.474
2641.66	683.522
2643.76	690.569
2645.86	719.617
2647.96	699.165
2650.06	722.713
2652.15	710.26
2654.25	729.308
2656.35	720.356
2658.44	741.404
2660.53	698.951
2662.63	722.999
2664.72	704.047
2666.81	745.594
2668.9	723.642
2670.99	711.19
2673.08	751.238
2675.17	724.285
2677.26	704.333
2679.34	692.381
2681.43	764.429
2683.51	741.476
2685.6	741.524
2687.68	726.072
2689.76	716.62
2691.85	769.667
2693.93	748.715
2696.01	704.763
2698.09	706.81
2700.17	757.858
2702.24	700.406
2704.32	734.954
2706.4	752.001
2708.47	712.049
2710.55	740.597
2712.62	749.645
2714.69	728.192
2716.77	717.24
2718.84	701.288
2720.91	737.836
2722.98	703.383
2725.05	743.431
2727.11	740.979
2729.18	754.526
2731.25	764.074
2733.32	732.622
2735.38	706.67
2737.44	751.717
2739.51	722.765
2741.57	729.813
2743.63	741.861
2745.69	725.408
2747.75	742.956
2749.81	739.504
2751.87	741.027
2753.93	745.382
2755.99	737.554
2758.04	715.6
2760.1	738.83
2762.15	742.284
2764.21	756.746
2766.26	729.837
2768.31	744.509
2770.36	746.662
2772.42	737.596
2774.47	737.514
2776.52	770.933
2778.56	737.881
2780.61	743.815
2782.66	748.132
2784.7	730.082
2786.75	742.105
2788.79	741.012
2790.84	784.177
2792.8	736.601
2794.87	748.594
2796.93	758.087
2799	735.58
2801.07	708.574
2803.14	709.567
2805.2	721.06
2807.27	715.553
2809.33	765.047
2811.39	764.04
2813.46	776.533
2815.52	720.526
2817.58	750.52
2819.64	764.013
2821.7	754.506
2823.76	756.999
2825.82	759.493
2827.87	752.986
2829.93	737.979
2831.98	737.972
2834.04	744.466
2836.09	723.959
2838.15	733.952
2840.2	736.445
2842.25	746.439
2844.3	737.932
2846.35	788.425
2848.4	785.418
2850.45	772.912
2852.5	749.405
2854.55	716.398
2856.59	738.391
2858.64	720.385
2860.68	730.378
2862.73	715.371
2864.77	736.865
2866.81	743.858
2868.85	749.351
2870.9	750.344
2872.94	716.837
2874.97	769.831
2877.01	741.824
2879.05	729.317
2881.09	739.31
2883.13	734.304
2885.16	731.797
2887.2	739.79
2889.23	799.283
2891.26	743.277
2893.3	739.27
2895.33	729.763
2897.36	778.756
2899.39	728.75
2901.42	765.743
2903.45	724.736
2905.48	724.229
2907.5	751.223
2909.53	720.716
2911.55	751.709
2913.58	727.202
2915.6	766.196
2917.63	786.189
2919.65	771.182
2921.67	727.175
2923.69	727.169
2925.71	743.662
2927.73	739.155
2929.75	709.148
2931.77	732.642
2933.79	712.135
2935.8	769.128
2937.82	721.121
2939.84	708.115
2941.85	747.608
2943.86	711.101
2945.88	716.094
2947.89	723.088
2949.9	707.081
2951.91	709.074
2953.92	762.068
2955.93	711.061
2957.94	733.054
2959.94	729.547
2961.95	705.04
2963.96	715.534
2965.96	745.027
2967.97	734.02
2969.97	739.513
2971.97	742.007
2973.97	770.5
2975.98	717.993
2977.98	723.486
2979.98	720.98
2981.98	741.473
2983.97	733.966
2985.97	747.959
2987.97	768.453
2989.97	770.946
2991.96	757.439
2993.95	766.432
2995.95	739.426
2997.94	780.919
2999.93	725.912