File: DateTimeSpectrumPointNumber1.txt
#Acq. time (s)=	0.8
#Accumulations=	3
#Range (cm-¹)=	1500...2000
#Windows=	2
#Autofocus=	Off
#AutoExposure=	Off
#Spike filter=	Multiple accum.
#Delay time (s)=	0
#Binning=	1
#Readout mode=	Signal
#DeNoise=	Off
#ICS correction=	Off
#Dark correction=	Off
#Inst. Process=	Off
#Instrument=	LabRAM HR Evol
#Detector=	Emulator CCD
#Objective=	x100
#Grating=	1800 gr/mm
#ND Filter=	100%
#Laser (nm)=	512
#Slit=	150.001
#Hole=	70.0087
#Project=	A
#Sample=	B
#Site=	C
#Title=	D_185
#Remark=
#Date=	30.10.2017 13:59
#Acquired=	30.10.2017 13:59:20
1500.39	369.5
1500.89	413.5
1501.39	370
1501.88	436
1502.38	356
1502.88	406
1503.38	357
1503.87	349
1504.37	365
1504.87	369
1505.37	386.5
1505.86	348
1506.36	377
1506.86	350
1507.35	386
1507.85	377
1508.35	382.5
1508.84	357.5
1509.34	383
1509.84	401
1510.33	358
1510.83	365.5
1511.33	371
1511.82	393
1512.32	352
1512.82	393.5
1513.31	377.5
1513.81	420
1514.31	392
1514.8	396
1515.3	413.5
1515.8	395
1516.29	385
1516.79	386.5
1517.28	389
1517.78	387
1518.28	373.5
1518.77	376.5
1519.27	406.5
1519.76	358
1520.26	390
1520.76	357.5
1521.25	374
1521.75	367.5
1522.24	382
1522.74	408
1523.23	416
1523.73	393.5
1524.23	422.5
1524.72	437.5
1525.22	391
1525.71	392.5
1526.21	383.5
1526.7	380
1527.2	412
1527.69	357
1528.19	393
1528.68	386
1529.18	410.5
1529.68	388.5
1530.17	431
1530.66	431
1531.16	352
1531.65	397.5
1532.15	421
1532.65	378
1533.14	389
1533.63	367
1534.13	357
1534.62	373.5
1535.12	387.5
1535.61	365
1536.11	365.5
1536.6	366
1537.1	373
1537.59	418.5
1538.09	378
1538.58	407
1539.08	369
1539.57	403
1540.07	380.5
1540.56	354
1541.05	354
1541.55	364
1542.04	382.5
1542.54	402
1543.03	429.5
1543.52	396.5
1544.02	355
1544.51	367
1545.01	408
1545.5	363.5
1545.99	367
1546.49	425
1546.98	400.5
1547.48	416
1547.97	365
1548.46	392
1548.96	364
1549.45	360
1549.94	360
1550.44	395
1550.93	402
1551.42	410.5
1551.92	385
1552.41	404.5
1552.91	359.5
1553.4	402.5
1553.89	399
1554.38	375.5
1554.88	397
1555.37	409
1555.86	401.5
1556.36	358
1556.85	404.5
1557.34	395
1557.84	406
1558.33	391
1558.82	403
1559.31	380
1559.81	378
1560.3	371
1560.79	391
1561.29	371
1561.78	411.5
1562.27	393
1562.76	381
1563.26	398
1563.75	415
1564.24	370.5
1564.73	373
1565.23	367
1565.72	401
1566.21	380
1566.7	382
1567.2	382
1567.69	376
1568.18	363
1568.67	372
1569.16	380
1569.66	362.5
1570.15	397
1570.64	403.5
1571.13	421.5
1571.62	379
1572.12	403
1572.61	385
1573.1	407.5
1573.59	436
1574.08	426
1574.58	411
1575.07	371
1575.56	432
1576.05	400.5
1576.54	368
1577.03	363
1577.52	380
1578.02	430
1578.51	394.5
1579	406
1579.49	387.5
1579.98	413
1580.47	373
1580.96	415.5
1581.45	386
1581.94	381
1582.44	385.5
1582.93	374.5
1583.42	408.5
1583.91	390
1584.4	372
1584.89	369
1585.38	413
1585.87	398
1586.36	416.5
1586.85	410
1587.35	410.5
1587.84	383
1588.33	370
1588.82	390
1589.31	429
1589.8	453.5
1590.29	390
1590.78	372.5
1591.27	382.5
1591.76	420.5
1592.25	398
1592.74	402
1593.23	432
1593.72	371
1594.21	398
1594.7	373
1595.19	397
1595.68	384
1596.17	387
1596.66	388.5
1597.15	432.5
1597.64	388
1598.13	385
1598.62	375.5
1599.11	420.5
1599.6	402
1600.09	419
1600.58	382
1601.07	439
1601.56	431
1602.05	372
1602.54	425
1603.03	449
1603.52	421
1604	437.5
1604.49	395.5
1604.98	459.5
1605.47	399.5
1605.96	449
1606.45	374.5
1606.94	393.5
1607.43	404
1607.92	386.5
1608.41	389
1608.9	382
1609.39	454.5
1609.88	407.5
1610.36	398.5
1610.85	377
1611.34	404
1611.83	417
1612.32	415.5
1612.81	417
1613.3	380
1613.79	427.5
1614.27	403
1614.76	414
1615.25	379
1615.74	379
1616.23	403
1616.72	405
1617.2	459.5
1617.69	375
1618.18	439
1618.67	379
1619.16	416.5
1619.64	377
1620.13	406
1620.62	418
1621.11	413
1621.6	406
1622.09	394
1622.57	431.5
1623.06	379.5
1623.55	383
1624.04	412
1624.52	402.5
1625.01	446.5
1625.5	392
1625.99	391.5
1626.48	435.5
1626.96	403
1627.45	420
1627.94	412
1628.42	399.5
1628.91	429
1629.4	468
1629.89	409
1630.37	396.5
1630.86	429.5
1631.35	414
1631.84	400.5
1632.32	409
1632.81	391
1633.3	435
1633.78	432.5
1634.27	409
1634.76	435
1635.25	428
1635.73	406
1636.22	425
1636.71	420
1637.19	401.5
1637.68	427.5
1638.17	451.5
1638.65	401
1639.14	394.5
1639.63	398.5
1640.11	415
1640.6	393
1641.09	385
1641.57	392
1642.06	437
1642.55	387
1643.03	417.5
1643.52	389
1644	398
1644.49	424.5
1644.98	411
1645.46	440.5
1645.95	409
1646.44	406.5
1646.92	462
1647.41	427
1647.89	459.5
1648.38	416.5
1648.87	414.5
1649.35	395.5
1649.84	457
1650.32	408.5
1650.81	414
1651.29	429.5
1651.78	433.5
1652.26	411
1652.75	418.5
1653.24	388.5
1653.72	403
1654.21	439
1654.69	428
1655.18	436.5
1655.66	401
1656.15	419
1656.63	429.5
1657.12	422.5
1657.6	413
1658.09	448
1658.57	411.5
1659.06	464.5
1659.54	435.5
1660.03	471.5
1660.51	420.5
1661	413
1661.48	421.5
1661.97	432
1662.45	405
1662.94	472
1663.42	481
1663.91	469.5
1664.39	424
1664.88	429.5
1665.36	464
1665.85	425.5
1666.33	440
1666.82	417
1667.3	430
1667.78	398
1668.27	409
1668.75	417.5
1669.24	434
1669.72	407
1670.21	410.5
1670.69	454
1671.17	436.5
1671.66	417
1672.14	444
1672.63	407
1673.11	446.5
1673.59	413
1674.08	419
1674.56	467.5
1675.05	430
1675.53	408
1676.01	424.5
1676.5	435
1676.98	451
1677.46	396
1677.95	470
1678.43	420.5
1678.92	400.5
1679.4	407
1679.88	419
1680.36	401
1680.85	428
1681.33	408
1681.81	466
1682.3	433.5
1682.78	427
1683.26	407
1683.75	469
1684.23	452.5
1684.71	435
1685.2	463.5
1685.68	425
1686.16	402
1686.65	414
1687.13	410
1687.61	451
1688.09	410.5
1688.58	468
1689.06	402
1689.54	419.5
1690.03	428.5
1690.51	425.5
1690.99	441.5
1691.47	415.5
1691.95	480.5
1692.44	453
1692.92	425
1693.4	419
1693.88	468
1694.37	479
1694.85	424.5
1695.33	412
1695.81	439
1696.3	470
1696.78	423.5
1697.26	411
1697.74	420
1698.22	461
1698.71	472
1699.19	459
1699.67	450
1700.15	413.5
1700.63	437
1701.12	426
1701.6	466
1702.08	421
1702.56	434
1703.04	423.5
1703.52	446
1704	447
1704.49	433
1704.97	456
1705.45	479
1705.93	436
1706.41	419.5
1706.89	447.5
1707.38	429
1707.86	452
1708.34	457.5
1708.82	464.5
1709.3	453.5
1709.78	451
1710.26	455
1710.74	416
1711.22	469.5
1711.7	457.5
1712.19	484.5
1712.67	496
1713.15	496
1713.63	420
1714.11	467
1714.59	468
1715.07	422
1715.55	455
1716.03	447
1716.51	412
1716.99	422
1717.47	445
1717.95	436
1718.43	433
1718.91	422
1719.39	448
1719.87	434
1720.36	465
1720.84	484
1721.32	430
1721.8	447
1722.28	455
1722.76	418
1723.24	453
1723.72	490
1724.2	449.5
1724.68	436
1725.16	474.5
1725.64	461
1726.12	471.5
1726.6	422
1727.08	440
1727.55	465
1728.03	500.5
1728.51	436
1728.99	439
1729.47	431
1729.95	486.5
1730.43	453.5
1730.91	431
1731.39	440.5
1731.87	463.5
1732.35	441
1732.83	422
1733.31	422
1733.79	494
1734.27	472.5
1734.74	452
1735.22	453
1735.7	494.5
1736.18	444.5
1736.66	457
1737.14	452.5
1737.62	425
1738.1	467
1738.58	453
1739.06	459
1739.54	464
1740.01	475.5
1740.49	435
1740.97	441.5
1741.45	457
1741.93	449.5
1742.41	463
1742.89	476
1743.36	448
1743.84	454
1744.32	465
1744.8	445
1745.28	485
1745.75	507
1746.23	474
1746.71	429
1747.19	454
1747.67	453
1748.15	444.5
1748.63	441
1749.1	477
1749.58	450.5
1750.06	495.5
1750.54	478
1751.01	463
1751.49	458.5
1751.97	479
1752.45	488.5
1752.92	479.5
1753.4	461.5
1753.88	455
1754.36	446
1754.84	500
1755.31	440.5
1755.79	444
1756.27	462
1756.75	498.5
1757.22	471
1757.7	457
1758.18	478
1758.65	436
1759.13	475
1759.61	489
1760.09	486
1760.56	433
1761.04	465
1761.52	449.5
1761.99	441
1762.47	467
1762.95	485
1763.43	505
1763.9	471.5
1764.38	469
1764.86	456
1765.33	478.5
1765.81	451.5
1766.29	459.5
1766.76	473.5
1767.24	445
1767.72	478.5
1768.19	442
1768.67	442
1769.15	491.5
1769.62	451.5
1770.1	457.5
1770.57	473
1771.05	449
1771.53	516.5
1772	446
1772.48	447.5
1772.96	466
1773.43	483
1773.91	456.5
1774.38	473.5
1774.86	463
1775.34	483.5
1775.81	478
1776.29	475
1776.76	455.5
1777.24	469
1777.71	491
1778.19	491
1778.67	462
1779.14	455
1779.62	497
1780.09	449.5
1780.57	516
1781.04	464
1781.52	453.5
1782	505
1782.47	458
1782.94	461
1783.42	455
1783.9	509.5
1784.37	473
1784.85	493
1785.32	470
1785.8	476
1786.27	453
1786.75	479
1787.22	493
1787.7	509
1788.17	484
1788.65	455
1789.12	455.5
1789.6	453
1790.07	492.5
1790.55	463
1791.02	518
1791.49	472
1791.97	462
1792.45	472.5
1792.92	466.5
1793.39	459
1793.87	481
1794.34	495
1794.82	460
1795.29	503
1795.77	470
1796.24	482
1796.71	463
1797.19	476
1797.66	488.5
1798.14	480
1798.61	473.5
1799.08	468
1799.56	498.5
1800.03	476
1800.51	470
1800.98	485
1801.45	519
1801.93	503
1802.4	469
1802.88	532
1803.35	508
1803.82	505.5
1804.3	511.5
1804.77	486.5
1805.24	498.5
1805.72	535
1806.19	478
1806.67	489.5
1807.14	480
1807.61	497.5
1808.09	499
1808.56	495.5
1809.03	466.5
1809.5	468
1809.98	497
1810.45	487.5
1810.92	514.5
1811.4	513
1811.87	532.5
1812.34	498
1812.82	493
1813.29	463
1813.76	487.5
1814.24	504.5
1814.71	516.5
1815.18	508
1815.65	499.5
1816.13	464
1816.6	501.5
1817.07	484
1817.55	472
1818.02	516
1818.49	535
1818.96	493
1819.44	466
1819.91	509.5
1820.38	520
1820.85	505
1821.33	485
1821.8	534
1822.27	497
1822.74	494
1823.21	483
1823.69	469
1824.16	502
1824.63	501
1825.1	517
1825.57	483
1826.05	485
1826.52	518
1826.99	546
1827.46	522.5
1827.93	481
1828.41	556.5
1828.88	490
1829.35	492
1829.82	506.5
1830.29	489
1830.76	516
1831.23	491
1831.71	509.5
1832.18	524.5
1832.65	488
1833.12	497.5
1833.59	520
1834.06	552.5
1834.53	533
1835.01	503
1835.48	490.5
1835.95	542
1836.42	514.5
1836.89	489
1837.36	535
1837.83	500
1838.3	500
1838.77	522
1839.25	555
1839.72	499
1840.19	496.5
1840.66	514
1841.13	544
1841.6	479
1842.07	504.5
1842.54	516
1843.01	542.5
1843.48	531
1843.95	510.5
1844.42	500.5
1844.89	538
1845.36	569
1845.84	508.5
1846.3	515
1846.78	523
1847.25	537
1847.72	513
1848.19	509.5
1848.66	524
1849.13	506
1849.6	525
1850.07	527.5
1850.54	525
1851.01	537.5
1851.48	507
1851.95	531.5
1852.42	516
1852.89	503
1853.36	525.5
1853.83	522.5
1854.3	565.5
1854.76	501
1855.24	505
1855.7	519.5
1856.17	522
1856.64	510
1857.11	536.5
1857.58	518.5
1858.05	502
1858.52	499.5
1858.99	501
1859.46	526
1859.93	493
1860.4	533.5
1860.87	589
1861.34	534
1861.81	525
1862.28	523.5
1862.74	527
1863.21	499
1863.68	534.5
1864.15	520
1864.62	549
1865.09	519
1865.56	499
1866.03	553.5
1866.5	562
1866.96	518
1867.43	543.5
1867.9	499
1868.37	528.5
1868.84	509
1869.31	513.5
1869.78	508
1870.24	556.5
1870.71	508.5
1871.18	502
1871.65	515
1872.12	522
1872.59	529
1873.05	581.5
1873.52	505
1873.99	568
1874.46	534
1874.93	556.5
1875.4	521.5
1875.86	540
1876.33	568
1876.8	538.5
1877.27	537
1877.73	530
1878.2	528
1878.67	520.5
1879.14	530
1879.61	553.5
1880.07	533
1880.54	550
1881.01	541.5
1881.48	541.5
1881.94	534
1882.41	554.5
1882.88	530
1883.35	510
1883.82	508
1884.28	516
1884.75	525.5
1885.22	510
1885.68	532
1886.15	572.5
1886.62	534.5
1887.09	547
1887.55	535
1888.02	550
1888.49	561
1888.95	560
1889.42	534
1889.89	597
1890.35	581
1890.82	598.5
1891.29	556.5
1891.76	530.5
1892.22	569.5
1892.69	570
1893.16	558
1893.62	558.5
1894.09	516
1894.55	527
1895.02	564.5
1895.49	538.5
1895.95	532
1896.42	563
1896.89	568.5
1897.35	566.5
1897.82	564
1898.29	563.5
1898.75	558
1899.22	558
1899.68	590.5
1900.15	591
1900.62	530
1901.08	563.5
1901.55	576
1902.01	523
1902.48	549
1902.95	610.5
1903.41	547
1903.88	541
1904.34	594
1904.81	559
1905.28	531.5
1905.74	537
1906.21	560
1906.67	577
1907.14	557
1907.6	547
1908.07	547
1908.54	549
1909	588.5
1909.47	572.5
1909.93	545
1910.4	539.5
1910.86	576.5
1911.33	544
1911.79	530
1912.26	534
1912.72	601.5
1913.19	538
1913.65	531
1914.12	592
1914.58	548.5
1915.05	557
1915.51	546.5
1915.98	546
1916.44	577.5
1916.91	581
1917.37	557
1917.84	598
1918.3	538
1918.77	563.5
1919.23	572.5
1919.69	575.5
1920.16	544
1920.62	582
1921.09	564.5
1921.55	614.5
1922.02	592.5
1922.48	598
1922.94	566
1923.41	578.5
1923.87	588
1924.34	552
1924.8	575
1925.27	572
1925.73	594
1926.2	585
1926.66	541
1927.12	541
1927.59	590
1928.05	577
1928.51	548.053
1928.98	590.106
1929.44	569.659
1929.91	550.213
1930.37	568.766
1930.83	561.319
1931.3	600.872
1931.76	588.425
1932.22	554.978
1932.69	551.031
1933.15	578.585
1933.61	575.138
1934.08	567.691
1934.54	588.744
1935	593.297
1935.47	555.85
1935.93	576.904
1936.39	556.957
1936.86	627.51
1937.32	576.563
1937.78	578.116
1938.25	553.169
1938.71	585.222
1939.17	614.776
1939.64	614.26
1940.1	570.128
1940.56	580.516
1941.02	571.054
1941.49	589.654
1941.95	574.884
1942.41	616.287
1942.88	590.007
1943.34	569.446
1943.8	595.939
1944.27	582.083
1944.73	618.641
1945.19	596.631
1945.65	600.404
1946.11	610.692
1946.58	568.936
1947.04	590.173
1947.5	620.49
1947.96	597.993
1948.43	598.456
1948.89	622.174
1949.35	595.521
1949.81	581.83
1950.28	614.426
1950.74	587.081
1951.2	608.922
1951.66	602.263
1952.12	601.488
1952.59	578.969
1953.05	577.172
1953.51	578.981
1953.97	575.441
1954.43	583.875
1954.89	609.458
1955.36	614.857
1955.82	620.701
1956.28	618.372
1956.74	596.607
1957.2	620.942
1957.66	583.147
1958.13	618.86
1958.59	594.319
1959.05	582.831
1959.51	620.399
1959.97	605.996
1960.43	583.384
1960.89	600.256
1961.36	594.269
1961.82	624.584
1962.28	592.655
1962.74	593.014
1963.2	606.155
1963.66	616.179
1964.12	608.919
1964.58	608.856
1965.04	598.905
1965.51	600.216
1965.97	612.95
1966.43	627.543
1966.89	595.697
1967.35	610.492
1967.81	609.874
1968.27	604.999
1968.73	593.434
1969.19	606.059
1969.65	597.693
1970.11	597.62
1970.57	599.853
1971.04	590.547
1971.49	617.872
1971.96	603.7
1972.42	627.048
1972.88	613.537
1973.34	635.348
1973.8	618.396
1974.26	597.42
1974.72	613.355
1975.18	624.534
1975.64	617.157
1976.1	612.414
1976.56	605.691
1977.02	637.893
1977.48	619.177
1977.94	603.917
1978.4	619.985
1978.86	639.068
1979.32	611.794
1979.78	627.543
1980.24	614.814
1980.7	622.552
1981.16	609.144
1981.62	631.134
1982.08	628.363
1982.54	632.415
1983	620.216
1983.46	612.316
1983.91	607.966
1984.37	637.526
1984.83	628.276
1985.29	628.52
1985.75	640.328
1986.21	629.086
1986.67	612.34
1987.13	598.926
1987.59	634.539
1988.05	651.308
1988.51	637.906
1988.67	631.487
1989.14	653.935
1989.6	631.882
1990.07	626.329
1990.53	643.277
1990.99	635.724
1991.46	625.171
1991.92	645.118
1992.39	636.566
1992.85	616.013
1993.32	622.46
1993.78	631.907
1994.24	652.355
1994.71	628.302
1995.17	625.749
1995.64	617.696
1996.1	638.644
1996.57	603.091
1997.03	612.538
1997.5	646.985
1997.96	640.933
1998.42	656.88
1998.89	669.327
1999.35	619.275
1999.82	629.222