File: DateTimeSpectrumPointNumber1.txt
#Acq. time (s)=	3
#Accumulations=	5
#Range (cm-¹)=	-400...1000
#Windows=	3
#Autofocus=	Off
#AutoExposure=	Off
#Spike filter=	Off
#Delay time (s)=	0
#Binning=	1
#Readout mode=	Signal
#DeNoise=	Off
#ICS correction=	Off
#Dark correction=	Off
#Inst. Process=	Off
#Instrument=	LabRAM HR Evol
#Detector=	Emulator CCD
#Objective=	x100
#Grating=	1800 gr/mm
#ND Filter=	100%
#Laser (nm)=	512
#Slit=	150.001
#Hole=	70.0087
#Project=	A
#Sample=	B
#Site=	C
#Title=	D_19
#Remark=
#Date=	05.10.2017 11:30
#Acquired=	05.10.2017 11:30:40
-398.136	404.2
-396.875	393.008
-395.615	399.015
-394.356	378.223
-393.096	394.63
-391.836	404.638
-390.578	410.645
-389.318	405.453
-388.06	382.061
-386.801	389.268
-385.543	390.276
-384.284	413.883
-383.026	397.491
-381.769	403.499
-380.511	386.506
-379.254	409.114
-377.997	393.721
-376.74	419.329
-375.483	402.336
-374.227	403.144
-372.971	394.752
-371.715	397.159
-370.459	382.167
-369.203	374.574
-367.947	378.782
-366.692	381.589
-365.436	408.397
-364.182	374.205
-362.927	394.812
-361.673	399.22
-360.419	370.827
-359.165	414.435
-357.911	403.443
-356.657	393.25
-355.404	378.858
-354.15	396.665
-352.898	405.673
-351.646	393.28
-350.392	407.688
-349.14	381.896
-347.888	389.103
-346.636	402.911
-345.385	398.118
-344.133	385.126
-342.882	370.934
-341.631	419.941
-340.38	382.149
-339.129	395.156
-337.879	413.364
-336.628	392.571
-335.379	398.579
-334.129	398.587
-332.879	372.194
-331.63	379.202
-330.38	397.609
-329.132	384.217
-327.883	403.024
-326.635	403.232
-325.386	371.04
-324.138	387.847
-322.89	377.255
-321.642	392.662
-320.395	366.47
-319.147	401.878
-317.901	414.085
-316.654	376.293
-315.407	370.7
-314.16	384.708
-312.914	390.315
-311.668	382.723
-310.422	409.531
-309.176	373.138
-307.931	382.146
-306.685	398.153
-305.44	375.561
-304.196	400.968
-302.951	379.776
-301.707	360.384
-300.462	395.391
-299.219	389.399
-297.975	405.206
-296.732	393.414
-295.487	384.822
-294.245	385.629
-293.002	363.237
-291.759	365.444
-290.516	394.252
-289.274	380.459
-288.032	390.867
-286.79	403.875
-285.549	380.282
-284.307	387.49
-283.066	388.897
-281.825	400.705
-280.584	383.313
-279.343	372.32
-278.102	387.128
-276.863	383.935
-275.622	387.743
-274.382	374.75
-273.143	388.958
-271.903	366.366
-270.664	399.773
-269.425	372.181
-268.186	389.588
-266.947	399.396
-265.709	391.203
-264.471	367.211
-263.232	369.219
-261.995	361.626
-260.758	368.034
-259.52	398.241
-258.283	387.449
-257.046	363.457
-255.81	366.064
-254.573	402.872
-253.337	350.079
-252.1	389.287
-250.864	376.294
-249.628	371.902
-248.394	384.11
-247.158	372.317
-245.922	397.125
-244.688	375.332
-243.453	381.34
-242.218	373.347
-240.984	384.155
-239.751	371.363
-238.516	358.17
-237.283	387.378
-236.049	371.185
-234.816	381.993
-233.583	384.401
-232.35	376.808
-231.118	371.816
-229.886	385.423
-228.653	363.031
-227.421	398.638
-226.19	382.646
-224.958	362.654
-223.726	379.061
-222.495	384.269
-221.264	395.476
-220.033	374.284
-218.803	382.091
-217.572	386.699
-216.341	394.907
-215.112	377.514
-213.882	329.922
-212.653	368.729
-211.423	363.537
-210.194	359.145
-208.966	358.952
-207.736	350.36
-206.508	369.967
-205.28	380.175
-204.052	389.582
-202.824	354.19
-201.597	376.998
-200.369	406.005
-199.142	376.013
-197.915	376.42
-196.688	368.228
-195.461	371.836
-194.234	370.843
-193.008	370.451
-191.781	395.458
-190.556	371.066
-189.33	371.673
-188.105	355.081
-186.88	363.089
-185.654	386.296
-184.43	378.904
-183.206	355.311
-181.98	380.519
-180.757	390.126
-179.533	349.934
-178.308	366.342
-177.085	395.149
-175.862	365.157
-174.639	373.764
-173.416	355.772
-172.193	370.38
-170.97	386.387
-169.748	380.995
-168.526	357.402
-167.303	356.41
-166.081	371.417
-164.861	387.425
-163.639	371.033
-162.418	329.44
-161.197	393.448
-159.976	381.055
-158.755	336.263
-157.535	349.07
-156.316	364.878
-155.095	377.286
-153.876	388.493
-152.655	349.301
-151.436	361.308
-150.218	353.316
-148.999	361.524
-147.78	373.931
-146.562	373.539
-145.344	355.346
-144.126	336.354
-142.908	373.161
-141.69	374.569
-140.472	359.777
-139.255	357.384
-138.037	334.592
-136.82	365.799
-135.604	347.407
-134.387	360.614
-133.171	375.222
-131.955	371.63
-130.739	370.437
-129.524	378.845
-128.309	367.852
-127.093	367.06
-125.878	372.668
-124.664	351.875
-123.448	344.483
-122.234	344.09
-121.02	396.098
-119.806	394.505
-118.592	363.113
-117.378	359.921
-116.165	356.728
-114.952	364.536
-113.739	379.943
-112.526	349.551
-111.313	362.359
-110.101	354.166
-108.889	360.174
-107.676	379.981
-106.465	390.589
-105.253	382.996
-104.042	343.004
-102.83	352.612
-101.62	335.019
-100.408	362.827
-99.1982	358.434
-97.9882	390.242
-96.7771	369.049
-95.5673	362.457
-94.3577	368.465
-93.1483	385.872
-91.939	360.48
-90.7299	364.087
-89.5209	352.495
-88.312	359.703
-87.1033	363.71
-85.8948	343.118
-84.6864	359.125
-83.4793	364.533
-82.2712	362.14
-81.0633	368.148
-79.8566	381.556
-78.649	362.363
-77.4426	365.571
-76.2353	386.178
-75.0293	363.786
-73.8222	372.793
-72.6164	349.801
-71.4109	383.209
-70.2042	352.216
-68.9989	344.624
-67.7938	365.631
-66.5888	346.839
-65.384	353.847
-64.1793	349.654
-62.9747	393.062
-61.7703	344.869
-60.566	373.277
-59.3619	352.484
-58.158	363.892
-56.9553	356.3
-55.7517	363.507
-54.5481	341.915
-53.3459	353.122
-52.1427	342.33
-50.9408	383.737
-49.7379	361.145
-48.5363	370.153
-47.3337	362.76
-46.1323	358.568
-44.9312	381.375
-43.729	376.583
-42.5281	349.991
-41.3274	355.198
-40.1268	353.206
-38.9264	365.413
-37.7261	360.221
-36.526	370.428
-35.326	376.636
-34.1261	357.244
-32.9264	354.851
-31.7269	371.059
-30.5287	373.266
-29.3294	365.474
-28.1303	347.482
-26.9325	351.089
-25.7337	358.697
-24.5362	343.504
-23.3377	363.712
-22.1405	355.719
-20.9423	356.727
-19.7454	354.735
-18.5486	341.342
-17.352	347.35
-16.1543	379.357
-14.958	337.765
-13.7618	363.572
-12.5658	369.18
-11.3699	354.388
-10.1742	366.595
-8.97858	363.603
-7.78314	365.61
-6.58784	374.018
-5.39385	376.826
-4.19884	345.033
-3.00398	342.441
-1.81043	358.848
-0.615856	364.456
0.577403	374.463
1.77168	365.871
2.96581	353.879
4.15747	365.286
5.35131	375.894
6.545	366.701
7.73623	348.909
8.92963	374.716
10.1229	351.524
11.3137	365.132
12.5066	375.939
13.6971	349.547
14.8898	380.754
16.08	358.362
17.2724	384.97
18.4623	342.977
19.6521	340.185
20.844	342.192
22.0335	350.6
23.2228	350.607
24.4143	370.015
25.6034	388.823
26.7923	365.03
27.9833	365.438
29.172	349.245
30.3604	348.453
31.5487	343.06
32.7369	359.268
33.9249	372.276
35.1151	365.283
36.3029	358.491
37.4905	364.498
38.6779	366.706
39.8652	364.114
41.0524	379.121
42.2394	367.929
43.4263	357.336
44.6107	377.544
45.7973	361.951
46.9837	343.959
48.17	338.567
49.3561	355.974
50.5421	362.582
51.7257	354.389
52.9114	371.397
54.097	346.005
55.2824	352.212
56.4654	345.22
57.6505	361.227
58.8355	367.835
60.018	354.242
61.2027	364.45
62.385	374.458
63.5694	374.465
64.7514	364.873
65.9355	342.88
67.1172	379.488
68.301	365.095
69.4824	346.103
70.6659	365.511
71.847	338.318
73.028	346.726
74.2111	381.533
75.3918	327.741
76.5723	348.749
77.7527	333.756
78.9352	370.964
80.1153	374.571
81.2953	363.179
82.4751	354.386
83.6548	378.394
84.8343	362.402
86.0137	361.009
87.1952	347.617
88.3743	345.624
89.5533	361.832
90.7321	336.639
91.9107	341.847
93.0892	336.055
94.2653	345.862
95.4436	344.67
96.6217	355.077
97.7996	354.285
98.9774	365.893
100.155	371.7
101.33	354.508
102.508	366.715
103.685	333.923
104.862	343.53
106.037	357.538
107.213	340.346
108.39	354.153
109.564	346.561
110.741	368.768
111.915	356.576
113.091	366.784
114.264	354.591
115.44	344.799
116.614	373.806
117.789	344.014
118.962	336.821
120.137	360.029
121.31	352.437
122.483	373.244
123.658	359.452
124.83	344.659
126.002	368.467
127.177	338.874
128.349	362.282
129.521	375.49
130.692	364.897
131.864	358.105
133.035	354.112
134.209	348.52
135.38	366.328
136.551	342.735
137.722	334.743
138.892	354.75
140.063	350.358
141.233	345.165
142.403	337.173
143.574	373.781
144.741	369.388
145.911	335.996
147.081	343.403
148.25	372.011
149.42	363.218
150.589	352.226
151.756	347.834
152.925	341.041
154.094	347.649
155.26	344.856
156.429	347.264
157.597	365.272
158.763	378.279
159.931	366.287
161.097	353.294
162.265	379.523
163.432	362.474
164.598	358.902
165.763	338.246
166.93	349.24
168.095	349.631
169.262	342.381
170.427	357.839
171.591	359.303
172.758	363.839
173.922	355.68
175.086	359.928
176.252	368.295
177.416	373.685
178.579	348.174
179.743	366.014
180.906	341.853
182.069	354.268
183.232	347.194
184.398	356.802
185.56	363.104
186.723	358.942
187.885	343.209
189.048	362.587
190.21	358.536
191.372	350.849
192.532	341.32
193.693	341.468
194.855	354.141
196.017	347.046
197.178	356.116
198.339	346.618
199.498	366.884
200.659	359.839
201.82	367.318
202.978	356.039
204.139	363.814
205.299	355.297
206.457	352.015
207.617	342.746
208.777	369.505
209.935	355.148
211.094	355.434
212.252	353.304
213.411	365.386
214.568	338.717
215.725	326.733
216.884	348.101
218.041	361.84
219.197	371.662
219.803	364.987
220.972	345.191
222.142	355.195
223.312	368.799
224.481	375.802
225.651	363.406
226.82	343.21
227.987	337.014
229.155	358.218
230.324	347.822
231.493	356.226
232.659	351.43
233.827	362.234
234.996	324.438
236.164	331.042
237.329	354.445
238.497	369.249
239.662	366.453
240.83	352.657
241.997	349.461
243.162	338.665
244.329	351.069
245.494	349.473
246.661	352.077
247.825	367.081
248.989	351.085
250.156	321.489
251.32	351.892
252.486	370.896
253.649	360.7
254.813	371.304
255.979	349.508
257.142	359.912
258.305	356.116
259.468	344.12
260.633	332.124
261.796	361.128
262.958	350.132
264.121	378.335
265.283	349.539
266.445	360.143
267.607	342.547
268.769	352.151
269.931	334.755
271.092	340.159
272.254	343.363
273.415	330.767
274.576	364.971
275.737	363.375
276.898	342.979
278.059	341.182
279.219	345.386
280.38	362.99
281.54	325.194
282.698	313.798
283.858	350.002
285.018	353.006
286.177	369.61
287.335	329.014
288.494	360.018
289.654	364.822
290.811	357.625
291.97	373.629
293.126	334.633
294.285	327.237
295.444	367.441
296.6	348.845
297.758	350.049
298.914	342.453
300.072	347.457
301.228	356.661
302.383	335.865
303.541	347.669
304.696	343.872
305.854	367.476
307.009	358.88
308.164	319.884
309.318	358.288
310.475	357.692
311.629	348.296
312.784	336.5
313.938	368.504
315.094	344.108
316.248	348.312
317.402	355.315
318.555	327.319
319.709	328.923
320.862	347.527
322.015	340.731
323.168	339.135
324.321	344.539
325.474	345.943
326.627	364.147
327.779	344.351
328.931	362.955
330.084	343.358
331.236	370.962
332.385	341.366
333.537	351.57
334.689	346.174
335.84	333.978
336.992	338.382
338.141	345.786
339.292	332.59
340.443	369.194
341.591	344.398
342.742	363.602
343.893	369.205
345.041	355.809
346.191	329.613
347.339	335.217
348.489	329.821
349.637	359.025
350.786	357.429
351.934	351.033
353.083	323.037
354.23	358.641
355.377	334.245
356.526	322.648
357.673	341.052
358.819	357.656
359.968	333.86
361.114	347.864
362.26	373.268
363.406	373.672
364.554	354.876
365.7	349.88
366.846	361.484
367.991	357.888
369.136	337.092
370.281	352.095
371.427	361.099
372.571	353.503
373.716	383.707
374.861	360.111
376.005	353.715
377.15	343.519
378.294	358.523
379.438	345.527
380.582	343.931
381.725	350.335
382.869	342.739
384.013	351.342
385.154	344.746
386.297	347.75
387.44	348.554
388.583	351.958
389.724	361.362
390.866	331.966
392.009	323.57
393.149	339.774
394.291	359.778
395.433	360.182
396.573	351.385
397.715	342.189
398.855	337.393
399.996	362.397
401.135	359.001
402.277	370.405
403.416	371.009
404.555	335.013
405.695	351.217
406.834	348.421
407.975	356.825
409.113	352.629
410.251	338.232
411.389	348.836
412.529	341.44
413.667	351.244
414.805	374.048
415.942	342.452
417.079	350.256
418.219	352.46
419.356	342.064
420.493	379.675
421.63	350.285
422.766	352.896
423.903	360.507
425.039	346.318
426.175	355.329
427.311	354.939
428.447	337.55
429.583	344.761
430.719	314.572
431.852	369.983
432.988	368.193
434.123	371.204
435.258	351.415
436.393	348.626
437.526	378.837
438.661	335.647
439.795	354.858
440.928	351.869
442.062	363.88
443.196	324.291
444.328	354.101
445.462	344.912
446.594	345.523
447.727	378.934
448.859	366.145
449.992	340.955
451.123	347.766
452.256	355.777
453.387	356.588
454.52	351.399
455.65	316.609
456.781	366.22
457.913	360.831
459.043	358.642
460.173	352.253
461.306	349.463
462.435	338.074
463.565	361.485
464.694	351.496
465.824	340.507
466.955	330.517
468.084	362.328
469.213	367.739
470.342	364.55
471.47	358.961
472.599	331.571
473.727	337.382
474.856	354.393
475.984	346.004
477.112	338.815
478.24	379.825
479.367	365.036
480.493	333.647
481.62	333.458
482.747	348.469
483.875	359.479
485.002	371.09
486.126	370.701
487.253	336.112
488.38	319.523
489.504	361.333
490.63	334.944
491.757	345.555
492.881	368.766
494.007	356.377
495.13	343.187
496.256	349.598
497.379	355.009
498.505	379.62
499.628	340.231
500.753	359.441
501.876	354.652
503.001	348.663
504.123	356.074
505.246	351.085
506.37	334.695
507.492	353.906
508.615	346.117
509.739	360.128
510.86	357.339
511.982	344.949
513.104	357.36
514.225	360.371
515.346	377.582
516.47	365.793
517.591	362.203
518.711	363.214
519.832	343.425
520.953	362.836
522.073	351.247
523.193	348.258
524.314	385.868
525.434	339.679
526.552	331.69
527.671	368.501
528.791	346.712
529.91	344.522
531.03	336.933
532.149	344.144
533.266	352.955
534.385	339.566
535.504	357.776
536.623	352.587
537.739	351.198
538.858	343.609
539.974	337.42
541.092	367.63
542.21	360.041
543.326	332.852
544.444	353.463
545.559	341.074
546.677	336.884
547.792	366.095
548.907	357.706
550.024	344.717
551.139	355.128
552.256	359.338
553.37	364.549
554.485	345.36
555.601	350.971
556.716	352.782
557.83	369.592
558.944	340.603
560.057	333.614
561.173	355.425
562.287	376.436
563.4	372.846
564.513	356.257
565.627	349.068
566.74	353.479
567.852	343.29
568.965	349.3
570.078	343.911
571.19	352.122
572.303	330.333
573.415	362.944
574.527	343.554
575.639	354.965
576.749	352.376
577.86	356.187
578.972	363.198
580.083	361.608
581.192	356.219
582.304	351.23
583.415	359.241
584.523	363.252
585.634	355.462
586.745	371.473
587.853	377.684
588.964	366.495
590.072	369.506
591.182	365.316
592.29	357.527
593.399	351.138
594.507	368.549
595.617	335.36
596.724	352.57
597.833	348.381
598.94	363.792
600.047	346.803
601.156	352.014
602.263	338.024
603.369	378.035
604.476	348.846
605.582	347.857
606.69	356.868
607.796	362.478
608.902	362.889
610.008	342.5
611.114	336.311
612.219	345.922
613.324	363.733
614.43	344.743
615.535	347.154
616.64	356.965
617.745	346.576
618.849	348.387
619.954	383.597
621.058	348.408
622.163	369.619
623.265	358.83
624.369	352.641
625.473	353.051
626.576	352.062
627.678	331.273
628.781	389.284
629.885	343.295
630.986	349.905
632.089	348.716
633.192	356.927
634.293	346.538
635.396	356.749
636.496	358.759
637.599	340.77
638.699	324.781
639.801	336.792
640.901	351.403
642.003	331.013
643.103	351.224
644.202	346.435
645.304	337.046
646.403	353.657
647.503	347.067
648.604	369.878
649.703	342.889
650.802	374.3
651.9	340.111
652.999	355.721
654.097	330.932
655.198	331.143
656.296	361.354
657.394	357.965
658.492	342.575
659.59	334.386
660.687	349.197
661.785	354.808
662.882	362.019
663.979	346.829
665.077	340.44
666.171	357.851
667.268	352.262
668.365	358.073
669.462	335.483
670.558	339.294
671.652	360.905
672.749	364.916
673.845	360.127
674.939	354.137
676.035	334.148
677.13	332.759
678.224	342.77
679.319	361.381
680.412	329.591
681.508	344.002
682.601	353.613
683.696	367.824
684.788	383.635
685.883	347.445
686.975	320.656
688.07	356.267
689.162	338.113
690.254	356.536
691.348	341.133
692.44	349.375
693.532	349.157
694.623	347.105
695.717	356.747
696.808	356.381
697.899	348.55
698.99	374.15
700.081	352.74
701.172	352.379
702.263	341.085
703.353	352.285
704.444	348.717
705.534	351.253
706.624	355.275
707.714	361.666
708.804	346.553
709.894	364.096
710.983	349.63
712.073	365.012
713.16	360.323
714.249	347.958
715.339	369.547
716.428	350.935
717.514	355.079
718.603	353.699
719.692	338.426
720.778	352.361
721.867	354.859
722.955	359.965
724.041	347.01
725.129	351.111
726.215	347.874
727.302	357.981
728.388	349.216
729.475	352.555
730.56	358.992
731.646	336.746
732.733	357.002
733.818	349.877
734.902	353.43
735.989	340.543
737.074	342.765
738.158	344.66
739.242	359.881
740.328	357.548
741.093	340.843
742.19	349.047
743.287	352.85
744.383	350.854
745.48	328.057
746.576	338.461
747.67	340.664
748.766	350.668
749.862	337.071
750.958	351.075
752.054	352.278
753.147	352.282
754.242	330.885
755.338	349.289
756.431	337.292
757.526	349.296
758.621	370.3
759.713	352.103
760.808	364.906
761.9	359.91
762.995	327.314
764.087	344.917
765.181	365.121
766.273	350.524
767.367	349.728
768.458	353.131
769.552	343.135
770.643	319.338
771.734	353.742
772.828	346.945
773.919	357.949
775.009	324.952
776.102	349.556
777.193	339.759
778.283	341.763
779.374	364.166
780.464	355.57
781.556	358.973
782.646	350.177
783.736	370.58
784.826	375.984
785.915	351.787
787.005	351.391
788.094	378.994
789.183	333.798
790.272	378.001
791.361	351.005
792.45	337.008
793.539	350.812
794.627	339.815
795.713	376.619
796.802	350.622
797.89	325.226
798.978	363.229
800.066	360.233
801.152	368.036
802.239	351.84
803.327	367.044
804.414	361.247
805.499	361.451
806.587	357.854
807.671	378.058
808.758	349.861
809.845	375.865
810.93	350.668
812.016	365.672
813.101	349.875
814.187	341.879
815.271	335.082
816.357	361.486
817.441	336.089
818.524	364.293
819.61	351.296
820.693	358.7
821.777	369.503
822.862	353.307
823.945	355.71
825.028	361.914
826.111	385.717
827.195	376.321
828.278	327.924
829.36	362.328
830.443	341.931
831.525	349.535
832.607	353.938
833.689	341.942
834.77	350.545
835.852	373.349
836.933	373.952
838.015	352.756
839.096	325.159
840.177	345.563
841.258	335.966
842.339	340.37
843.42	339.774
844.501	340.377
845.579	361.581
846.659	379.984
847.74	358.988
848.82	358.191
849.9	328.595
850.977	356.798
852.057	354.002
853.137	339.605
854.214	351.409
855.294	381.012
856.371	361.216
857.45	350.019
858.527	379.423
859.606	367.826
860.682	355.23
861.761	369.633
862.837	342.237
863.916	359.24
864.992	358.044
866.07	335.447
867.146	364.051
868.222	358.054
869.3	373.858
870.375	343.261
871.45	341.465
872.526	337.868
873.603	338.872
874.678	377.675
875.753	357.079
876.828	375.482
877.902	346.286
878.977	352.889
880.051	347.093
881.126	367.897
882.2	365.9
883.274	347.704
884.348	355.707
885.422	353.911
886.495	361.714
887.569	365.918
888.642	344.521
889.715	350.725
890.789	351.528
891.862	347.732
892.932	382.135
894.005	344.939
895.078	347.942
896.15	370.346
897.221	365.749
898.293	374.553
899.365	354.556
900.435	361.76
901.507	357.563
902.579	362.567
903.649	370.17
904.72	369.574
905.789	350.577
906.861	348.181
907.93	362.584
909.001	371.988
910.07	354.791
911.138	364.195
912.209	360.198
913.278	370.202
914.348	348.005
915.416	378.609
916.484	360.612
917.552	352.016
918.622	352.219
919.69	336.023
920.758	356.227
921.825	356.63
922.893	353.634
923.96	349.437
925.029	341.641
926.096	354.044
927.163	378.448
928.23	330.651
929.296	340.055
930.363	367.658
931.429	353.062
932.495	351.065
933.559	349.669
934.625	364.072
935.691	362.076
936.757	341.879
937.823	341.283
938.888	342.686
939.952	339.69
941.017	348.093
942.082	341.697
943.147	362.5
944.21	351.104
945.275	363.907
946.339	360.111
947.402	356.114
948.466	375.118
949.529	382.921
950.593	359.925
951.655	336.928
952.719	359.132
953.78	366.135
954.844	366.139
955.905	362.942
956.969	362.946
958.03	372.749
959.091	349.753
960.154	345.156
961.215	343.16
962.276	354.163
963.337	343.567
964.399	347.971
965.46	357.374
966.52	355.378
967.58	377.181
968.64	343.185
969.7	339.188
970.762	363.392
971.821	376.595
972.881	371.999
973.94	374.802
975	352.206
976.059	350.009
977.118	367.613
978.175	333.216
979.234	364.02
980.292	351.623
981.351	353.827
982.409	364.63
983.468	339.034
984.524	377.037
985.582	359.041
986.64	365.644
987.698	338.248
988.753	357.851
989.811	366.255
990.868	367.458
991.924	352.662
992.981	352.865
994.036	341.069
995.093	367.472
996.148	347.476
997.204	358.279
998.259	346.683
999.315	353.486
999.844	362.288