File: DateTimeSpectrumPointNumber1.txt
#Acq. time (s)=	1
#Accumulations=	2
#Range (cm-¹)=	-400...5000
#Windows=	14
#Autofocus=	Off
#AutoExposure=	Off
#Spike filter=	Multiple accum.
#Delay time (s)=	0
#Binning=	1
#Readout mode=	Signal
#DeNoise=	Off
#ICS correction=	Off
#Dark correction=	Off
#Inst. Process=	Off
#Instrument=	LabRAM HR Evol
#Detector=	Emulator CCD
#Objective=	x100
#Grating=	1800 gr/mm
#ND Filter=	100%
#Laser (nm)=	512
#Slit=	150.001
#Hole=	70.0087
#Project=	A
#Sample=	B
#Site=	C
#Title=	D
#Remark=
#Date=	05.10.2017 15:13
#Acquired=	05.10.2017 15:13:12
-399.654	366
-393.983	325.003
-388.317	344.005
-382.655	372.008
-376.998	334.011
-371.345	379.014
-365.695	317.016
-360.051	354.019
-354.41	375.022
-348.773	346.024
-343.141	328.027
-337.514	327.03
-331.89	345.032
-326.271	316.035
-320.656	359.038
-315.044	325.041
-309.437	358.043
-303.836	370.046
-298.236	347.049
-292.642	317.051
-287.053	375.054
-281.466	319.057
-275.886	399.06
-270.308	313.062
-264.734	326.065
-259.165	375.068
-253.601	330.07
-248.04	375.073
-242.484	379.076
-236.931	395.078
-231.384	342.081
-225.839	373.084
-220.299	336.087
-214.764	330.089
-209.232	310.092
-203.705	363.095
-198.182	367.097
-192.662	342.1
-187.148	323.103
-181.637	338.106
-176.131	363.108
-170.628	346.111
-165.13	337.114
-159.635	339.116
-154.145	310.119
-148.66	320.122
-143.178	350.124
-137.7	340.127
-132.227	313.13
-126.757	310.133
-121.292	305.135
-115.83	305.138
-110.373	350.141
-104.92	360.143
-99.471	322.146
-94.0263	371.149
-88.5857	319.152
-83.1494	317.154
-77.7172	330.157
-72.2881	336.16
-66.8643	337.162
-61.4434	363.165
-56.028	349.168
-50.6155	308.17
-45.2072	360.173
-39.803	305.176
-34.403	355.179
-29.0071	318.181
-23.6154	324.184
-18.2278	382.187
-12.8444	305.189
-7.46507	317.192
-2.08871	309.195
3.28236	369.198
8.65048	342.2
14.0133	336.203
19.3732	328.206
24.7279	380.208
30.0796	336.211
35.426	326.214
40.7695	335.216
46.1078	338.219
51.4431	312.222
56.7755	346.225
62.1027	335.227
67.4247	343.23
72.7437	307.233
78.0599	317.235
83.3708	308.238
88.6789	352.241
93.9817	329.244
99.2793	358.246
104.574	361.249
109.866	342.252
115.153	375.254
120.436	310.257
125.715	301.26
130.991	337.262
136.261	326.265
141.529	333.268
146.792	362.271
152.051	320.273
157.306	378.276
162.558	315.287
167.804	317.349
173.048	336.626
178.289	311.863
183.523	345.128
188.756	313.009
193.983	338.974
199.206	326.09
204.426	312.523
209.641	317.091
214.853	315.618
219.548	318.099
224.809	348.152
230.067	358.205
235.323	312.258
240.573	328.31
245.821	350.363
251.063	336.416
256.303	305.469
261.537	316.521
266.769	311.574
271.998	338.627
277.221	311.68
282.44	311.733
287.656	346.785
292.869	366.838
298.077	381.891
303.282	319.944
308.482	349.997
313.679	336.049
318.873	312.102
324.062	315.155
329.247	344.208
334.428	371.26
339.607	363.313
344.78	328.366
349.951	378.419
355.117	349.472
360.28	325.524
365.438	310.577
370.593	376.63
375.745	382.683
380.893	340.736
386.035	333.788
391.175	328.841
396.312	352.894
401.444	316.947
406.573	359.999
411.697	330.052
416.818	337.105
421.935	333.158
427.049	342.211
432.157	309.263
437.263	337.316
442.364	323.369
447.463	314.422
452.558	308.474
457.649	315.527
462.735	332.58
467.818	313.633
472.898	320.686
477.974	372.738
483.046	377.791
488.114	369.844
493.177	318.897
498.239	338.95
503.295	376.002
508.349	313.055
513.397	324.108
518.444	403.161
523.487	390.213
528.524	357.266
533.559	313.319
538.589	321.372
543.616	317.425
548.641	355.477
553.658	336.53
558.676	321.583
563.688	326.636
568.695	338.689
573.7	334.741
578.702	313.794
583.699	397.847
588.694	356.9
593.684	314.952
598.669	331.005
603.651	324.058
608.631	350.111
613.606	321.164
618.579	369.216
623.546	368.269
628.511	347.322
633.471	355.375
638.427	323.427
643.382	344.48
648.33	312.533
653.277	361.586
658.218	357.639
663.156	324.691
668.091	352.744
673.022	354.797
677.95	382.85
682.874	311.903
687.795	312.28
692.711	349.418
697.624	336.936
702.533	323.395
707.439	334.681
712.341	346.469
717.24	317.404
722.134	315.995
727.026	349.221
731.913	317.38
736.798	313.177
741.322	338.149
746.255	304.191
751.186	336.232
756.112	347.273
761.034	382.315
765.953	320.356
770.869	309.397
775.78	331.439
780.689	334.48
785.593	306.521
790.495	319.563
795.392	376.604
800.286	334.645
805.176	318.687
810.063	346.728
814.948	342.77
819.828	343.811
824.705	382.852
829.578	376.894
834.446	307.935
839.314	341.976
844.174	326.018
849.035	315.059
853.889	390.1
858.742	358.142
863.59	328.183
868.434	376.224
873.276	347.266
878.115	327.307
882.949	341.348
887.779	319.39
892.606	316.431
897.431	321.473
902.251	332.514
907.068	317.555
911.881	377.597
916.69	321.638
921.498	327.679
926.299	364.721
931.1	326.762
935.896	306.803
940.688	389.845
945.477	334.886
950.262	325.928
955.044	318.969
959.822	321.01
964.597	314.052
969.37	326.093
974.138	332.134
978.902	324.176
983.663	329.217
988.422	342.258
993.176	316.3
997.926	340.341
1002.67	309.382
1007.42	365.424
1012.16	380.465
1016.9	367.506
1021.63	336.548
1026.36	351.589
1031.09	392.631
1035.81	373.672
1040.53	310.713
1045.25	312.755
1049.96	348.796
1054.67	362.837
1059.38	391.879
1064.08	311.92
1068.78	335.961
1073.47	318.003
1078.16	364.044
1082.85	315.085
1087.54	365.127
1092.22	382.168
1096.9	329.21
1101.58	341.251
1106.25	314.292
1110.92	365.334
1115.58	329.375
1120.24	392.416
1124.9	346.458
1129.56	331.499
1134.21	339.54
1138.86	355.582
1143.5	328.623
1148.14	327.664
1152.78	378.706
1157.42	338.747
1162.05	324.789
1166.68	349.83
1171.3	354.871
1175.92	326.627
1180.54	364.571
1185.16	323.609
1189.77	350.938
1194.37	344.64
1198.98	364.882
1203.58	350.199
1208.18	384.833
1212.77	334.638
1217.36	325.647
1221.95	357.651
1226.53	340.778
1231.1	380.478
1235.73	337.514
1240.36	319.549
1244.98	384.585
1249.61	372.621
1254.23	353.656
1258.84	347.692
1263.45	321.727
1268.06	377.763
1272.67	329.798
1277.27	380.834
1281.87	359.869
1286.47	390.905
1291.06	399.941
1295.65	369.976
1300.23	378.012
1304.82	351.047
1309.4	342.083
1313.97	346.118
1318.55	342.154
1323.12	403.189
1327.68	334.225
1332.24	333.26
1336.81	392.296
1341.36	395.332
1345.92	387.367
1350.47	376.403
1355.01	374.438
1359.56	340.474
1364.1	348.509
1368.64	379.545
1373.17	396.58
1377.7	368.616
1382.23	371.652
1386.75	344.687
1391.28	359.723
1395.79	342.758
1400.31	360.794
1404.82	379.829
1409.33	372.865
1413.83	362.9
1418.33	341.936
1422.83	371.971
1427.33	422.007
1431.82	358.043
1436.31	409.078
1440.8	384.114
1445.28	401.149
1449.76	349.185
1454.23	369.22
1458.71	410.256
1463.18	364.291
1467.65	364.327
1472.11	402.363
1476.57	443.398
1481.03	356.434
1485.48	397.469
1489.93	399.505
1494.38	367.54
1498.82	362.576
1503.26	394.611
1507.7	374.647
1512.14	409.682
1516.57	407.718
1521	386.754
1525.42	396.789
1529.85	413.825
1534.26	391.86
1538.68	456.896
1543.09	394.931
1547.5	390.967
1551.91	382.002
1556.31	377.038
1560.71	398.074
1565.11	411.109
1569.5	398.145
1573.89	437.18
1578.28	454.216
1582.66	406.251
1587.05	390.287
1591.42	458.322
1595.8	428.358
1600.17	417.393
1604.54	420.429
1608.91	437.465
1613.27	414.5
1617.63	456.536
1621.98	406.571
1626.34	416.607
1630.69	415.642
1635.03	411.678
1639.38	457.973
1643.72	458.39
1648.06	425.791
1652.39	424.763
1656.72	460.911
1661.05	444.757
1665.37	426.005
1669.69	462.267
1674.01	429.288
1678.33	455.626
1682.64	428.036
1686.78	429.069
1691.14	445.062
1695.49	465.056
1699.85	464.049
1704.2	446.043
1708.54	467.036
1712.89	447.03
1717.23	478.023
1721.57	454.017
1725.9	500.01
1730.23	512.004
1734.56	510.997
1738.89	452.991
1743.21	485.984
1747.53	457.978
1751.85	502.971
1756.16	468.965
1760.48	545.958
1764.78	480.952
1769.09	479.945
1773.39	494.939
1777.69	516.932
1781.98	567.926
1786.28	546.919
1790.57	509.913
1794.85	494.906
1799.14	494.9
1803.42	490.893
1807.7	539.887
1811.97	535.88
1816.24	504.874
1820.51	501.867
1824.78	533.861
1829.04	508.854
1833.3	525.848
1837.56	567.841
1841.81	551.835
1846.06	582.828
1850.31	574.822
1854.56	556.815
1858.8	541.809
1863.04	548.802
1867.27	543.796
1871.5	592.789
1875.74	623.783
1879.96	578.776
1884.19	597.77
1888.41	582.763
1892.63	595.757
1896.84	624.75
1901.05	566.744
1905.26	584.737
1909.47	581.731
1913.67	618.724
1917.87	600.718
1922.07	599.711
1926.26	612.705
1930.45	621.698
1934.64	632.692
1938.83	658.685
1943.01	670.679
1947.19	625.672
1951.37	640.666
1955.54	670.659
1959.71	628.653
1963.88	639.646
1968.05	672.64
1972.21	687.633
1976.37	643.627
1980.52	667.62
1984.68	707.614
1988.83	701.607
1992.97	657.601
1997.12	708.594
2001.26	712.588
2005.4	717.581
2009.53	733.575
2013.67	683.568
2017.8	700.562
2021.92	750.555
2026.05	754.549
2030.17	725.542
2034.29	751.536
2038.4	716.529
2042.51	754.523
2046.62	773.516
2050.73	731.51
2054.83	733.503
2058.93	826.497
2063.03	740.49
2067.13	793.484
2071.22	789.477
2075.31	784.125
2079.39	808.789
2083.48	769.879
2087.56	794.311
2091.64	823.196
2095.71	811.457
2099.78	827.311
2103.85	812.966
2107.92	839.257
2111.98	850.982
2116.04	892.455
2120.08	899.826
2124.18	889.824
2128.29	889.822
2132.39	841.82
2136.49	851.818
2140.58	925.817
2144.67	893.815
2148.76	864.813
2152.85	896.811
2156.93	877.809
2161.01	932.807
2165.09	900.805
2169.16	934.804
2173.23	901.802
2177.3	903.8
2181.37	914.798
2185.43	954.796
2189.49	925.794
2193.55	972.793
2197.61	951.791
2201.66	976.789
2205.71	983.787
2209.75	994.785
2213.8	989.783
2217.84	989.781
2221.88	1029.78
2225.91	1006.78
2229.95	1005.78
2233.98	991.774
2238	1035.77
2242.03	1001.77
2246.05	1007.77
2250.07	1016.77
2254.08	1040.76
2258.1	1074.76
2262.11	1061.76
2266.12	1089.76
2270.12	1051.76
2274.12	1070.76
2278.12	1121.75
2282.12	1106.75
2286.11	1083.75
2290.1	1150.75
2294.09	1157.75
2298.08	1164.74
2302.06	1124.74
2306.04	1116.74
2310.02	1132.74
2313.99	1133.74
2317.96	1154.74
2321.93	1155.73
2325.9	1155.73
2329.86	1210.73
2333.82	1156.73
2337.78	1227.73
2341.74	1207.72
2345.69	1216.72
2349.64	1196.72
2353.58	1204.72
2357.53	1193.72
2361.47	1202.72
2365.41	1263.71
2369.34	1283.71
2373.28	1268.71
2377.21	1321.71
2381.14	1258.71
2385.06	1294.7
2388.98	1276.7
2392.9	1285.7
2396.82	1314.7
2400.73	1292.7
2404.64	1317.69
2408.55	1299.69
2412.46	1317.69
2416.36	1308.69
2420.26	1328.69
2424.16	1364.69
2428.06	1317.68
2431.95	1391.68
2435.84	1380.68
2439.72	1364.68
2443.61	1394.68
2447.49	1359.67
2451.37	1353.67
2455.24	1434.67
2459.12	1401.67
2462.99	1412.67
2466.86	1429.67
2470.72	1404.66
2474.58	1424.66
2478.44	1459.66
2482.3	1419.24
2486.16	1453.91
2490.01	1428.17
2493.86	1427.65
2497.7	1450.42
2501.55	1446.48
2505.39	1479.5
2509.23	1478.91
2513.06	1488.3
2516.89	1535.34
2520.72	1503.42
2524.13	1492.31
2528.01	1542.32
2531.88	1553.34
2535.75	1578.35
2539.62	1505.37
2543.48	1536.38
2547.34	1552.4
2551.2	1520.41
2555.06	1522.43
2558.91	1552.44
2562.77	1564.46
2566.61	1571.47
2570.46	1543.49
2574.3	1595.5
2578.14	1561.52
2581.98	1619.54
2585.82	1564.55
2589.65	1590.57
2593.48	1619.58
2597.31	1662.6
2601.14	1634.61
2604.96	1629.63
2608.78	1611.64
2612.6	1628.66
2616.41	1630.67
2620.22	1656.69
2624.03	1648.7
2627.84	1690.72
2631.64	1621.73
2635.44	1702.75
2639.24	1635.76
2643.04	1658.78
2646.83	1667.8
2650.63	1671.81
2654.41	1658.83
2658.2	1668.84
2661.98	1686.86
2665.76	1674.87
2669.54	1707.89
2673.32	1714.9
2677.09	1687.92
2680.86	1683.93
2684.63	1707.95
2688.4	1714.96
2692.16	1702.98
2695.92	1703.99
2699.68	1717.01
2703.43	1765.02
2707.18	1728.04
2710.93	1766.06
2714.68	1784.07
2718.43	1770.09
2722.17	1736.1
2725.91	1724.12
2729.65	1731.13
2733.38	1768.15
2737.11	1799.16
2740.84	1745.18
2744.57	1741.19
2748.29	1826.21
2752.02	1766.22
2755.73	1818.24
2759.45	1765.25
2763.17	1774.27
2766.88	1786.28
2770.59	1792.3
2774.29	1786.32
2778	1790.33
2781.7	1766.35
2785.4	1777.36
2789.09	1831.38
2792.79	1794.39
2796.48	1778.41
2800.17	1765.42
2803.85	1764.44
2807.54	1778.45
2811.22	1816.47
2814.9	1775.48
2818.57	1809.5
2822.24	1799.51
2825.92	1780.53
2829.58	1834.54
2833.25	1805.56
2836.91	1777.58
2840.57	1779.59
2844.23	1842.61
2847.89	1801.62
2851.54	1829.64
2855.19	1805.65
2858.84	1833.67
2862.49	1780.68
2866.13	1817.7
2869.77	1822.56
2873.41	1800.31
2877.04	1802.04
2880.68	1796.78
2884.31	1810.55
2887.94	1791.71
2891.56	1783.7
2895.18	1814.2
2898.8	1804.01
2902.42	1778.96
2906.04	1792.63
2909.52	1810.76
2913.18	1783.76
2916.83	1775.75
2920.49	1816.74
2924.14	1769.73
2927.79	1802.73
2931.44	1804.72
2935.08	1806.71
2938.73	1783.7
2942.37	1794.69
2946	1813.69
2949.64	1754.68
2953.27	1749.67
2956.9	1755.66
2960.53	1782.66
2964.15	1770.65
2967.78	1762.64
2971.4	1824.63
2975.02	1755.63
2978.63	1757.62
2982.24	1766.61
2985.85	1735.6
2989.46	1736.59
2993.07	1763.59
2996.67	1758.58
3000.27	1730.57
3003.87	1736.56
3007.47	1743.56
3011.06	1716.55
3014.65	1745.54
3018.24	1714.53
3021.83	1713.52
3025.41	1695.52
3028.99	1705.51
3032.57	1697.5
3036.15	1773.49
3039.72	1693.49
3043.3	1702.48
3046.86	1695.47
3050.43	1675.46
3054	1710.45
3057.56	1673.45
3061.12	1674.44
3064.68	1655.43
3068.23	1738.42
3071.78	1673.42
3075.33	1665.41
3078.88	1643.4
3082.43	1672.39
3085.97	1634.38
3089.51	1635.38
3093.05	1687.37
3096.58	1621.36
3100.12	1687.35
3103.65	1624.35
3107.18	1660.34
3110.7	1614.33
3114.23	1606.32
3117.75	1614.31
3121.27	1620.31
3124.78	1625.3
3128.3	1647.29
3131.81	1577.28
3135.32	1593.28
3138.83	1584.27
3142.33	1556.26
3145.83	1599.25
3149.33	1558.25
3152.83	1537.24
3156.33	1529.23
3159.82	1526.22
3163.31	1535.21
3166.8	1516.21
3170.28	1585.2
3173.77	1504.19
3177.25	1522.18
3180.72	1538.18
3184.2	1496.17
3187.68	1492.16
3191.15	1512.15
3194.61	1534.14
3198.08	1462.14
3201.55	1474.13
3205.01	1511.12
3208.47	1501.11
3211.93	1511.11
3215.38	1450.1
3218.83	1459.09
3222.28	1431.08
3225.73	1434.07
3229.18	1443.07
3232.62	1426.34
3236.06	1402.69
3239.5	1415.82
3242.93	1456.04
3246.37	1443.88
3249.8	1422.85
3253.23	1377.06
3256.65	1378.2
3260.08	1394.85
3263.5	1350.29
3266.92	1387.42
3270.34	1392.38
3273.75	1340.23
3277.21	1338.17
3280.67	1326.1
3284.13	1371.03
3287.58	1336.97
3291.03	1341.9
3294.48	1314.84
3297.92	1279.77
3301.37	1317.71
3304.81	1283.64
3308.25	1301.57
3311.69	1312.51
3315.12	1258.44
3318.55	1291.38
3321.98	1277.31
3325.41	1286.24
3328.84	1233.18
3332.26	1220.11
3335.68	1274.05
3339.1	1206.98
3342.52	1214.92
3345.93	1212.85
3349.35	1207.78
3352.76	1195.72
3356.16	1169.65
3359.57	1192.59
3362.97	1155.52
3366.37	1155.46
3369.77	1165.39
3373.17	1152.32
3376.56	1162.26
3379.95	1134.19
3383.34	1120.13
3386.73	1172.06
3390.11	1114.99
3393.5	1121.93
3396.88	1139.86
3400.25	1094.8
3403.63	1127.73
3407.01	1082.67
3410.38	1065.6
3413.74	1091.53
3417.11	1068.47
3420.48	1049.4
3423.84	1051.34
3427.2	1058.27
3430.56	1041.2
3433.91	1085.14
3437.27	1015.07
3440.62	1016.01
3443.97	1063.94
3447.31	996.876
3450.66	1022.81
3454	1001.74
3457.34	1027.68
3460.67	983.612
3464.01	984.547
3467.34	959.481
3470.67	974.415
3474	966.349
3477.33	978.283
3480.65	969.217
3483.97	951.152
3487.3	921.086
3490.61	957.02
3493.93	976.954
3497.24	964.888
3500.55	945.823
3503.86	891.757
3507.17	882.691
3510.47	931.625
3513.77	910.559
3517.07	923.493
3520.37	930.428
3523.66	853.362
3526.96	902.296
3530.25	907.23
3533.54	872.164
3536.82	899.099
3540.1	851.033
3543.39	825.967
3546.67	838.901
3549.94	884.835
3553.22	814.769
3556.49	831.704
3559.76	820.638
3563.03	855.572
3566.3	801.506
3569.56	804.44
3572.82	783.375
3576.08	824.309
3579.34	763.243
3582.6	812.036
3585.85	816.473
3589.1	769.589
3592.35	786.562
3595.59	782.528
3598.84	779.684
3602.08	754.458
3605.32	749.331
3608.56	750.766
3611.79	766.632
3614.71	731.075
3617.99	722.101
3621.26	704.126
3624.54	718.152
3627.81	698.178
3631.08	732.204
3634.35	766.23
3637.61	711.255
3640.87	745.281
3644.14	712.307
3647.39	723.333
3650.65	729.359
3653.9	709.384
3657.16	698.41
3660.41	704.436
3663.65	705.462
3666.9	679.488
3670.14	692.513
3673.39	641.539
3676.62	665.565
3679.86	712.591
3683.1	638.617
3686.33	637.642
3689.56	625.668
3692.79	645.694
3696.02	671.72
3699.24	607.745
3702.46	636.771
3705.68	619.797
3708.9	606.823
3712.12	610.849
3715.33	636.875
3718.54	641.9
3721.75	654.926
3724.96	582.952
3728.16	569.978
3731.37	623.004
3734.57	573.029
3737.77	584.055
3740.96	591.081
3744.16	559.107
3747.35	602.133
3750.54	625.158
3753.73	573.184
3756.92	559.21
3760.1	578.236
3763.28	583.261
3766.46	544.287
3769.64	601.313
3772.81	532.339
3775.99	523.365
3779.16	526.39
3782.33	538.416
3785.5	530.442
3788.66	512.468
3791.82	520.494
3794.98	520.519
3798.14	501.545
3801.3	527.571
3804.45	567.597
3807.61	492.623
3810.76	508.648
3813.91	525.674
3817.05	500.7
3820.2	505.726
3823.34	479.752
3826.48	517.777
3829.61	483.803
3832.75	544.829
3835.88	495.855
3839.02	480.881
3842.14	501.906
3845.27	479.932
3848.4	470.958
3851.52	505.984
3854.64	498.009
3857.76	530.035
3860.88	466.061
3863.99	515.087
3867.1	476.113
3870.22	460.138
3873.32	479.164
3876.43	462.19
3879.53	457.216
3882.64	463.242
3885.74	438.267
3888.83	485.293
3891.93	441.319
3895.02	468.345
3898.12	514.371
3901.21	434.396
3904.29	455.422
3907.38	469.448
3910.46	447.919
3913.54	427.629
3916.62	423.928
3919.7	415.841
3922.78	451.263
3925.85	428.358
3928.92	443.152
3931.99	417.095
3935.06	425.754
3938.12	427.536
3941.18	426.777
3944.24	405.6
3947.35	412.609
3950.45	475.618
3953.55	410.627
3956.65	407.636
3959.75	421.645
3962.84	410.655
3965.93	419.664
3969.02	425.673
3972.11	413.682
3975.2	398.691
3978.28	390.7
3981.36	407.71
3984.44	381.719
3987.52	424.728
3990.6	398.737
3993.67	443.746
3996.75	447.755
3999.82	419.765
4002.88	425.774
4005.95	373.783
4009.01	372.792
4012.08	395.801
4015.14	417.81
4018.19	386.819
4021.25	402.829
4024.3	369.838
4027.36	436.847
4030.41	362.856
4033.46	386.865
4036.5	368.874
4039.55	368.884
4042.59	354.893
4045.63	356.902
4048.67	381.911
4051.7	393.92
4054.74	353.929
4057.77	391.939
4060.8	437.948
4063.83	391.957
4066.85	394.966
4069.88	366.975
4072.9	432.984
4075.92	364.994
4078.94	355.003
4081.95	376.012
4084.97	393.021
4087.98	371.03
4090.99	366.039
4094	381.049
4097.01	358.058
4100.01	350.067
4103.01	345.076
4106.01	359.085
4109.01	362.094
4112.01	386.104
4115	409.113
4117.99	372.122
4120.98	392.131
4123.97	334.14
4126.96	364.149
4129.94	398.158
4132.93	378.168
4135.91	368.177
4138.89	409.186
4141.86	367.195
4144.84	350.204
4147.81	352.213
4150.78	360.223
4153.75	339.232
4156.72	402.241
4159.68	347.25
4162.64	350.259
4165.6	355.268
4168.56	414.278
4171.52	346.287
4174.48	353.296
4177.43	370.305
4180.38	357.314
4183.33	415.323
4186.27	337.333
4189.22	357.342
4192.16	366.351
4195.1	329.36
4198.04	378.369
4200.98	358.378
4203.92	375.388
4206.85	406.397
4209.78	348.406
4212.71	391.415
4215.64	344.424
4218.57	360.817
4221.49	326.152
4224.41	342.385
4227.33	386.223
4230.25	343.701
4233.16	367.511
4236.08	342.004
4238.99	349.019
4241.9	354.797
4244.81	332.388
4247.71	322.74
4250.62	321.875
4253.33	367.298
4256.27	363.315
4259.21	358.331
4262.16	391.348
4265.09	327.364
4268.03	372.38
4270.97	381.397
4273.9	341.413
4276.83	340.429
4279.76	314.446
4282.69	351.462
4285.62	361.479
4288.54	314.495
4291.46	354.511
4294.38	393.528
4297.3	363.544
4300.22	314.561
4303.13	323.577
4306.04	313.593
4308.95	347.61
4311.86	377.626
4314.77	357.642
4317.67	400.659
4320.58	353.675
4323.48	351.692
4326.38	324.708
4329.28	343.724
4332.17	359.741
4335.06	330.757
4337.96	317.773
4340.85	392.79
4343.73	315.806
4346.62	362.823
4349.5	324.839
4352.39	353.855
4355.27	326.872
4358.15	316.888
4361.02	387.904
4363.9	328.921
4366.77	339.937
4369.64	361.954
4372.51	344.97
4375.38	315.986
4378.25	317.003
4381.11	337.019
4383.97	323.036
4386.83	314.052
4389.69	349.068
4392.54	395.085
4395.4	339.101
4398.25	310.117
4401.1	329.134
4403.95	313.15
4406.8	389.167
4409.64	371.183
4412.48	360.199
4415.33	332.216
4418.17	338.232
4421	321.248
4423.84	331.265
4426.67	320.281
4429.5	340.298
4432.33	323.314
4435.16	311.33
4437.99	312.347
4440.81	372.363
4443.64	395.38
4446.46	363.396
4449.27	364.412
4452.09	361.429
4454.91	334.445
4457.72	343.461
4460.53	336.478
4463.34	307.494
4466.15	360.511
4468.95	352.527
4471.76	396.543
4474.56	393.56
4477.36	314.576
4480.16	357.592
4482.96	349.609
4485.75	307.625
4488.54	327.642
4491.33	347.658
4494.12	362.674
4496.91	331.691
4499.7	316.707
4502.48	312.723
4505.26	348.74
4508.04	336.756
4510.82	340.987
4513.6	311.289
4516.37	337.554
4519.14	327.779
4521.91	362.288
4524.68	387.804
4527.45	346.932
4530.22	339.209
4532.98	350.319
4535.74	339.589
4538.5	359.122
4541.26	341
4543.75	318.865
4546.55	355.827
4549.35	365.789
4552.14	333.751
4554.93	341.713
4557.72	377.675
4560.51	356.637
4563.3	327.599
4566.09	336.561
4568.87	336.523
4571.65	310.485
4574.43	349.448
4577.21	321.41
4579.98	323.372
4582.76	349.334
4585.53	342.296
4588.3	303.258
4591.07	324.22
4593.84	341.182
4596.6	360.144
4599.37	325.106
4602.13	321.09
4604.89	369.15
4607.65	317.21
4610.4	322.27
4613.16	361.331
4615.91	330.391
4618.66	356.451
4621.41	308.511
4624.16	315.572
4626.91	309.632
4629.65	317.692
4632.39	384.752
4635.13	339.812
4637.87	354.873
4640.61	329.933
4643.34	342.993
4646.08	304.053
4648.81	311.114
4651.54	335.174
4654.27	311.234
4656.99	382.294
4659.72	307.355
4662.44	315.415
4665.16	311.475
4667.88	374.535
4670.6	343.596
4673.31	304.656
4676.03	317.716
4678.74	361.776
4681.45	320.836
4684.16	318.897
4686.87	334.957
4689.57	329.017
4692.28	386.078
4694.98	330.138
4697.68	369.198
4700.38	316.258
4703.07	379.318
4705.77	315.379
4708.46	373.439
4711.15	351.499
4713.84	319.559
4716.53	384.62
4719.21	329.68
4721.9	313.74
4724.58	316.8
4727.26	334.861
4729.94	324.921
4732.61	341.981
4735.29	336.041
4737.96	367.102
4740.64	330.162
4743.31	307.222
4745.97	312.282
4748.64	319.342
4751.3	316.403
4753.97	307.463
4756.63	380.523
4759.29	336.583
4761.95	308.644
4764.6	401.704
4767.26	318.764
4769.91	325.824
4772.56	362.885
4775.21	319.945
4777.86	352.005
4780.5	358.065
4783.15	307.126
4785.79	334.186
4788.43	326.246
4791.06	337.041
4793.7	343.187
4796.34	367.074
4798.97	323.765
4801.6	362.763
4804.23	346.17
4806.86	337.561
4809.49	340.167
4812.11	319.103
4814.73	334.454
4817.35	324.793
4819.93	305.743
4822.59	310.689
4825.25	315.635
4827.91	377.58
4830.56	305.526
4833.21	312.472
4835.87	320.418
4838.52	317.364
4841.17	345.31
4843.81	306.256
4846.46	332.202
4849.1	315.148
4851.74	326.094
4854.38	323.04
4857.02	334.986
4859.66	325.932
4862.29	367.878
4864.93	355.824
4867.56	348.769
4870.19	354.715
4872.81	322.661
4875.44	329.607
4878.07	390.553
4880.69	325.499
4883.31	371.445
4885.93	372.391
4888.55	313.337
4891.17	323.283
4893.78	337.229
4896.39	320.175
4899	319.121
4901.61	324.067
4904.22	345.013
4906.83	372.958
4909.43	307.904
4912.03	375.85
4914.64	350.796
4917.24	317.742
4919.83	344.688
4922.43	350.634
4925.02	333.58
4927.62	329.526
4930.21	316.472
4932.8	323.418
4935.39	307.364
4937.97	334.31
4940.56	335.256
4943.14	305.202
4945.72	303.147
4948.3	363.093
4950.88	308.039
4953.45	349.985
4956.03	362.931
4958.6	315.877
4961.17	341.823
4963.74	313.769
4966.31	303.715
4968.88	367.661
4971.44	367.607
4974	307.553
4976.56	307.499
4979.12	344.445
4981.68	340.391
4984.24	360.336
4986.79	390.282
4989.34	310.228
4991.89	311.174
4994.44	330.12
4996.99	316.066
4999.54	371.012
4999.82	336.006