File: DateTimeSpectrumPointNumber1.txt
#Acq. time (s)=	1
#Accumulations=	2
#Range (cm-¹)=	0...1000
#Windows=	2
#Autofocus=	Off
#AutoExposure=	Off
#Spike filter=	Multiple accum.
#Delay time (s)=	0
#Binning=	1
#Readout mode=	Signal
#DeNoise=	Off
#ICS correction=	Off
#Dark correction=	Off
#Inst. Process=	Off
#Instrument=	LabRAM HR Evol
#Detector=	Emulator CCD
#Objective=	x100
#Grating=	1800 gr/mm
#ND Filter=	100%
#Laser (nm)=	512
#Slit=	150.001
#Hole=	70.0087
#Project=	A
#Sample=	B
#Site=	C
#Title=	D_7
#Remark=
#Date=	16.10.2017 08:21
#Acquired=	16.10.2017 08:21:13
0.232828	348
1.43646	369
2.63761	340
3.83862	344
5.04181	352
6.24252	363
7.44541	334
8.64583	349
9.8461	314
11.0462	312
12.2485	308
13.4483	376
14.648	346
15.8476	361
17.0493	342
18.2485	305
19.4476	307
20.6465	328
21.8453	372
23.044	372
24.2425	387
25.4408	329
26.639	357
27.8371	366
29.035	339
30.2328	382
31.4304	363
32.6278	313
33.8252	366
35.0223	358
36.217	311
37.4139	316
38.6107	336
39.8072	313
41.0037	306
42.1977	350
43.3938	357
44.5898	325
45.7833	309
46.9791	351
48.1746	325
49.3677	354
50.563	327
51.7558	314
52.9508	353
54.1433	331
55.3379	341
56.5302	319
57.7246	312
58.9165	345
60.1106	325
61.3022	327
62.4937	332
63.6874	350
64.8786	316
66.0696	334
67.2628	305
68.4536	393
69.6442	328
70.8347	337
72.025	356
73.2175	317
74.4075	356
75.5974	327
76.7871	353
77.9767	360
79.1662	325
80.3555	376
81.5447	320
82.7337	315
83.9225	328
85.1113	305
86.2998	319
87.4883	306
88.6766	321
89.8647	361
91.0504	348
92.2382	335
93.4259	308
94.6135	305
95.8009	359
96.9859	316
98.173	338.016
99.36	327.032
100.545	324.048
101.731	334.065
102.918	397.081
104.102	326.097
105.288	303.113
106.472	329.129
107.658	391.145
108.841	338.162
110.027	314.178
111.21	360.194
112.396	316.21
113.579	309.226
114.764	330.242
115.946	371.258
117.129	335.275
118.314	352.291
119.496	315.307
120.678	311.323
121.862	324.339
123.044	343.355
124.226	329.372
125.407	327.388
126.591	329.404
127.772	302.42
128.953	310.436
130.134	325.452
131.315	346.468
132.495	308.485
133.676	309.501
134.856	338.517
136.036	324.533
137.216	301.549
138.396	330.565
139.576	366.582
140.756	320.598
141.935	321.614
143.115	329.63
144.294	366.646
145.471	307.662
146.65	342.678
147.828	315.695
149.007	348.711
150.185	317.727
151.361	312.743
152.54	315.759
153.718	346.775
154.893	364.792
156.071	359.808
157.249	301.824
158.424	327.84
159.601	335.856
160.776	374.872
161.953	322.888
163.128	361.905
164.305	311.921
165.479	370.937
166.655	371.953
167.83	362.969
169.003	375.985
170.18	313.002
171.353	349.018
172.527	311.034
173.702	329.05
174.875	358.066
176.049	345.082
177.221	317.098
178.396	343.115
179.569	328.131
180.742	320.147
181.914	345.163
183.086	373.179
184.258	368.195
185.43	308.212
186.604	328.228
187.776	322.244
188.947	347.26
190.119	392.276
191.29	341.292
192.459	309.308
193.63	312.325
194.8	303.341
195.971	308.357
197.142	327.373
198.312	364.389
199.482	347.405
200.65	351.422
201.82	375.438
202.99	337.454
204.159	334.47
205.327	350.486
206.496	340.502
207.665	332.518
208.832	322.535
210.001	371.551
211.167	306.567
212.336	373.583
213.505	309.599
214.671	327.615
215.839	328.632
217.005	331.648
218.17	317.664
219.338	338.68
220.504	305.696
221.671	340.712
222.836	312.728
224.001	349.745
225.168	354.761
226.333	326.777
227.498	311.793
228.662	329.809
229.829	351.825
230.993	306.842
232.157	302.858
233.321	389.874
234.484	370.89
235.648	317.906
236.814	305.922
237.977	341.938
239.14	318.955
240.303	307.971
241.466	354.987
242.629	303.003
243.791	311.019
244.951	370.035
246.114	303.052
247.276	358.068
248.438	315.084
249.6	361.1
250.761	344.116
251.923	327.132
253.082	315.148
254.244	323.165
255.405	329.181
256.566	311.197
257.725	354.213
258.885	338.229
260.044	344.245
261.204	326.262
262.365	342.278
263.522	352.294
264.682	358.31
265.84	369.326
267	320.342
268.157	382.358
269.317	323.375
270.474	347.391
271.633	353.407
272.79	313.423
273.947	308.439
275.106	332.455
276.262	307.472
277.418	303.488
278.574	336.504
279.733	302.52
280.888	359.536
282.044	317.552
283.2	331.568
284.355	341.585
285.513	376.601
286.668	319.617
287.823	320.633
288.978	357.649
290.133	312.665
291.287	303.682
292.442	312.698
293.596	358.714
294.75	333.73
295.904	365.746
297.058	376.762
298.21	312.778
299.363	349.795
300.517	343.811
301.67	355.827
302.823	308.843
303.974	347.859
305.127	315.875
306.28	372.892
307.433	341.908
308.583	344.924
309.735	308.94
310.888	363.956
312.038	355.972
313.19	367.988
314.339	304.005
315.491	309.021
316.64	311.037
317.792	328.053
318.941	347.069
320.092	360.085
321.241	314.102
322.389	322.118
323.54	325.134
324.688	335.15
325.836	313.166
326.987	319.182
328.135	313.198
329.283	345.215
330.432	337.231
331.58	344.247
332.727	388.263
333.875	303.279
335.022	330.295
336.169	331.312
337.316	356.328
338.462	349.344
339.609	347.36
340.755	371.376
341.902	317.392
343.048	348.408
344.194	307.425
345.34	309.441
346.485	320.457
347.631	339.473
348.776	344.489
349.922	313.505
351.067	360.522
352.21	317.538
353.355	312.554
354.5	322.57
355.644	316.586
356.786	321.602
357.931	316.618
359.075	335.635
360.217	366.651
361.361	321.667
362.503	344.683
363.646	331.699
364.788	307.715
365.931	322.732
367.072	329.748
368.215	304.764
369.356	320.78
370.499	306.796
371.639	371.812
372.78	319.828
373.922	400.845
375.062	332.861
376.202	316.877
377.344	322.893
378.484	319.909
379.624	362.925
380.763	312.942
381.905	303.958
383.044	340.974
384.183	305.99
385.322	329.006
386.46	353.022
387.599	362.038
388.737	335.055
389.876	333.071
391.014	320.087
392.152	363.103
393.29	367.119
394.428	324.135
395.565	341.152
396.703	323.168
397.838	347.184
398.975	321.2
400.112	386.216
401.249	377.232
402.386	344.248
403.521	368.265
404.657	307.281
405.794	319.297
406.928	340.313
408.064	312.329
409.2	360.345
410.334	320.362
411.469	307.378
412.603	321.394
413.738	351.41
414.871	369.426
416.007	320.442
417.14	338.458
418.275	329.475
419.407	365.491
420.54	377.507
421.674	329.523
422.806	304.539
423.938	311.555
425.073	344.572
426.204	358.588
427.336	335.604
428.467	307.62
429.601	307.636
430.732	330.652
431.863	336.668
432.994	383.685
434.125	327.701
435.256	329.717
436.387	323.733
437.517	359.749
438.647	311.765
439.778	343.782
440.908	319.798
442.038	367.814
443.167	338.83
444.297	383.846
445.426	306.862
446.554	322.878
447.683	358.895
448.812	310.911
449.941	334.927
451.068	315.943
452.196	316.959
453.325	323.975
454.451	306.992
455.579	305.008
456.708	386.024
457.833	338.04
458.961	307.056
460.087	325.072
461.215	356.088
462.34	316.105
463.467	370.121
464.592	310.137
465.719	374.153
466.844	347.169
467.969	310.185
469.095	320.202
470.22	327.218
471.344	317.234
472.47	327.25
473.594	346.266
474.718	324.282
475.842	327.298
476.965	335.315
478.091	395.331
479.214	310.347
480.338	379.363
481.461	308.379
482.583	349.395
483.706	347.412
484.829	337.428
485.951	308.444
487.074	356.46
488.196	307.476
489.318	338.492
490.44	365.508
491.56	334.525
492.681	335.541
493.803	306.557
494.924	316.573
496.046	309.589
497.165	347.605
498.286	360.622
499.407	338.638
500.525	376.654
501.646	359.67
502.767	329.686
503.885	339.702
505.005	313.718
506.123	367.735
507.243	312.751
508.361	380.767
509.48	320.783
510.598	362.799
511.717	382.815
512.834	326.832
513.953	347.848
515.07	311.864
516.187	368.88
517.306	315.896
518.422	326.912
519.539	357.928
520.655	343.945
521.773	325.961
522.889	325.977
524.005	331.993
525.121	344.009
526.236	308.025
527.352	320.042
528.467	350.058
529.582	378.074
530.697	321.09
531.812	369.106
532.927	336.122
534.042	329.118
535.156	344.255
536.27	308.001
537.385	335.39
538.499	350.148
539.611	361.095
540.724	390.204
541.838	339.712
542.952	337.857
544.063	387.049
545.176	349.604
546.29	324.064
547.4	370.224
548.513	338.617
549.626	336.191
550.737	337.246
551.849	350.71
552.959	348.021
554.072	331.273
555.182	359.265
556.294	337.43
557.403	340.529
558.513	361.51
559.625	351.679
560.734	313.264
561.845	326.635
562.954	332.286
564.063	327.695
565.172	333.253
566.283	326.232
567.392	335.78
568.5	342.308
569.608	324.578
570.716	353.053
571.824	354.316
572.932	336.485
574.04	350.687
575.148	334.298
576.255	355.447
577.363	323.932
578.47	316.756
579.577	349.795
580.684	352.473
581.791	339.023
582.897	319.033
584.004	315.442
585.111	312.177
586.215	341.374
587.321	345.576
588.208	323.911
589.325	306.901
590.444	366.891
591.56	378.88
592.679	351.87
593.796	317.86
594.912	316.85
596.03	367.839
597.146	321.829
598.262	304.819
599.38	345.808
600.496	318.798
601.611	329.788
602.726	365.778
603.842	319.767
604.957	326.757
606.074	327.747
607.189	371.736
608.303	383.726
609.418	338.716
610.532	343.706
611.647	319.695
612.761	330.685
613.875	339.675
614.989	321.664
616.103	305.654
617.216	347.644
618.33	368.633
619.441	358.623
620.554	307.613
621.667	308.603
622.78	329.592
623.893	303.582
625.004	305.572
626.116	355.561
627.229	372.551
628.341	330.541
629.451	339.531
630.563	319.52
631.673	348.51
632.785	320.5
633.896	317.489
635.006	307.479
636.117	362.469
637.226	322.458
638.337	320.448
639.446	368.438
640.557	339.428
641.666	322.417
642.774	326.407
643.885	340.397
644.993	366.386
646.101	380.376
647.211	319.366
648.319	341.356
649.426	344.345
650.536	367.335
651.644	310.325
652.751	391.314
653.858	318.304
654.965	346.294
656.072	356.283
657.181	318.273
658.287	336.263
659.394	318.253
660.5	307.242
661.607	304.232
662.713	361.222
663.819	359.211
664.925	367.201
666.03	312.191
667.134	333.181
668.239	344.17
669.344	303.16
670.45	332.15
671.555	391.139
672.66	305.129
673.762	312.119
674.867	315.108
675.972	304.098
677.074	369.088
678.178	310.078
679.282	336.067
680.384	349.057
681.488	326.047
682.592	376.036
683.693	315.026
684.797	332.016
685.898	340.006
687.001	358.995
688.102	335.985
689.205	356.975
690.306	361.964
691.407	339.954
692.509	304.944
693.61	305.934
694.712	368.923
695.812	329.913
696.912	310.903
698.012	354.892
699.114	325.882
700.213	350.872
701.313	334.861
702.412	305.851
703.511	344.841
704.61	317.831
705.711	367.82
706.81	308.81
707.909	346.8
709.007	343.789
710.106	339.779
711.204	344.769
712.302	302.759
713.4	337.748
714.498	335.738
715.596	350.728
716.691	316.717
717.789	320.707
718.886	381.697
719.983	347.686
721.081	377.676
722.175	318.666
723.272	335.656
724.369	341.645
725.466	358.635
726.56	325.625
727.656	316.614
728.75	327.604
729.846	317.594
730.942	331.584
732.036	359.573
733.132	341.563
734.225	357.553
735.321	336.542
736.414	314.532
737.509	321.522
738.602	328.512
739.695	363.501
740.79	305.491
741.882	356.481
742.974	313.47
744.069	332.46
745.161	358.45
746.253	308.439
747.347	343.429
748.439	311.419
749.531	350.409
750.622	315.398
751.714	348.388
752.805	382.378
753.896	332.367
754.989	321.357
756.08	337.347
757.171	336.337
758.261	331.326
759.352	333.316
760.442	318.306
761.53	340.295
762.621	324.285
763.711	343.275
764.8	308.264
765.89	304.254
766.98	321.244
768.069	318.234
769.157	357.223
770.246	307.213
771.335	324.203
772.422	313.192
773.511	350.182
774.599	307.172
775.686	311.162
776.774	320.151
777.863	362.141
778.949	324.131
780.037	327.12
781.123	322.11
782.211	317.1
783.296	340.089
784.384	319.079
785.469	335.069
786.554	364.059
787.641	326.048
788.726	330.038
789.811	315.028
790.898	329.017
791.983	349.007
793.067	346.997
794.154	342.987
795.238	309.976
796.322	395.966
797.406	304.956
798.49	385.945
799.573	381.935
800.657	326.925
801.743	359.915
802.826	350.904
803.909	346.894
804.992	362.884
806.075	338.873
807.156	338.863
808.238	364.853
809.321	328.842
810.404	342.832
811.486	331.822
812.568	312.812
813.65	345.801
814.73	325.791
815.812	325.781
816.893	351.77
817.975	302.76
819.054	349.75
820.136	329.74
821.217	352.729
822.296	335.719
823.377	390.709
824.455	363.698
825.536	364.688
826.617	327.678
827.695	348.667
828.775	313.657
829.853	313.647
830.931	344.637
832.011	358.626
833.089	306.616
834.169	324.606
835.246	332.595
836.323	328.585
837.403	324.575
838.48	325.565
839.557	315.554
840.634	344.544
841.71	308.534
842.789	372.523
843.865	390.513
844.942	367.503
846.018	303.492
847.094	311.482
848.17	311.472
849.246	321.462
850.321	342.451
851.397	323.441
852.473	317.431
853.548	329.42
854.623	333.41
855.698	329.4
856.773	322.39
857.848	332.379
858.921	328.369
859.995	378.359
861.07	366.348
862.144	338.338
863.216	304.328
864.29	359.318
865.364	325.307
866.436	318.297
867.51	323.287
868.583	343.276
869.655	305.266
870.728	303.256
871.799	337.245
872.872	366.235
873.943	310.225
875.016	321.215
876.086	307.204
877.159	324.194
878.229	330.184
879.3	304.173
880.372	344.163
881.442	327.153
882.512	351.143
883.582	311.132
884.653	336.122
885.723	314.112
886.792	320.101
887.861	344.091
888.931	315.081
890.002	317.07
891.071	330.06
892.139	317.05
893.208	335.04
894.277	311.029
895.345	309.019
896.413	375.009
897.481	305.998
898.549	353.988
899.617	304.978
900.683	335.968
901.751	327.957
902.818	317.947
903.886	341.937
904.953	305.926
906.018	329.916
907.085	303.906
908.152	359.896
909.219	376.885
910.284	342.875
911.35	311.865
912.417	329.854
913.481	375.844
914.547	302.834
915.611	328.823
916.677	324.813
917.741	378.803
918.806	312.793
919.87	327.782
920.935	322.772
921.999	382.762
923.062	302.751
924.127	314.741
925.19	368.731
926.252	327.721
927.317	305.71
928.38	311.7
929.442	326.69
930.504	322.679
931.566	335.669
932.631	319.659
933.692	303.648
934.754	332.638
935.816	347.628
936.877	303.618
937.939	366.607
939	323.597
940.061	327.587
941.122	310.576
942.183	345.566
943.244	309.556
944.305	375.546
945.365	327.535
946.424	331.525
947.484	307.515
948.544	375.504
949.604	366.494
950.664	391.484
951.722	313.473
952.782	376.463
953.841	323.453
954.899	303.443
955.958	326.432
957.015	327.422
958.074	317.412
959.133	357.401
960.19	344.391
961.249	310.381
962.305	311.371
963.364	311.36
964.42	344.35
965.476	366.34
966.535	351.329
967.591	373.319
968.646	355.309
969.704	309.298
970.76	335.288
971.815	317.278
972.87	341.268
973.928	341.257
974.983	308.247
976.038	326.237
977.093	316.226
978.147	304.216
979.202	342.206
980.257	331.196
981.311	310.185
982.365	321.175
983.419	333.165
984.473	322.154
985.527	372.144
986.581	339.134
987.635	305.124
988.688	311.113
989.742	365.103
990.795	324.093
991.846	308.082
992.899	359.072
993.952	313.062
995.005	307.051
996.055	339.041
997.108	344.031
998.16	329.021
999.211	329.01
999.737	366.005